Workbook

Sheet Controlli
A1: CONTROLLI PIANO FINANZIARIO — ORTI
A3: 1. SALDO PARTENZA
A4: C4:D4 = saldi iniziali hardcoded (mesi chiusi)? | B4: =IF(OR(_xlfn.ISFORMULA('Piano Finanziario'!C4),_xlfn.ISFORMULA('Piano Finanziario'!D4)),"ERRORE","OK")
A5: E4 = D37 (giugno parte da saldo reale maggio)? | B5: =IF('Piano Finanziario'!E4='Piano Finanziario'!D37,"OK","ERRORE")
A6: Catena E4:K4 = mese prec riga 37? | B6: =IF(AND('Piano Finanziario'!E4='Piano Finanziario'!D37,'Piano Finanziario'!F4='Piano Finanziario'!E37,'Piano Finanziario'!G4='Piano Finanziario'!F37,'Piano Finanziario'!H4='Piano Finanziario'!G37,'Piano Finanziario'!I4='Piano Finanziario'!H37,'Piano Finanziario'!J4='Piano Finanziario'!I37,'Piano Finanziario'!K4='Piano Finanziario'!J37),"OK","ERRORE")
A7: (non applicabile — mesi passati rimossi) | B7: OK
A9: 2. TOTALE ENTRATE (riga 12)
A10: Riga 12 = SUM(6:11) per mesi C:K? | B10: =IF(AND('Piano Finanziario'!C12=SUM('Piano Finanziario'!C6:'Piano Finanziario'!C11),'Piano Finanziario'!D12=SUM('Piano Finanziario'!D6:'Piano Finanziario'!D11),'Piano Finanziario'!E12=SUM('Piano Finanziario'!E6:'Piano Finanziario'!E11),'Piano Finanziario'!F12=SUM('Piano Finanziario'!F6:'Piano Finanziario'!F11),'Piano Finanziario'!G12=SUM('Piano Finanziario'!G6:'Piano Finanziario'!G11),'Piano Finanziario'!H12=SUM('Piano Finanziario'!H6:'Piano Finanziario'!H11),'Piano Finanziario'!I12=SUM('Piano Finanziario'!I6:'Piano Finanziario'!I11),'Piano Finanziario'!J12=SUM('Piano Finanziario'!J6:'Piano Finanziario'!J11),'Piano Finanziario'!K12=SUM('Piano Finanziario'!K6:'Piano Finanziario'!K11)),"OK","ERRORE")
A12: 3. TOTALE USCITE (riga 27)
A13: Riga 27 = SUM(14:26) per mesi C:K? | B13: =IF(AND('Piano Finanziario'!C27=SUM('Piano Finanziario'!C14:'Piano Finanziario'!C26),'Piano Finanziario'!D27=SUM('Piano Finanziario'!D14:'Piano Finanziario'!D26),'Piano Finanziario'!E27=SUM('Piano Finanziario'!E14:'Piano Finanziario'!E26),'Piano Finanziario'!F27=SUM('Piano Finanziario'!F14:'Piano Finanziario'!F26),'Piano Finanziario'!G27=SUM('Piano Finanziario'!G14:'Piano Finanziario'!G26),'Piano Finanziario'!H27=SUM('Piano Finanziario'!H14:'Piano Finanziario'!H26),'Piano Finanziario'!I27=SUM('Piano Finanziario'!I14:'Piano Finanziario'!I26),'Piano Finanziario'!J27=SUM('Piano Finanziario'!J14:'Piano Finanziario'!J26),'Piano Finanziario'!K27=SUM('Piano Finanziario'!K14:'Piano Finanziario'!K26)),"OK","ERRORE")
A15: 4. CASH FLOW (riga 29)
A16: Riga 29 = Entrate - Uscite per mesi C:K? | B16: =IF(AND('Piano Finanziario'!C29='Piano Finanziario'!C12-'Piano Finanziario'!C27,'Piano Finanziario'!D29='Piano Finanziario'!D12-'Piano Finanziario'!D27,'Piano Finanziario'!E29='Piano Finanziario'!E12-'Piano Finanziario'!E27,'Piano Finanziario'!F29='Piano Finanziario'!F12-'Piano Finanziario'!F27,'Piano Finanziario'!G29='Piano Finanziario'!G12-'Piano Finanziario'!G27,'Piano Finanziario'!H29='Piano Finanziario'!H12-'Piano Finanziario'!H27,'Piano Finanziario'!I29='Piano Finanziario'!I12-'Piano Finanziario'!I27,'Piano Finanziario'!J29='Piano Finanziario'!J12-'Piano Finanziario'!J27,'Piano Finanziario'!K29='Piano Finanziario'!K12-'Piano Finanziario'!K27),"OK","ERRORE")
A21: 6. RIFERIMENTI USCITE — FOGLI DETTAGLIO (mesi I:R)
A22: Riga 14 — Salari e Stipendi | B22: =IF(AND('Piano Finanziario'!C14='Salari e Stipendi'!D4,'Piano Finanziario'!D14='Salari e Stipendi'!E4,'Piano Finanziario'!E14='Salari e Stipendi'!F4,'Piano Finanziario'!F14='Salari e Stipendi'!G4,'Piano Finanziario'!G14='Salari e Stipendi'!H4,'Piano Finanziario'!H14='Salari e Stipendi'!I4,'Piano Finanziario'!I14='Salari e Stipendi'!J4,'Piano Finanziario'!J14='Salari e Stipendi'!K4,'Piano Finanziario'!K14='Salari e Stipendi'!L4),"OK","ERRORE")
A23: Riga 15 — Utenze | B23: =IF(AND('Piano Finanziario'!C15=Utenze!D3,'Piano Finanziario'!D15=Utenze!E3,'Piano Finanziario'!E15=Utenze!F3,'Piano Finanziario'!F15=Utenze!G3,'Piano Finanziario'!G15=Utenze!H3,'Piano Finanziario'!H15=Utenze!I3,'Piano Finanziario'!I15=Utenze!J3,'Piano Finanziario'!J15=Utenze!K3,'Piano Finanziario'!K15=Utenze!L3),"OK","ERRORE")
A24: Riga 16 — Materie Prime/Consumo | B24: =IF(AND('Piano Finanziario'!C16=MAX('Materie Prime-Consumo '!D3,'Materie Prime-Consumo '!D4),'Piano Finanziario'!D16=MAX('Materie Prime-Consumo '!E3,'Materie Prime-Consumo '!E4),'Piano Finanziario'!E16=MAX('Materie Prime-Consumo '!F3,'Materie Prime-Consumo '!F4),'Piano Finanziario'!F16=MAX('Materie Prime-Consumo '!G3,'Materie Prime-Consumo '!G4),'Piano Finanziario'!G16=MAX('Materie Prime-Consumo '!H3,'Materie Prime-Consumo '!H4),'Piano Finanziario'!H16=MAX('Materie Prime-Consumo '!I3,'Materie Prime-Consumo '!I4),'Piano Finanziario'!I16=MAX('Materie Prime-Consumo '!J3,'Materie Prime-Consumo '!J4),'Piano Finanziario'!J16=MAX('Materie Prime-Consumo '!K3,'Materie Prime-Consumo '!K4),'Piano Finanziario'!K16=MAX('Materie Prime-Consumo '!L3,'Materie Prime-Consumo '!L4)),"OK","ERRORE")
A25: Riga 17 — Tasse e Imposte | B25: =IF(AND('Piano Finanziario'!C17='Tasse e Imposte'!D3,'Piano Finanziario'!D17='Tasse e Imposte'!E3,'Piano Finanziario'!E17='Tasse e Imposte'!F3,'Piano Finanziario'!F17='Tasse e Imposte'!G3,'Piano Finanziario'!G17='Tasse e Imposte'!H3,'Piano Finanziario'!H17='Tasse e Imposte'!I3,'Piano Finanziario'!I17='Tasse e Imposte'!J3,'Piano Finanziario'!J17='Tasse e Imposte'!K3,'Piano Finanziario'!K17='Tasse e Imposte'!L3),"OK","ERRORE")
A26: Riga 18 — Commissioni Portali | B26: =IF(AND('Piano Finanziario'!C18='Commisisoni Portali'!D3,'Piano Finanziario'!D18='Commisisoni Portali'!E3,'Piano Finanziario'!E18='Commisisoni Portali'!F3,'Piano Finanziario'!F18='Commisisoni Portali'!G3,'Piano Finanziario'!G18='Commisisoni Portali'!H3,'Piano Finanziario'!H18='Commisisoni Portali'!I3,'Piano Finanziario'!I18='Commisisoni Portali'!J3,'Piano Finanziario'!J18='Commisisoni Portali'!K3,'Piano Finanziario'!K18='Commisisoni Portali'!L3),"OK","ERRORE")
A27: Riga 19 — Mutui e Finanziamenti | B27: =IF(AND('Piano Finanziario'!C19='Mutui e Finaziamenti'!D3,'Piano Finanziario'!D19='Mutui e Finaziamenti'!E3,'Piano Finanziario'!E19='Mutui e Finaziamenti'!F3,'Piano Finanziario'!F19='Mutui e Finaziamenti'!G3,'Piano Finanziario'!G19='Mutui e Finaziamenti'!H3,'Piano Finanziario'!H19='Mutui e Finaziamenti'!I3,'Piano Finanziario'!I19='Mutui e Finaziamenti'!J3,'Piano Finanziario'!J19='Mutui e Finaziamenti'!K3,'Piano Finanziario'!K19='Mutui e Finaziamenti'!L3),"OK","ERRORE")
A28: Riga 20 — Consulenze | B28: =IF(AND('Piano Finanziario'!C20=Consulenze!D3,'Piano Finanziario'!D20=Consulenze!E3,'Piano Finanziario'!E20=Consulenze!F3,'Piano Finanziario'!F20=Consulenze!G3,'Piano Finanziario'!G20=Consulenze!H3,'Piano Finanziario'!H20=Consulenze!I3,'Piano Finanziario'!I20=Consulenze!J3,'Piano Finanziario'!J20=Consulenze!K3,'Piano Finanziario'!K20=Consulenze!L3),"OK","ERRORE")
A29: Riga 21 — Godimento Beni di Terzi | B29: =IF(AND('Piano Finanziario'!C21='Godimento Beni di Terzi'!D4,'Piano Finanziario'!D21='Godimento Beni di Terzi'!E4,'Piano Finanziario'!E21='Godimento Beni di Terzi'!F4,'Piano Finanziario'!F21='Godimento Beni di Terzi'!G4,'Piano Finanziario'!G21='Godimento Beni di Terzi'!H4,'Piano Finanziario'!H21='Godimento Beni di Terzi'!I4,'Piano Finanziario'!I21='Godimento Beni di Terzi'!J4,'Piano Finanziario'!J21='Godimento Beni di Terzi'!K4,'Piano Finanziario'!K21='Godimento Beni di Terzi'!L4),"OK","ERRORE")
A30: Riga 22 — Varie ed Eventuali | B30: =IF(AND('Piano Finanziario'!C22=' Varie ed Eventuali'!D3,'Piano Finanziario'!D22=' Varie ed Eventuali'!E3,'Piano Finanziario'!E22=' Varie ed Eventuali'!F3,'Piano Finanziario'!F22=' Varie ed Eventuali'!G3,'Piano Finanziario'!G22=' Varie ed Eventuali'!H3,'Piano Finanziario'!H22=' Varie ed Eventuali'!I3,'Piano Finanziario'!I22=' Varie ed Eventuali'!J3,'Piano Finanziario'!J22=' Varie ed Eventuali'!K3,'Piano Finanziario'!K22=' Varie ed Eventuali'!L3),"OK","ERRORE")
A31: Riga 23 — Canoni e servizi | B31: =IF(AND('Piano Finanziario'!C23='Canoni e servizi'!D4,'Piano Finanziario'!D23='Canoni e servizi'!E4,'Piano Finanziario'!E23='Canoni e servizi'!F4,'Piano Finanziario'!F23='Canoni e servizi'!G4,'Piano Finanziario'!G23='Canoni e servizi'!H4,'Piano Finanziario'!H23='Canoni e servizi'!I4,'Piano Finanziario'!I23='Canoni e servizi'!J4,'Piano Finanziario'!J23='Canoni e servizi'!K4,'Piano Finanziario'!K23='Canoni e servizi'!L4),"OK","ERRORE")
A33: 7. SALDO PROIETTATO (riga 37)
A34: Riga 37 = riga 4 + riga 29 per mesi attivi I:R? | B34: =IF(AND('Piano Finanziario'!C37='Piano Finanziario'!C4+'Piano Finanziario'!C29,'Piano Finanziario'!D37='Piano Finanziario'!D4+'Piano Finanziario'!D29,'Piano Finanziario'!E37='Piano Finanziario'!E4+'Piano Finanziario'!E29,'Piano Finanziario'!F37='Piano Finanziario'!F4+'Piano Finanziario'!F29,'Piano Finanziario'!G37='Piano Finanziario'!G4+'Piano Finanziario'!G29,'Piano Finanziario'!H37='Piano Finanziario'!H4+'Piano Finanziario'!H29,'Piano Finanziario'!I37='Piano Finanziario'!I4+'Piano Finanziario'!I29,'Piano Finanziario'!J37='Piano Finanziario'!J4+'Piano Finanziario'!J29,'Piano Finanziario'!K37='Piano Finanziario'!K4+'Piano Finanziario'!K29),"OK","ERRORE")
A36: 8. CASH FLOW CON AFFIDAMENTI (riga 45)
A37: Riga 45 = riga 37 + riga 43 per mesi attivi I:R? | B37: =IF(AND('Piano Finanziario'!C45='Piano Finanziario'!C37+'Piano Finanziario'!C43,'Piano Finanziario'!D45='Piano Finanziario'!D37+'Piano Finanziario'!D43,'Piano Finanziario'!E45='Piano Finanziario'!E37+'Piano Finanziario'!E43,'Piano Finanziario'!F45='Piano Finanziario'!F37+'Piano Finanziario'!F43,'Piano Finanziario'!G45='Piano Finanziario'!G37+'Piano Finanziario'!G43,'Piano Finanziario'!H45='Piano Finanziario'!H37+'Piano Finanziario'!H43,'Piano Finanziario'!I45='Piano Finanziario'!I37+'Piano Finanziario'!I43,'Piano Finanziario'!J45='Piano Finanziario'!J37+'Piano Finanziario'!J43,'Piano Finanziario'!K45='Piano Finanziario'!K37+'Piano Finanziario'!K43),"OK","ERRORE")
A39: 9. COLONNA TOTALI (T)
A40: L12 Totale Entrate = SUM(C12:K12)? | B40: =IF('Piano Finanziario'!L12=SUM('Piano Finanziario'!C12:'Piano Finanziario'!K12),"OK","ERRORE")
A41: L27 Totale Uscite = SUM(C27:K27)? | B41: =IF('Piano Finanziario'!L27=SUM('Piano Finanziario'!C27:'Piano Finanziario'!K27),"OK","ERRORE")
A42: L29 Cash Flow = L12 - L27? | B42: =IF('Piano Finanziario'!L29='Piano Finanziario'!L12-'Piano Finanziario'!L27,"OK","ERRORE")
A44: =CONCATENATE("RISULTATO COMPLESSIVO") | B44: =IF(COUNTIF(B4:B42,"ERRORE")=0,"✓ TUTTI I "&COUNTA(B4:B42)&" CONTROLLI OK","✗ "&COUNTIF(B4:B42,"ERRORE")&" ERRORI TROVATI su "&COUNTA(B4:B42)&" verifiche")

Sheet Piano Finanziario
A1: ORTI S.R.L. | C1: 2026
C2: APRILE | D2: MAGGIO | E2: GIUGNO | F2: LUGLIO | G2: AGOSTO | H2: SETTEMBRE | I2: OTTOBRE | J2: NOVEMBRE | K2: DICEMBRE | L2: TOTALI
A4: SALDO MESE PRECED | C4: 339337.46 | D4: 581125.86 | E4: =D37 | F4: =E37 | G4: =F37 | H4: =G37 | I4: =H37 | J4: =I37 | K4: =J37
A6: Entrate Hotel | E6: 600000 | F6: 750000 | G6: 830000 | H6: 580000 | I6: =110000+160000 | L6: =SUM(C6:K6)
A7: Entrate Residence | E7: 100000 | F7: 120000 | G7: 140000 | H7: 100000 | I7: =26000+17000 | L7: =SUM(C7:K7)
A8: Entrate CVM | E8: 25000 | F8: 45000 | G8: 48000 | H8: 30000 | I8: =5798+10000 | L8: =SUM(C8:K8)
A9: Entrate Supermercato | E9: 25620 | F9: 25620 | G9: 25620 | H9: 25620 | I9: 25620 | J9: 25620 | K9: 25620 | L9: =SUM(C9:K9)
A10: Rientro Sospesi | L10: =SUM(C10:K10)
A11: Caparre Intur | L11: =SUM(C11:K11)
A12: TOTALE ENTRATE | C12: =SUM(C6:C11) | D12: =SUM(D6:D11) | E12: =SUM(E6:E11) | F12: =SUM(F6:F11) | G12: =SUM(G6:G11) | H12: =SUM(H6:H11) | I12: =SUM(I6:I11) | J12: =SUM(J6:J11) | K12: =SUM(K6:K11) | L12: =SUM(C12:K12)
A14: Salari e Stipendi | C14: ='Salari e Stipendi'!D4 | D14: ='Salari e Stipendi'!E4 | E14: ='Salari e Stipendi'!F4 | F14: ='Salari e Stipendi'!G4 | G14: ='Salari e Stipendi'!H4 | H14: ='Salari e Stipendi'!I4 | I14: ='Salari e Stipendi'!J4 | J14: ='Salari e Stipendi'!K4 | K14: ='Salari e Stipendi'!L4 | L14: =SUM(C14:K14)
A15: Utenze | C15: =Utenze!D3 | D15: =Utenze!E3 | E15: =Utenze!F3 | F15: =Utenze!G3 | G15: =Utenze!H3 | H15: =Utenze!I3 | I15: =Utenze!J3 | J15: =Utenze!K3 | K15: =Utenze!L3 | L15: =SUM(C15:K15)
A16: Materie Prime/Consumo | C16: =MAX('Materie Prime-Consumo '!D3,'Materie Prime-Consumo '!D4) | D16: =MAX('Materie Prime-Consumo '!E3,'Materie Prime-Consumo '!E4) | E16: =MAX('Materie Prime-Consumo '!F3,'Materie Prime-Consumo '!F4) | F16: =MAX('Materie Prime-Consumo '!G3,'Materie Prime-Consumo '!G4) | G16: =MAX('Materie Prime-Consumo '!H3,'Materie Prime-Consumo '!H4) | H16: =MAX('Materie Prime-Consumo '!I3,'Materie Prime-Consumo '!I4) | I16: =MAX('Materie Prime-Consumo '!J3,'Materie Prime-Consumo '!J4) | J16: =MAX('Materie Prime-Consumo '!K3,'Materie Prime-Consumo '!K4) | K16: =MAX('Materie Prime-Consumo '!L3,'Materie Prime-Consumo '!L4) | L16: =SUM(C16:K16)
A17: Tasse e Imposte | C17: ='Tasse e Imposte'!D3 | D17: ='Tasse e Imposte'!E3 | E17: ='Tasse e Imposte'!F3 | F17: ='Tasse e Imposte'!G3 | G17: ='Tasse e Imposte'!H3 | H17: ='Tasse e Imposte'!I3 | I17: ='Tasse e Imposte'!J3 | J17: ='Tasse e Imposte'!K3 | K17: ='Tasse e Imposte'!L3 | L17: =SUM(C17:K17)
A18: Commissioni Portali | C18: ='Commisisoni Portali'!D3 | D18: ='Commisisoni Portali'!E3 | E18: ='Commisisoni Portali'!F3 | F18: ='Commisisoni Portali'!G3 | G18: ='Commisisoni Portali'!H3 | H18: ='Commisisoni Portali'!I3 | I18: ='Commisisoni Portali'!J3 | J18: ='Commisisoni Portali'!K3 | K18: ='Commisisoni Portali'!L3 | L18: =SUM(C18:K18)
A19: Mutui e Finaziamenti | C19: ='Mutui e Finaziamenti'!D3 | D19: ='Mutui e Finaziamenti'!E3 | E19: ='Mutui e Finaziamenti'!F3 | F19: ='Mutui e Finaziamenti'!G3 | G19: ='Mutui e Finaziamenti'!H3 | H19: ='Mutui e Finaziamenti'!I3 | I19: ='Mutui e Finaziamenti'!J3 | J19: ='Mutui e Finaziamenti'!K3 | K19: ='Mutui e Finaziamenti'!L3 | L19: =SUM(C19:K19)
A20: Consulenze | C20: =Consulenze!D3 | D20: =Consulenze!E3 | E20: =Consulenze!F3 | F20: =Consulenze!G3 | G20: =Consulenze!H3 | H20: =Consulenze!I3 | I20: =Consulenze!J3 | J20: =Consulenze!K3 | K20: =Consulenze!L3 | L20: =SUM(C20:K20)
A21: Godimento Beni di Terzi | C21: ='Godimento Beni di Terzi'!D4 | D21: ='Godimento Beni di Terzi'!E4 | E21: ='Godimento Beni di Terzi'!F4 | F21: ='Godimento Beni di Terzi'!G4 | G21: ='Godimento Beni di Terzi'!H4 | H21: ='Godimento Beni di Terzi'!I4 | I21: ='Godimento Beni di Terzi'!J4 | J21: ='Godimento Beni di Terzi'!K4 | K21: ='Godimento Beni di Terzi'!L4 | L21: =SUM(C21:K21)
A22: Varie ed Eventuali | C22: =' Varie ed Eventuali'!D3 | D22: =' Varie ed Eventuali'!E3 | E22: =' Varie ed Eventuali'!F3 | F22: =' Varie ed Eventuali'!G3 | G22: =' Varie ed Eventuali'!H3 | H22: =' Varie ed Eventuali'!I3 | I22: =' Varie ed Eventuali'!J3 | J22: =' Varie ed Eventuali'!K3 | K22: =' Varie ed Eventuali'!L3 | L22: =SUM(C22:K22)
A23: Canoni e servizi | C23: ='Canoni e servizi'!D4 | D23: ='Canoni e servizi'!E4 | E23: ='Canoni e servizi'!F4 | F23: ='Canoni e servizi'!G4 | G23: ='Canoni e servizi'!H4 | H23: ='Canoni e servizi'!I4 | I23: ='Canoni e servizi'!J4 | J23: ='Canoni e servizi'!K4 | K23: ='Canoni e servizi'!L4 | L23: =SUM(C23:K23)
A24: Deposito Fitto | L24: =SUM(C24:K24)
A27: TOTALE USCITE | C27: =SUM(C14:C26) | D27: =SUM(D14:D26) | E27: =SUM(E14:E26) | F27: =SUM(F14:F26) | G27: =SUM(G14:G26) | H27: =SUM(H14:H26) | I27: =SUM(I14:I26) | J27: =SUM(J14:J26) | K27: =SUM(K14:K26) | L27: =SUM(C27:K27)
A29: Cash Flow | C29: =C12-C27 | D29: =D12-D27 | E29: =E12-E27 | F29: =F12-F27 | G29: =G12-G27 | H29: =H12-H27 | I29: =I12-I27 | J29: =J12-J27 | ... L29: =L12-L27
A31: 30/04/2026 | C31: 30/04/2026 | D31: 31/05/2026
A32: Saldo MPS | B32: 31/05/2026 | C32: 469,192.55 € | D32: 469192.55
A33: Saldo Intesa | C33: 111,933.31 € | D33: 111933.31
A35: TOTALE BANCHE | C35: =SUM(C32:C34)
A37: Saldo di Periodo/Proiettato | C37: =C4+C29 | D37: =D4+D29 | E37: =E4+E29 | F37: =F4+F29 | G37: =G4+G29 | H37: =H4+H29 | I37: =I4+I29 | J37: =J4+J29 | K37: =K4+K29 | L37: =K37
A39: Fin. MPS 60 mesi | C39: 0 | D39: 0 | E39: 0 | F39: 0 | G39: 0 | H39: 0 | I39: 0 | J39: 0 | K39: 0
A43: TOTALE AFFIDAMENTI | C43: =SUM(C39:C42) | D43: =SUM(D39:D42) | E43: =SUM(E39:E42) | F43: =SUM(F39:F42) | G43: =SUM(G39:G42) | H43: =SUM(H39:H42) | I43: =SUM(I39:I42) | J43: =SUM(J39:J42) | K43: =SUM(K39:K42) | L43: =SUM(C43:K43)
A45: CASH FLOW CON AFFID. | C45: =C37+C43 | D45: =D37+D43 | E45: =E37+E43 | F45: =F37+F43 | G45: =G37+G43 | H45: =H37+H43 | I45: =I37+I43 | J45: =J37+J43 | K45: =K37+K43 | L45: =K45

Sheet Salari e Stipendi
D1: 2026
A2: CODICE | D2: APRILE | E2: MAGGIO | F2: GIUGNO | G2: LUGLIO | H2: AGOSTO | I2: SETTEMBRE | J2: OTTOBRE | K2: NOVEMBRE | L2: DICEMBRE
B4: Salari e Stipendi | C4: =SUM(D4:L4) | D4: =SUM(D5:D135) | E4: =SUM(E5:E135) | F4: =SUM(F5:F135) | G4: =SUM(G5:G135) | H4: =SUM(H5:H135) | I4: =SUM(I5:I135) | J4: =SUM(J5:J135) | K4: =SUM(K5:K135) | L4: =SUM(L5:L135)
A5: 670101 | B5: SALARI | C5: =SUM(D5:L5) | F5: 76220.46 | G5: 85000 | H5: 95000 | I5: 90000 | J5: 80000 | K5: 120000 | L5: 40000
A6: 350301 | B6: F24 | C6: =SUM(D6:L6) | F6: 44748.74 | G6: 50000 | H6: 60000 | I6: 50000 | J6: 35000 | K6: 55000 | L6: 18000
C7: =SUM(D7:L7)
C8: =SUM(D8:L8)
C9: =SUM(D9:L9)
C10: =SUM(D10:L10)
C11: =SUM(D11:L11)
C12: =SUM(D12:L12)
C13: =SUM(D13:L13)
C14: =SUM(D14:L14)
C15: =SUM(D15:L15)
C16: =SUM(D16:L16)
C17: =SUM(D17:L17)
C18: =SUM(D18:L18)
... C69: =SUM(D69:L69)

Sheet Utenze
D1: 2026
A2: CODICE | D2: APRILE | E2: MAGGIO | F2: GIUGNO | G2: LUGLIO | H2: AGOSTO | I2: SETTEMBRE | J2: OTTOBRE | K2: NOVEMBRE | L2: DICEMBRE
B3: Utenze | C3: =SUM(D3:L3) | D3: =SUM(D4:D134) | E3: =SUM(E4:E134) | F3: =SUM(F4:F134) | G3: =SUM(G4:G134) | H3: =SUM(H4:H134) | I3: =SUM(I4:I134) | J3: =SUM(J4:J134) | K3: =SUM(K4:K134) | L3: =SUM(L4:L134)
A4: 570913 | B4: Energia elettrica | C4: =SUM(D4:L4) | F4: 15066.02 | G4: 27525.61 | H4: 22000 | I4: 19000 | J4: 17000 | K4: 20000 | L4: 27000
A5: 570919 | B5: Gas | C5: =SUM(D5:L5) | F5: 6500 | G5: 6500 | H5: 6500 | I5: 6500 | J5: 6500 | K5: 6500 | L5: 6500
A6: 18 | B6: Acqua - Ausino | C6: =SUM(D6:L6) | F6: 2714.5 | H6: 2143.09
A7: 44 | B7: Vodafone (intur) | C7: =SUM(D7:L7)
A8: 570909 | B8: Connectivia | C8: =SUM(D8:L8) | F8: 5000 | H8: 3500 | J8: 3500 | L8: 3500
C9: =SUM(D9:L9)
C10: =SUM(D10:L10)
C11: =SUM(D11:L11)
C12: =SUM(D12:L12)
C13: =SUM(D13:L13)
C14: =SUM(D14:L14)
C15: =SUM(D15:L15)
C16: =SUM(D16:L16)
C17: =SUM(D17:L17)
C18: =SUM(D18:L18)
C19: =SUM(D19:L19)
C20: =SUM(D20:L20)
... C68: =SUM(D68:L68)

Sheet Materie Prime-Consumo 
D1: 2026
A2: CODICE | D2: APRILE | E2: MAGGIO | F2: GIUGNO | G2: LUGLIO | H2: AGOSTO | I2: SETTEMBRE | J2: OTTOBRE | K2: NOVEMBRE | L2: DICEMBRE
B3: PREVISIONALE | C3: =SUM(D3:L3) | F3: 95000 | G3: 120000 | H3: 145000 | I3: 140000 | J3: 135000 | K3: 75000 | L3: 60000
B4: Materie Prime e Consumo | C4: =SUM(D4:L4) | D4: =SUM(D5:D185) | E4: =SUM(E5:E185) | F4: =SUM(F5:F185) | G4: =SUM(G5:G185) | H4: =SUM(H5:H185) | I4: =SUM(I5:I185) | J4: =SUM(J5:J185) | K4: =SUM(K5:K185) | L4: =SUM(L5:L185)
A5: 801 | B5: A. Migliore srl | C5: =SUM(D5:L5) | G5: 201.41
A6: 281 | B6: Abiti da lavoro Cavaliere srls | C6: =SUM(D6:L6)
A7: 1183 | B7: Adra srl | C7: =SUM(D7:L7) | F7: 160.38 | H7: 839.47 | I7: 116.6
A8: 412 | B8: Alberto D'Urso | C8: =SUM(D8:L8) | F8: 234.06 | G8: 527.86
A9: 1589 | B9: Alnumar di Garofalo Massimiliano | G9: 1920.41
A10: 92 | B10: Amalfi sei esse | C10: =SUM(D10:L10) | G10: 6384.75 | H10: 6825.63 | I10: 9528.63 | J10: 180.08
A11: 1720 | B11: Amalfi ghiaccio
A12: 131 | B12: Amalfi Web | C12: =SUM(D12:L12)
A13: 147 | B13: Amato Filippo | C13: =SUM(D13:L13)
A14: 325 | B14: Alfera srl | C14: =SUM(D14:L14) | H14: 2260
A15: 916 | B15: Allestimenti Di Palo | C15: =SUM(D15:L15)
A16: 790 | B16: Amato Prisco pane | C16: =SUM(D16:L16)
A17: 1260 | B17: Aniello Bisogno & Figli | C17: =SUM(D17:L17)
A18: 667 | B18: Attianese Frutta e Verdura | C18: =SUM(D18:L18)
A19: 1298 | B19: Apicella Lorenzo | C19: =SUM(D19:L19)
A20: 758 | B20: B&G Di Palo Commercio | C20: =SUM(D20:L20)
A21: 74 | B21: Bellagaia | C21: =SUM(D21:L21) | G21: 8248.92 | H21: 1192.1
A22: 399 | B22: Campitiello Fabio | C22: =SUM(D22:L22)
A23: 864 | B23: Capuano Raffaele | C23: =SUM(D23:L23) | F23: 80
A24: 208 | B24: Casa Vinicola Sammarco | C24: =SUM(D24:L24) | G24: 666.12 | H24: 1141.92
A25: 1137 | B25: Coccorullo Falegnamenria | C25: =SUM(D25:L25)
A26: 125 | B26: Centro Distribuzione Maglio | C26: =SUM(D26:L26) | G26: 1588.4
A27: 315 | B27: Centro service Snc | C27: =SUM(D27:L27)
A28: 423 | B28: Cica | C28: =SUM(D28:L28) | G28: 2062.02 | H28: 570.02
A29: 417 | B29: Cimmini Filomena | C29: =SUM(D29:L29) | F29: 51.48
A30: 369 | B30: Creative Idea | C30: =SUM(D30:L30)
A31: 1003 | B31: Ditta Pansa | C31: =SUM(D31:L31)
A32: 226 | B32: De Luca | C32: =SUM(D32:L32)
A33: 7 | B33: DG Network | C33: =SUM(D33:L33)
A34: 161 | B34: Di Sarno Coffee | C34: =SUM(D34:L34) | F34: 1951.96 | G34: 6296.08 | H34: 1945.46
A35: 32 | B35: Ditta Apicella | C35: =SUM(D35:L35)
A36: 1003 | B36: Ditta Pansa | C36: =SUM(D36:L36)
A37: 133 | B37: Fabbrocino Michele | C37: =SUM(D37:L37) | G37: 1846.68 | H37: 10575.14 | I37: 4164.01
A38: 672 | B38: Barela Farmacia | C38: =SUM(D38:L38)
A39: 127 | B39: Feio Srl | C39: =SUM(D39:L39) | G39: 1697.14
A40: 179 | B40: Ferrigno Maria | C40: =SUM(D40:L40)
...

Sheet Tasse e Imposte
D1: 2026
A2: CODICE | D2: APRILE | E2: MAGGIO | F2: GIUGNO | G2: LUGLIO | H2: AGOSTO | I2: SETTEMBRE | J2: OTTOBRE | K2: NOVEMBRE | L2: DICEMBRE
B3: Tasse e Imposte | C3: =SUM(D3:L3) | D3: =SUM(D4:D135) | E3: =SUM(E4:E135) | F3: =SUM(F4:F135) | G3: =SUM(G4:G135) | H3: =SUM(H4:H135) | I3: =SUM(I4:I135) | J3: =SUM(J4:J135) | K3: =SUM(K4:K135) | L3: =SUM(L4:L135)
A4: 710104 | B4: IMU | C4: =SUM(D4:L4) | F4: 5325
A5: 630511 | B5: IMPOSTE | C5: =SUM(D5:L5) | G5: 7500
A6: 630519 | B6: TARI HOTEL | C6: =SUM(D6:L6) | G6: 0
A7: 350101 | B7: IVA | C7: =SUM(D7:L7) | G7: 50000 | J7: 10000
A8: 350305 | B8: RITENUTE PROFESSIONISTI (1040)
A9: 390590 | B9: IMPOSTA DI SOGGIORNO HP | C9: =SUM(D9:L9) | F9: 12300 | G9: 15000 | H9: 15400 | I9: 19000 | J9: 17500 | K9: 10000
B10: IMPOSTA DI SOGGIORNO AR | C10: =SUM(D10:L10) | F10: 1210 | G10: 2400 | H10: 2900 | I10: 2700 | J10: 2030 | K10: 1380
A11: 390593 | B11: IMPOSTA DI SOGGIORNO CVM | C11: =SUM(D11:L11) | F11: 870 | G11: 1100 | H11: 1100 | I11: 1800 | J11: 1200 | K11: 750
A12: 630519 | B12: TARI RESIDENCE | C12: =SUM(D12:L12)
B13: TARI CVM | C13: =SUM(D13:L13)
B14: IRES/IRAP | C14: =SUM(D14:L14) | F14: 121000
C15: =SUM(D15:L15)
C16: =SUM(D16:L16)
C17: =SUM(D17:L17)
C18: =SUM(D18:L18)
C19: =SUM(D19:L19)
C20: =SUM(D20:L20)
C21: =SUM(D21:L21)
C22: =SUM(D22:L22)
C23: =SUM(D23:L23)
C24: =SUM(D24:L24)
C25: =SUM(D25:L25)
C26: =SUM(D26:L26)
... C69: =SUM(D69:L69)

Sheet Commisisoni Portali
D1: 2026
A2: CODICE | D2: APRILE | E2: MAGGIO | F2: GIUGNO | G2: LUGLIO | H2: AGOSTO | I2: SETTEMBRE | J2: OTTOBRE | K2: NOVEMBRE | L2: DICEMBRE
B3: Commisisoni Portali | C3: =SUM(D3:L3) | D3: =SUM(D4:D130) | E3: =SUM(E4:E130) | F3: =SUM(F4:F130) | G3: =SUM(G4:G130) | H3: =SUM(H4:H130) | I3: =SUM(I4:I130) | J3: =SUM(J4:J130) | K3: =SUM(K4:K130) | L3: =SUM(L4:L130)
A4: 57010192 | B4: Commissioni Booking | C4: =SUM(D4:L4) | F4: 16500 | G4: 32000 | H4: 37000 | I4: 4660 | J4: 28000 | K4: 14000 | L4: 700
A5: 57010192 | B5: Commissioni Expedia | C5: =SUM(D5:L5) | F5: 6600 | G5: 7300 | H5: 6300 | I5: 5500 | K5: 0 | L5: 7500
A6: 414 | B6: NEXI PAYMENTS S.p.A. | C6: =SUM(D6:L6) | F6: 5.49
C7: =SUM(D7:L7)
C8: =SUM(D8:L8)
C9: =SUM(D9:L9)
C10: =SUM(D10:L10)
C11: =SUM(D11:L11)
C12: =SUM(D12:L12)
C13: =SUM(D13:L13)
C14: =SUM(D14:L14)
C15: =SUM(D15:L15)
C16: =SUM(D16:L16)
C17: =SUM(D17:L17)
C18: =SUM(D18:L18)
... C64: =SUM(D64:L64)

Sheet Mutui e Finaziamenti
D1: 2026
A2: CODICE | D2: APRILE | E2: MAGGIO | F2: GIUGNO | G2: LUGLIO | H2: AGOSTO | I2: SETTEMBRE | J2: OTTOBRE | K2: NOVEMBRE | L2: DICEMBRE
B3: Mutui e Finanaziamenti | C3: =SUM(D3:L3) | D3: =SUM(D4:D134) | E3: =SUM(E4:E134) | F3: =SUM(F4:F134) | G3: =SUM(G4:G134) | H3: =SUM(H4:H134) | I3: =SUM(I4:I134) | J3: =SUM(J4:J134) | K3: =SUM(K4:K134) | L3: =SUM(L4:L134)
A4: 310394 | B4: Mutuo MPS | C4: =SUM(D4:L4) | F4: 166176 | L4: 166176
A5: 310392 | B5: EX Muto Intesa (mps) | C5: =SUM(D5:L5) | F5: 12231.88 | G5: 12265.38 | H5: 12264.67 | I5: 12233.4 | J5: 12263.24 | K5: 12234.42 | L5: 12261.8
A6: 310305 | B6: Finanziamento MPS 75k | C6: =SUM(D6:L6) | F6: 1393.92 | G6: 1393.92 | H6: 1393.92 | I6: 1393.92 | J6: 1393.92 | K6: 1393.92 | L6: 1393.92
C7: =SUM(D7:L7)
C8: =SUM(D8:L8)
C9: =SUM(D9:L9)
C10: =SUM(D10:L10)
C11: =SUM(D11:L11)
C12: =SUM(D12:L12)
C13: =SUM(D13:L13)
C14: =SUM(D14:L14)
C15: =SUM(D15:L15)
C16: =SUM(D16:L16)
C17: =SUM(D17:L17)
C18: =SUM(D18:L18)
... C68: =SUM(D68:L68)

Sheet Consulenze
D1: 2026
A2: CODICE | D2: APRILE | E2: MAGGIO | F2: GIUGNO | G2: LUGLIO | H2: AGOSTO | I2: SETTEMBRE | J2: OTTOBRE | K2: NOVEMBRE | L2: DICEMBRE
B3: Consulenze | C3: =SUM(D3:L3) | D3: =SUM(D4:D134) | E3: =SUM(E4:E134) | F3: =SUM(F4:F134) | G3: =SUM(G4:G134) | H3: =SUM(H4:H134) | I3: =SUM(I4:I134) | J3: =SUM(J4:J134) | K3: =SUM(K4:K134) | L3: =SUM(L4:L134)
A4: 61010191 | B4: Consulenza del lavoro | C4: =SUM(D4:L4) | G4: 2600 | I4: 3700 | K4: 0
A5: 610101 | B5: Consulenza fiscale | C5: =SUM(D5:L5) | G5: 5000 | I5: 5000
A6: 610105 | B6: Consulenza legale | C6: =SUM(D6:L6) | F6: 3522.9 | G6: 15000 | H6: 2292.04 | I6: 15000
A7: 610107 | B7: Consulenza notarile | C7: =SUM(D7:L7)
A8: 1549 | B8: Team Work | C8: =SUM(D8:L8)
A9: 630515 | B9: Polizza Generali | C9: =SUM(D9:L9) | G9: 9000
B10: Hospitality Project | C10: =SUM(D10:L10) | F10: 3416 | G10: 3416
A11: 1693 | B11: JoAnne Dunn Photographers | C11: =SUM(D11:L11)
A12: 132 | B12: STUDIO QUATTRO S.R.L. | C12: =SUM(D12:L12) | G12: 1742.16
C13: =SUM(D13:L13)
C14: =SUM(D14:L14)
C15: =SUM(D15:L15)
C16: =SUM(D16:L16)
C17: =SUM(D17:L17)
C18: =SUM(D18:L18)
C19: =SUM(D19:L19)
C20: =SUM(D20:L20)
C21: =SUM(D21:L21)
C22: =SUM(D22:L22)
C23: =SUM(D23:L23)
C24: =SUM(D24:L24)
... C68: =SUM(D68:L68)

Sheet Godimento Beni di Terzi
D1: 2026
A2: CODICE | D2: APRILE | E2: MAGGIO | F2: GIUGNO | G2: LUGLIO | H2: AGOSTO | I2: SETTEMBRE | J2: OTTOBRE | K2: NOVEMBRE | L2: DICEMBRE
B4: Gofimento Beni di Terzi | C4: =SUM(D4:L4) | D4: =SUM(D5:D135) | E4: =SUM(E5:E135) | F4: =SUM(F5:F135) | G4: =SUM(G5:G135) | H4: =SUM(H5:H135) | I4: =SUM(I5:I135) | J4: =SUM(J5:J135) | K4: =SUM(K5:K135) | L4: =SUM(L5:L135)
A5: 651101 | B5: Fitto Ramo d' Azienda | C5: =SUM(D5:L5) | F5: 446425.69 | G5: 122000
A6: 651101 | B6: Fitto AR | C6: =SUM(D6:L6) | H6: 120000
A7: 651101 | B7: Fitto CVM | C7: =SUM(D7:L7) | K7: 100000
C8: =SUM(D8:L8)
C9: =SUM(D9:L9)
C10: =SUM(D10:L10)
C11: =SUM(D11:L11)
C12: =SUM(D12:L12)
C13: =SUM(D13:L13)
C14: =SUM(D14:L14)
C15: =SUM(D15:L15)
C16: =SUM(D16:L16)
C17: =SUM(D17:L17)
C18: =SUM(D18:L18)
C19: =SUM(D19:L19)
... C69: =SUM(D69:L69)

Sheet Canoni e servizi
D1: 2026
A2: CODICE | D2: APRILE | E2: MAGGIO | F2: GIUGNO | G2: LUGLIO | H2: AGOSTO | I2: SETTEMBRE | J2: OTTOBRE | K2: NOVEMBRE | L2: DICEMBRE
B4: Canoni e servizi | C4: =SUM(D4:L4) | D4: =SUM(D5:D131) | E4: =SUM(E5:E131) | F4: =SUM(F5:F131) | G4: =SUM(G5:G131) | H4: =SUM(H5:H131) | I4: =SUM(I5:I131) | J4: =SUM(J5:J131) | K4: =SUM(K5:K131) | L4: =SUM(L5:L131)
A5: 12 | B5: Proxima Service | C5: =SUM(D5:L5)
A6: 948 | B6: Hoxell | C6: =SUM(D6:L6)
A7: 10 | B7: Sistemi (E_solver) | C7: =SUM(D7:L7)
B8: Zucchetti | C8: =SUM(D8:L8) | G8: 152.5 | L8: 16600
A9: 1270 | B9: BESTRANK SOCIETA' A | C9: =SUM(D9:L9)
A10: 81 | B10: PLAN ITALIA S.R.L. | C10: =SUM(D10:L10)
B11: Altamira | C11: =SUM(D11:L11) | F11: =310*1.22 | G11: =310*1.22 | H11: =310*1.22 | I11: =310*1.22 | J11: =310*1.22 | K11: =310*1.22 | L11: =310*1.22
A12: 750195 | B12: Commissioni Transato Pos | C12: =SUM(D12:L12) | F12: 15731.32 | G12: 7362.04 | H12: 813.88
A13: 76 | B13: Soft tecnology | C13: =SUM(D13:L13) | G13: 742.86
A14: 750107 | B14: Commissioni e spese Bancarie Varie(Imposta di bollo/tenuta conto/bonifici/etc ) | C14: =SUM(D14:L14) | H14: 2000
A15: 1076 | B15: Noleggio Tesla | C15: =SUM(D15:L15) | G15: 1030.64
A16: 1276 | B16: Alba Leasing S.P.A. | C16: =SUM(D16:L16)
A17: 137 | B17: Primavera Servizi Srl | C17: =SUM(D17:L17)
A18: 630515 | B18: Polizza Generali | C18: =SUM(D18:L18) | G18: 9000
A19: 52 | B19: Aruba | C19: =SUM(D19:L19) | F19: 14.52 | G19: 12.08
A20: 654 | B20: GOOGLE CLOUD ITALY S.R.L. | C20: =SUM(D20:L20) | F20: 10.58
A21: 1222 | B21: Pietra Di Luna Hotel - S.R.L. | C21: =SUM(D21:L21) | F21: 573.4 | G21: 347.7
C22: =SUM(D22:L22)
C23: =SUM(D23:L23)
C24: =SUM(D24:L24)
C25: =SUM(D25:L25)
C26: =SUM(D26:L26)
C27: =SUM(D27:L27)
C28: =SUM(D28:L28)
C29: =SUM(D29:L29)
C30: =SUM(D30:L30)
C31: =SUM(D31:L31)
C32: =SUM(D32:L32)
C33: =SUM(D33:L33)
... C66: =SUM(D66:L66)

Sheet  Varie ed Eventuali
D1: 2026
A2: CODICE | D2: APRILE | E2: MAGGIO | F2: GIUGNO | G2: LUGLIO | H2: AGOSTO | I2: SETTEMBRE | J2: OTTOBRE | K2: NOVEMBRE | L2: DICEMBRE
B3: Variee ed Eventuali | C3: =SUM(D3:L3) | D3: =SUM(D4:D134) | E3: =SUM(E4:E134) | F3: =SUM(F4:F134) | G3: =SUM(G4:G134) | H3: =SUM(H4:H134) | I3: =SUM(I4:I134) | J3: =SUM(J4:J134) | K3: =SUM(K4:K134) | L3: =SUM(L4:L134)
A4: 801 | B4: A. MIGLIORE S.R.L. | C4: =SUM(D4:L4)
A5: 650107 | B5: Spese Condominiali | C5: =SUM(D5:L5) | F5: 42534.57 | G5: 42534.57
A6: 1080 | B6: AUTOSTRADE PER L'ITALIA S.P.A. | C6: =SUM(D6:L6)
A7: 795 | B7: DEL RISPARMIO | C7: =SUM(D7:L7)
A8: 1625 | B8: EDILIZIA ED | C8: =SUM(D8:L8)
A9: 127 | B9: FEIO S.R.L. | C9: =SUM(D9:L9)
A10: 647 | B10: H & M HENNES & MAURITZ S.R.L. | C10: =SUM(D10:L10)
A11: 1629 | B11: Mana srls | C11: =SUM(D11:L11)
A12: 1626 | B12: ROSANTO S.R.L. | C12: =SUM(D12:L12)
A13: 1638 | B13: CENTRO MODA S.R.L. | C13: =SUM(D13:L13) | F13: 1997.01
A14: 1646 | B14: DIECI S.R.L.S. | C14: =SUM(D14:L14) | F14: 198.01
A15: 1647 | B15: HAIR GALLERY EUROPE SRL | C15: =SUM(D15:L15) | F15: 15.84
A16: 179 | B16: FERRIGNO MARIA C S N C | C16: =SUM(D16:L16)
A17: 744 | B17: Nola Ferramenta Srl | C17: =SUM(D17:L17)
A18: 1036 | B18: Re Denari di Marco Oliva & C. Sas | C18: =SUM(D18:L18)
A19: 70 | B19: MAGALDI LIFE SRL SOC. UNIP. | C19: =SUM(D19:L19) | F19: 206.47
A20: 1696 | B20: READYPRINT DI PIPITONE BRUNO | C20: =SUM(D20:L20)
A21: 170 | B21: Leroy Merlin Italia srl | C21: =SUM(D21:L21) | F21: 81.88
A22: 109 | B22: MEDIAMARKET S.P.A. CON SOCIO UNICO | C22: =SUM(D22:L22) | F22: 213.88
A23: 123 | B23: PREGIS S.P.A. | C23: =SUM(D23:L23)
A24: 1183 | B24: ADRA S.R.L. | C24: =SUM(D24:L24)
A25: 618 | B25: Apple Retail Italia | C25: =SUM(D25:L25) | F25: 22.5
A26: 1724 | B26: D.L. Brothers | C26: =SUM(D26:L26) | F26: 296.56
A27: 1748 | B27: Doctor Spy Societa' A Responsabilita' Limitata | C27: =SUM(D27:L27) | F27: 600
C28: =SUM(D28:L28)
C29: =SUM(D29:L29)
C30: =SUM(D30:L30)
C31: =SUM(D31:L31)
C32: =SUM(D32:L32)
C33: =SUM(D33:L33)
C34: =SUM(D34:L34)
C35: =SUM(D35:L35)
C36: =SUM(D36:L36)
C37: =SUM(D37:L37)
C38: =SUM(D38:L38)
C39: =SUM(D39:L39)
... C68: =SUM(D68:L68)

Sheet DA MAPPARE
A1: Fornitori NON mappati in d_fornitori.csv — assegnare una voce (hotelops fornitori) e rigenerare
A2: Cod | B2: Nome (da export) | C2: GENNAIO | D2: FEBBRAIO | E2: MARZO | F2: APRILE | G2: MAGGIO | H2: GIUGNO | I2: LUGLIO | J2: AGOSTO | K2: SETTEMBRE | L2: OTTOBRE | M2: NOVEMBRE | N2: DICEMBRE
A3: 1758 | B3: BRILY DI AVETA VINCENZO | H3: 14.23
A4: 369 | B4: CREATIVE IDEA S.N.C. DI DE MARTINO DIODATO & C. | I4: 3111
A5: 1765 | B5: Fercolor s.r.l. | H5: 54.39
A6: 1773 | B6: Gruppo Adam s.r.l. | I6: 1499.9
A7: 1768 | B7: I.R.P.S. SRL | H7: 599.5
A8: 231 | B8: Ikea Italia Retail Srl | H8: 1039
A9: 1752 | B9: LO SCOGLIO DEI F.LLI DE SIMONE S.R.L. | H9: 600
A10: 1147 | B10: MINIERI MARIANO | I10: 90.16
A11: 1202 | B11: NILA S.R.L. | H11: 782.2
A12: 1764 | B12: OIP SRL | H12: 44.94
A13: 1759 | B13: PIROTECNICA PLATINUM S.R.L.S | H13: 23.45
A14: 1772 | B14: PROPAC S.R.L. | I14: 124.95
A15: 797 | B15: PUNTOFFICE DI CARDARELLI RITA | H15: 58
A16: 980 | B16: RISTORANTE O PADRONE DO'MARE DI DE SIANO GIACINTO & C. SNC | I16: 178.99
A17: 1762 | B17: SORRENTINO GIOVANNI S.N.C. DI SORRENTINO PASQUALE & C. | H17: 40.9
A18: 1010 | B18: VALLOUFFICIO SOLUZIONI di Zavaglia Nicola & C. S.A.S. | I18: 366
A19: 1755 | B19: VARZI GENERATION SRL | H19: 19.9
A20: 715 | B20: ZURLI MAURIZIO | I20: 196.93

Sheet ESCLUSI
A1: Fornitori ESCLUSI dalla cassa per scelta (is_excluded) — fuori dal saldo proiettato. NON sono un TODO: il motivo è in colonna Motivo.
A2: Cod | B2: Nome (da CSV) | C2: GENNAIO | D2: FEBBRAIO | E2: MARZO | F2: APRILE | G2: MAGGIO | H2: GIUGNO | I2: LUGLIO | J2: AGOSTO | K2: SETTEMBRE | L2: OTTOBRE | M2: NOVEMBRE | N2: DICEMBRE | O2: Motivo
A3: 27 | B3: AL MORO DI ROMAGNOLI ANDREA SAS | I3: 394.98 | O3: escluso da app cashflow
A4: 1745 | B4: POPPITI ALDO | H4: 19.61 | O4: escluso da app cashflow
