Workbook

Sheet Controlli
A1: CONTROLLI PIANO FINANZIARIO — ORTI
A3: 1. SALDO PARTENZA
A4: C4:E4 = saldi iniziali hardcoded (mesi chiusi)? | B4: =IF(OR(_xlfn.ISFORMULA('Piano Finanziario'!C4),_xlfn.ISFORMULA('Piano Finanziario'!D4),_xlfn.ISFORMULA('Piano Finanziario'!E4)),"ERRORE","OK") -> OK
A5: F4 = E37 (luglio parte da saldo reale giugno)? | B5: =IF('Piano Finanziario'!F4='Piano Finanziario'!E37,"OK","ERRORE") -> OK
A6: Catena F4:K4 = mese prec riga 37? | B6: =IF(AND('Piano Finanziario'!F4='Piano Finanziario'!E37,'Piano Finanziario'!G4='Piano Finanziario'!F37,'Piano Finanziario'!H4='Piano Finanziario'!G37,'Piano Finanziario'!I4='Piano Finanziario'!H37,'Piano Finanziario'!J4='Piano Finanziario'!I37,'Piano Finanziario'!K4='Piano Finanziario'!J37),"OK","ERRORE") -> OK
A7: (non applicabile — mesi passati rimossi) | B7: OK
A9: 2. TOTALE ENTRATE (riga 12)
A10: Riga 12 = SUM(6:11) per mesi C:K? | B10: =IF(AND('Piano Finanziario'!C12=SUM('Piano Finanziario'!C6:'Piano Finanziario'!C11),'Piano Finanziario'!D12=SUM('Piano Finanziario'!D6:'Piano Finanziario'!D11),'Piano Finanziario'!E12=SUM('Piano Finanziario'!E6:'Piano Finanziario'!E11),'Piano Finanziario'!F12=SUM('Piano Finanziario'!F6:'Piano Finanziario'!F11),'Piano Finanziario'!G12=SUM('Piano Finanziario'!G6:'Piano Finanziario'!G11),'Piano Finanziario'!H12=SUM('Piano Finanziario'!H6:'Piano Finanziario'!H11),'Piano Finanziario'!I12=SUM('Piano Finanziario'!I6:'Piano Finanziario'!I11),'Piano Finanziario'!J12=SUM('Piano Finanziario'!J6:'Piano Finanziario'!J11),'Piano Finanziario'!K12=SUM('Piano Finanziario'!K6:'Piano Finanziario'!K11)),"OK","ERRORE") -> OK
A12: 3. TOTALE USCITE (riga 27)
A13: Riga 27 = SUM(14:26) per mesi C:K? | B13: =IF(AND('Piano Finanziario'!C27=SUM('Piano Finanziario'!C14:'Piano Finanziario'!C26),'Piano Finanziario'!D27=SUM('Piano Finanziario'!D14:'Piano Finanziario'!D26),'Piano Finanziario'!E27=SUM('Piano Finanziario'!E14:'Piano Finanziario'!E26),'Piano Finanziario'!F27=SUM('Piano Finanziario'!F14:'Piano Finanziario'!F26),'Piano Finanziario'!G27=SUM('Piano Finanziario'!G14:'Piano Finanziario'!G26),'Piano Finanziario'!H27=SUM('Piano Finanziario'!H14:'Piano Finanziario'!H26),'Piano Finanziario'!I27=SUM('Piano Finanziario'!I14:'Piano Finanziario'!I26),'Piano Finanziario'!J27=SUM('Piano Finanziario'!J14:'Piano Finanziario'!J26),'Piano Finanziario'!K27=SUM('Piano Finanziario'!K14:'Piano Finanziario'!K26)),"OK","ERRORE") -> OK
A15: 4. CASH FLOW (riga 29)
A16: Riga 29 = Entrate - Uscite per mesi C:K? | B16: =IF(AND('Piano Finanziario'!C29='Piano Finanziario'!C12-'Piano Finanziario'!C27,'Piano Finanziario'!D29='Piano Finanziario'!D12-'Piano Finanziario'!D27,'Piano Finanziario'!E29='Piano Finanziario'!E12-'Piano Finanziario'!E27,'Piano Finanziario'!F29='Piano Finanziario'!F12-'Piano Finanziario'!F27,'Piano Finanziario'!G29='Piano Finanziario'!G12-'Piano Finanziario'!G27,'Piano Finanziario'!H29='Piano Finanziario'!H12-'Piano Finanziario'!H27,'Piano Finanziario'!I29='Piano Finanziario'!I12-'Piano Finanziario'!I27,'Piano Finanziario'!J29='Piano Finanziario'!J12-'Piano Finanziario'!J27,'Piano Finanziario'!K29='Piano Finanziario'!K12-'Piano Finanziario'!K27),"OK","ERRORE") -> OK
A21: 6. RIFERIMENTI USCITE — FOGLI DETTAGLIO (mesi I:R)
A22: Riga 14 — Salari e Stipendi | B22: =IF(AND('Piano Finanziario'!C14='Salari e Stipendi'!D4,'Piano Finanziario'!D14='Salari e Stipendi'!E4,'Piano Finanziario'!E14='Salari e Stipendi'!F4,'Piano Finanziario'!F14='Salari e Stipendi'!G4,'Piano Finanziario'!G14='Salari e Stipendi'!H4,'Piano Finanziario'!H14='Salari e Stipendi'!I4,'Piano Finanziario'!I14='Salari e Stipendi'!J4,'Piano Finanziario'!J14='Salari e Stipendi'!K4,'Piano Finanziario'!K14='Salari e Stipendi'!L4),"OK","ERRORE") -> OK
A23: Riga 15 — Utenze | B23: =IF(AND('Piano Finanziario'!C15=Utenze!D3,'Piano Finanziario'!D15=Utenze!E3,'Piano Finanziario'!E15=Utenze!F3,'Piano Finanziario'!F15=Utenze!G3,'Piano Finanziario'!G15=Utenze!H3,'Piano Finanziario'!H15=Utenze!I3,'Piano Finanziario'!I15=Utenze!J3,'Piano Finanziario'!J15=Utenze!K3,'Piano Finanziario'!K15=Utenze!L3),"OK","ERRORE") -> OK
A24: Riga 16 — Materie Prime/Consumo | B24: =IF(AND('Piano Finanziario'!C16=MAX('Materie Prime-Consumo '!D3,'Materie Prime-Consumo '!D4),'Piano Finanziario'!D16=MAX('Materie Prime-Consumo '!E3,'Materie Prime-Consumo '!E4),'Piano Finanziario'!E16=MAX('Materie Prime-Consumo '!F3,'Materie Prime-Consumo '!F4),'Piano Finanziario'!F16=MAX('Materie Prime-Consumo '!G3,'Materie Prime-Consumo '!G4),'Piano Finanziario'!G16=MAX('Materie Prime-Consumo '!H3,'Materie Prime-Consumo '!H4),'Piano Finanziario'!H16=MAX('Materie Prime-Consumo '!I3,'Materie Prime-Consumo '!I4),'Piano Finanziario'!I16=MAX('Materie Prime-Consumo '!J3,'Materie Prime-Consumo '!J4),'Piano Finanziario'!J16=MAX('Materie Prime-Consumo '!K3,'Materie Prime-Consumo '!K4),'Piano Finanziario'!K16=MAX('Materie Prime-Consumo '!L3,'Materie Prime-Consumo '!L4)),"OK","ERRORE") -> OK
A25: Riga 17 — Tasse e Imposte | B25: =IF(AND('Piano Finanziario'!C17='Tasse e Imposte'!D3,'Piano Finanziario'!D17='Tasse e Imposte'!E3,'Piano Finanziario'!E17='Tasse e Imposte'!F3,'Piano Finanziario'!F17='Tasse e Imposte'!G3,'Piano Finanziario'!G17='Tasse e Imposte'!H3,'Piano Finanziario'!H17='Tasse e Imposte'!I3,'Piano Finanziario'!I17='Tasse e Imposte'!J3,'Piano Finanziario'!J17='Tasse e Imposte'!K3,'Piano Finanziario'!K17='Tasse e Imposte'!L3),"OK","ERRORE") -> OK
A26: Riga 18 — Commissioni Portali | B26: =IF(AND('Piano Finanziario'!C18='Commisisoni Portali'!D3,'Piano Finanziario'!D18='Commisisoni Portali'!E3,'Piano Finanziario'!E18='Commisisoni Portali'!F3,'Piano Finanziario'!F18='Commisisoni Portali'!G3,'Piano Finanziario'!G18='Commisisoni Portali'!H3,'Piano Finanziario'!H18='Commisisoni Portali'!I3,'Piano Finanziario'!I18='Commisisoni Portali'!J3,'Piano Finanziario'!J18='Commisisoni Portali'!K3,'Piano Finanziario'!K18='Commisisoni Portali'!L3),"OK","ERRORE") -> OK
A27: Riga 19 — Mutui e Finanziamenti | B27: =IF(AND('Piano Finanziario'!C19='Mutui e Finaziamenti'!D3,'Piano Finanziario'!D19='Mutui e Finaziamenti'!E3,'Piano Finanziario'!E19='Mutui e Finaziamenti'!F3,'Piano Finanziario'!F19='Mutui e Finaziamenti'!G3,'Piano Finanziario'!G19='Mutui e Finaziamenti'!H3,'Piano Finanziario'!H19='Mutui e Finaziamenti'!I3,'Piano Finanziario'!I19='Mutui e Finaziamenti'!J3,'Piano Finanziario'!J19='Mutui e Finaziamenti'!K3,'Piano Finanziario'!K19='Mutui e Finaziamenti'!L3),"OK","ERRORE") -> OK
A28: Riga 20 — Consulenze | B28: =IF(AND('Piano Finanziario'!C20=Consulenze!D3,'Piano Finanziario'!D20=Consulenze!E3,'Piano Finanziario'!E20=Consulenze!F3,'Piano Finanziario'!F20=Consulenze!G3,'Piano Finanziario'!G20=Consulenze!H3,'Piano Finanziario'!H20=Consulenze!I3,'Piano Finanziario'!I20=Consulenze!J3,'Piano Finanziario'!J20=Consulenze!K3,'Piano Finanziario'!K20=Consulenze!L3),"OK","ERRORE") -> OK
A29: Riga 21 — Godimento Beni di Terzi | B29: =IF(AND('Piano Finanziario'!C21='Godimento Beni di Terzi'!D4,'Piano Finanziario'!D21='Godimento Beni di Terzi'!E4,'Piano Finanziario'!E21='Godimento Beni di Terzi'!F4,'Piano Finanziario'!F21='Godimento Beni di Terzi'!G4,'Piano Finanziario'!G21='Godimento Beni di Terzi'!H4,'Piano Finanziario'!H21='Godimento Beni di Terzi'!I4,'Piano Finanziario'!I21='Godimento Beni di Terzi'!J4,'Piano Finanziario'!J21='Godimento Beni di Terzi'!K4,'Piano Finanziario'!K21='Godimento Beni di Terzi'!L4),"OK","ERRORE") -> OK
A30: Riga 22 — Varie ed Eventuali | B30: =IF(AND('Piano Finanziario'!C22=' Varie ed Eventuali'!D3,'Piano Finanziario'!D22=' Varie ed Eventuali'!E3,'Piano Finanziario'!E22=' Varie ed Eventuali'!F3,'Piano Finanziario'!F22=' Varie ed Eventuali'!G3,'Piano Finanziario'!G22=' Varie ed Eventuali'!H3,'Piano Finanziario'!H22=' Varie ed Eventuali'!I3,'Piano Finanziario'!I22=' Varie ed Eventuali'!J3,'Piano Finanziario'!J22=' Varie ed Eventuali'!K3,'Piano Finanziario'!K22=' Varie ed Eventuali'!L3),"OK","ERRORE") -> OK
A31: Riga 23 — Canoni e servizi | B31: =IF(AND('Piano Finanziario'!C23='Canoni e servizi'!D4,'Piano Finanziario'!D23='Canoni e servizi'!E4,'Piano Finanziario'!E23='Canoni e servizi'!F4,'Piano Finanziario'!F23='Canoni e servizi'!G4,'Piano Finanziario'!G23='Canoni e servizi'!H4,'Piano Finanziario'!H23='Canoni e servizi'!I4,'Piano Finanziario'!I23='Canoni e servizi'!J4,'Piano Finanziario'!J23='Canoni e servizi'!K4,'Piano Finanziario'!K23='Canoni e servizi'!L4),"OK","ERRORE") -> OK
A33: 7. SALDO PROIETTATO (riga 37)
A34: Riga 37 = riga 4 + riga 29 per mesi attivi I:R? | B34: =IF(AND('Piano Finanziario'!C37='Piano Finanziario'!C4+'Piano Finanziario'!C29,'Piano Finanziario'!D37='Piano Finanziario'!D4+'Piano Finanziario'!D29,'Piano Finanziario'!E37='Piano Finanziario'!E4+'Piano Finanziario'!E29,'Piano Finanziario'!F37='Piano Finanziario'!F4+'Piano Finanziario'!F29,'Piano Finanziario'!G37='Piano Finanziario'!G4+'Piano Finanziario'!G29,'Piano Finanziario'!H37='Piano Finanziario'!H4+'Piano Finanziario'!H29,'Piano Finanziario'!I37='Piano Finanziario'!I4+'Piano Finanziario'!I29,'Piano Finanziario'!J37='Piano Finanziario'!J4+'Piano Finanziario'!J29,'Piano Finanziario'!K37='Piano Finanziario'!K4+'Piano Finanziario'!K29),"OK","ERRORE") -> OK
A36: 8. CASH FLOW CON AFFIDAMENTI (riga 45)
A37: Riga 45 = riga 37 + riga 43 per mesi attivi I:R? | B37: =IF(AND('Piano Finanziario'!C45='Piano Finanziario'!C37+'Piano Finanziario'!C43,'Piano Finanziario'!D45='Piano Finanziario'!D37+'Piano Finanziario'!D43,'Piano Finanziario'!E45='Piano Finanziario'!E37+'Piano Finanziario'!E43,'Piano Finanziario'!F45='Piano Finanziario'!F37+'Piano Finanziario'!F43,'Piano Finanziario'!G45='Piano Finanziario'!G37+'Piano Finanziario'!G43,'Piano Finanziario'!H45='Piano Finanziario'!H37+'Piano Finanziario'!H43,'Piano Finanziario'!I45='Piano Finanziario'!I37+'Piano Finanziario'!I43,'Piano Finanziario'!J45='Piano Finanziario'!J37+'Piano Finanziario'!J43,'Piano Finanziario'!K45='Piano Finanziario'!K37+'Piano Finanziario'!K43),"OK","ERRORE") -> OK
A39: 9. COLONNA TOTALI (T)
A40: L12 Totale Entrate = SUM(C12:K12)? | B40: =IF('Piano Finanziario'!L12=SUM('Piano Finanziario'!C12:'Piano Finanziario'!K12),"OK","ERRORE") -> ERRORE
A41: L27 Totale Uscite = SUM(C27:K27)? | B41: =IF('Piano Finanziario'!L27=SUM('Piano Finanziario'!C27:'Piano Finanziario'!K27),"OK","ERRORE") -> ERRORE
A42: L29 Cash Flow = L12 - L27? | B42: =IF('Piano Finanziario'!L29='Piano Finanziario'!L12-'Piano Finanziario'!L27,"OK","ERRORE") -> OK
A44: =CONCATENATE("RISULTATO COMPLESSIVO") -> RISULTATO COMPLESSIVO | B44: =IF(COUNTIF(B4:B42,"ERRORE")=0,"✓ TUTTI I "&COUNTA(B4:B42)&" CONTROLLI OK","✗ "&COUNTIF(B4:B42,"ERRORE")&" ERRORI TROVATI su "&COUNTA(B4:B42)&" verifiche") -> ✗ 2 ERRORI TROVATI su 22 verifiche

Sheet Piano Finanziario
A1: ORTI S.R.L. | C1: 2026 | L1: 2027
C2: APRILE | D2: MAGGIO | E2: GIUGNO | F2: LUGLIO | G2: AGOSTO | H2: SETTEMBRE | I2: OTTOBRE | J2: NOVEMBRE | K2: DICEMBRE | L2: GENNAIO | M2: FEBBRAIO | N2: MARZO | O2: APRILE | P2: MAGGIO | Q2: GIUGNO | R2: TOTALI
A4: SALDO MESE PRECED | C4: 339337.46 | D4: 581125.86 | E4: 863258.63 | F4: =E37 -> 863258.63 | G4: =F37 -> 891491.2 | H4: =G37 -> 1406533.6 | I4: =H37 -> 1643733.1 | J4: =I37 -> 1372057 | K4: =J37 -> 952782.05 | L4: =K37 -> -120323.95 | M4: =L37 -> -120702.15 | ... Q4: =P37 -> -122214.95
A6: Entrate Hotel | F6: 750000 | G6: 830000 | H6: 580000 | I6: =110000+160000 -> 270000 | R6: =SUM(C6:Q6) -> 2430000
A7: Entrate Residence | F7: 120000 | G7: 140000 | H7: 100000 | I7: =26000+17000 -> 43000 | R7: =SUM(C7:Q7) -> 403000
A8: Entrate CVM | F8: 45000 | G8: 48000 | H8: 30000 | I8: =5798+10000 -> 15798 | R8: =SUM(C8:Q8) -> 138798
A9: Entrate Supermercato | F9: 25620 | G9: 25620 | H9: 25620 | I9: 25620 | J9: 25620 | K9: 25620 | R9: =SUM(C9:Q9) -> 153720
A10: Rientro Sospesi | R10: =SUM(C10:Q10) -> 0
A11: Caparre Intur | R11: =SUM(C11:Q11) -> 0
A12: TOTALE ENTRATE | C12: =SUM(C6:C11) -> 0 | D12: =SUM(D6:D11) -> 0 | E12: =SUM(E6:E11) -> 0 | F12: =SUM(F6:F11) -> 940620 | G12: =SUM(G6:G11) -> 1043620 | H12: =SUM(H6:H11) -> 735620 | I12: =SUM(I6:I11) -> 354418 | J12: =SUM(J6:J11) -> 25620 | ... Q12: =SUM(Q6:Q11) -> 0 | R12: =SUM(C12:Q12) -> 3125518
A14: Salari e Stipendi | C14: ='Salari e Stipendi'!D4 -> 0 | D14: ='Salari e Stipendi'!E4 -> 0 | E14: ='Salari e Stipendi'!F4 -> 0 | F14: ='Salari e Stipendi'!G4 -> 153671.34 | G14: ='Salari e Stipendi'!H4 -> 155000 | H14: ='Salari e Stipendi'!I4 -> 140000 | I14: ='Salari e Stipendi'!J4 -> 115000 | J14: ='Salari e Stipendi'!K4 -> 175000 | ... Q14: ='Salari e Stipendi'!R4 -> 0 | R14: =SUM(C14:Q14) -> 796671.34
A15: Utenze | C15: =Utenze!D3 -> 0 | D15: =Utenze!E3 -> 0 | E15: =Utenze!F3 -> 0 | F15: =Utenze!G3 -> 34025.61 | G15: =Utenze!H3 -> 40779.02 | H15: =Utenze!I3 -> 25500 | I15: =Utenze!J3 -> 27000 | J15: =Utenze!K3 -> 26500 | ... Q15: =Utenze!R3 -> 0 | R15: =SUM(C15:Q15) -> 190804.63
A16: Materie Prime/Consumo | C16: =MAX('Materie Prime-Consumo '!D3,'Materie Prime-Consumo '!D4) -> 0 | D16: =MAX('Materie Prime-Consumo '!E3,'Materie Prime-Consumo '!E4) -> 0 | E16: =MAX('Materie Prime-Consumo '!F3,'Materie Prime-Consumo '!F4) -> 0 | F16: =MAX('Materie Prime-Consumo '!G3,'Materie Prime-Consumo '!G4) -> 120000 | G16: =MAX('Materie Prime-Consumo '!H3,'Materie Prime-Consumo '!H4) -> 145000 | H16: =MAX('Materie Prime-Consumo '!I3,'Materie Prime-Consumo '!I4) -> 140000 | I16: =MAX('Materie Prime-Consumo '!J3,'Materie Prime-Consumo '!J4) -> 135000 | J16: =MAX('Materie Prime-Consumo '!K3,'Materie Prime-Consumo '!K4) -> 75000 | ... Q16: =MAX('Materie Prime-Consumo '!R3,'Materie Prime-Consumo '!R4) -> 0 | R16: =SUM(C16:Q16) -> 675000
A17: Tasse e Imposte | C17: ='Tasse e Imposte'!D3 -> 0 | D17: ='Tasse e Imposte'!E3 -> 0 | E17: ='Tasse e Imposte'!F3 -> 0 | F17: ='Tasse e Imposte'!G3 -> 95437.2 | G17: ='Tasse e Imposte'!H3 -> 48571.24 | H17: ='Tasse e Imposte'!I3 -> 133000.94 | I17: ='Tasse e Imposte'!J3 -> 55260.64 | J17: ='Tasse e Imposte'!K3 -> 82590.34 | ... Q17: ='Tasse e Imposte'!R3 -> 0 | R17: =SUM(C17:Q17) -> 414860.36
A18: Commissioni Portali | C18: ='Commisisoni Portali'!D3 -> 0 | D18: ='Commisisoni Portali'!E3 -> 0 | E18: ='Commisisoni Portali'!F3 -> 0 | F18: ='Commisisoni Portali'!G3 -> 43897 | G18: ='Commisisoni Portali'!H3 -> 44300 | H18: ='Commisisoni Portali'!I3 -> 10500 | I18: ='Commisisoni Portali'!J3 -> 28000 | J18: ='Commisisoni Portali'!K3 -> 14000 | ... Q18: ='Commisisoni Portali'!R3 -> 0 | R18: =SUM(C18:Q18) -> 148897
A19: Mutui e Finaziamenti | C19: ='Mutui e Finaziamenti'!D3 -> 0 | D19: ='Mutui e Finaziamenti'!E3 -> 0 | E19: ='Mutui e Finaziamenti'!F3 -> 0 | F19: ='Mutui e Finaziamenti'!G3 -> 13659.3 | G19: ='Mutui e Finaziamenti'!H3 -> 13658.59 | H19: ='Mutui e Finaziamenti'!I3 -> 13627.32 | I19: ='Mutui e Finaziamenti'!J3 -> 13657.16 | J19: ='Mutui e Finaziamenti'!K3 -> 13628.34 | ... Q19: ='Mutui e Finaziamenti'!R3 -> 0 | R19: =SUM(C19:Q19) -> 248062.43
A20: Consulenze | C20: =Consulenze!D3 -> 0 | D20: =Consulenze!E3 -> 0 | E20: =Consulenze!F3 -> 0 | F20: =Consulenze!G3 -> 24754.8 | G20: =Consulenze!H3 -> 3416 | H20: =Consulenze!I3 -> 27616 | I20: =Consulenze!J3 -> 0 | J20: =Consulenze!K3 -> 0 | ... Q20: =Consulenze!R3 -> 0 | R20: =SUM(C20:Q20) -> 55786.8
A21: Godimento Beni di Terzi | C21: ='Godimento Beni di Terzi'!D4 -> 0 | D21: ='Godimento Beni di Terzi'!E4 -> 0 | E21: ='Godimento Beni di Terzi'!F4 -> 0 | F21: ='Godimento Beni di Terzi'!G4 -> 404000 | G21: ='Godimento Beni di Terzi'!H4 -> 60000 | H21: ='Godimento Beni di Terzi'!I4 -> 0 | I21: ='Godimento Beni di Terzi'!J4 -> 244000 | J21: ='Godimento Beni di Terzi'!K4 -> 50000 | ... Q21: ='Godimento Beni di Terzi'!R4 -> 0 | R21: =SUM(C21:Q21) -> 1488918
A22: Varie ed Eventuali | C22: =' Varie ed Eventuali'!D3 -> 0 | D22: =' Varie ed Eventuali'!E3 -> 0 | E22: =' Varie ed Eventuali'!F3 -> 0 | F22: =' Varie ed Eventuali'!G3 -> 3731.7 | G22: =' Varie ed Eventuali'!H3 -> 13534.88 | H22: =' Varie ed Eventuali'!I3 -> 6767.44 | I22: =' Varie ed Eventuali'!J3 -> 6767.44 | J22: =' Varie ed Eventuali'!K3 -> 6767.44 | ... Q22: =' Varie ed Eventuali'!R3 -> 0 | R22: =SUM(C22:Q22) -> 44336.34
A23: Canoni e servizi | C23: ='Canoni e servizi'!D4 -> 0 | D23: ='Canoni e servizi'!E4 -> 0 | E23: ='Canoni e servizi'!F4 -> 0 | F23: ='Canoni e servizi'!G4 -> 19210.48 | G23: ='Canoni e servizi'!H4 -> 4317.84 | H23: ='Canoni e servizi'!I4 -> 1408.84 | I23: ='Canoni e servizi'!J4 -> 1408.84 | J23: ='Canoni e servizi'!K4 -> 1408.84 | ... Q23: ='Canoni e servizi'!R4 -> 378.2 | R23: =SUM(C23:Q23) -> 48032.88
A24: Deposito Fitto | R24: =SUM(C24:Q24) -> 0
A27: TOTALE USCITE | C27: =SUM(C14:C26) -> 0 | D27: =SUM(D14:D26) -> 0 | E27: =SUM(E14:E26) -> 0 | F27: =SUM(F14:F26) -> 912387.43 | G27: =SUM(G14:G26) -> 528577.57 | H27: =SUM(H14:H26) -> 498420.54 | I27: =SUM(I14:I26) -> 626094.08 | J27: =SUM(J14:J26) -> 444894.96 | ... Q27: =SUM(Q14:Q26) -> 378.2 | R27: =SUM(C27:Q27) -> 4111369.8
A29: Cash Flow | C29: =C12-C27 -> 0 | D29: =D12-D27 -> 0 | E29: =E12-E27 -> 0 | F29: =F12-F27 -> 28232.57 | G29: =G12-G27 -> 515042.43 | H29: =H12-H27 -> 237199.46 | I29: =I12-I27 -> -271676.08 | J29: =J12-J27 -> -419274.96 | ... R29: =R12-R27 -> -985851.78
A31: 30/04/2026 | C31: 30/04/2026 | D31: 31/05/2026 | E31: 30/06/2026
A32: Saldo MPS | B32: 30/06/2026 | C32: 726,946.18 € | D32: 469192.55 | E32: 726946.18
A33: Saldo Intesa | C33: 136,312.45 € | D33: 111933.31 | E33: 136312.45
A35: TOTALE BANCHE | C35: =SUM(C32:C34) -> 0
A37: Saldo di Periodo/Proiettato | C37: =C4+C29 -> 339337.46 | D37: =D4+D29 -> 581125.86 | E37: =E4+E29 -> 863258.63 | F37: =F4+F29 -> 891491.2 | G37: =G4+G29 -> 1406533.6 | H37: =H4+H29 -> 1643733.1 | I37: =I4+I29 -> 1372057 | J37: =J4+J29 -> 952782.05 | ... Q37: =Q4+Q29 -> -122593.15 | R37: =Q37 -> -122593.15
A39: Fin. MPS 60 mesi | C39: 0 | D39: 0 | E39: 0 | F39: 0 | G39: 0 | H39: 0 | I39: 0 | J39: 0 | K39: 0
A43: TOTALE AFFIDAMENTI | C43: =SUM(C39:C42) -> 0 | D43: =SUM(D39:D42) -> 0 | E43: =SUM(E39:E42) -> 0 | F43: =SUM(F39:F42) -> 0 | G43: =SUM(G39:G42) -> 0 | H43: =SUM(H39:H42) -> 0 | I43: =SUM(I39:I42) -> 0 | J43: =SUM(J39:J42) -> 0 | ... Q43: =SUM(Q39:Q42) -> 0 | R43: =SUM(C43:Q43) -> 0
A45: CASH FLOW CON AFFID. | C45: =C37+C43 -> 339337.46 | D45: =D37+D43 -> 581125.86 | E45: =E37+E43 -> 863258.63 | F45: =F37+F43 -> 891491.2 | G45: =G37+G43 -> 1406533.6 | H45: =H37+H43 -> 1643733.1 | I45: =I37+I43 -> 1372057 | J45: =J37+J43 -> 952782.05 | ... Q45: =Q37+Q43 -> -122593.15 | R45: =Q45 -> -122593.15

Sheet Salari e Stipendi
D1: 2026 | M1: 2027
A2: CODICE | D2: APRILE | E2: MAGGIO | F2: GIUGNO | G2: LUGLIO | H2: AGOSTO | I2: SETTEMBRE | J2: OTTOBRE | K2: NOVEMBRE | L2: DICEMBRE | M2: GENNAIO | N2: FEBBRAIO | O2: MARZO | P2: APRILE | Q2: MAGGIO | R2: GIUGNO
B4: Salari e Stipendi | C4: =SUM(D4:L4) -> 796671.34 | D4: =SUM(D5:D135) -> 0 | E4: =SUM(E5:E135) -> 0 | F4: =SUM(F5:F135) -> 0 | G4: =SUM(G5:G135) -> 153671.34 | H4: =SUM(H5:H135) -> 155000 | I4: =SUM(I5:I135) -> 140000 | J4: =SUM(J5:J135) -> 115000 | K4: =SUM(K5:K135) -> 175000 | ... R4: =SUM(R5:R135) -> 0
A5: 670101 | B5: SALARI | C5: =SUM(D5:L5) -> 519171.34 | G5: 94171.34 | H5: 95000 | I5: 90000 | J5: 80000 | K5: 120000 | L5: 40000
A6: 350301 | B6: F24 | C6: =SUM(D6:L6) -> 277500 | G6: 59500 | H6: 60000 | I6: 50000 | J6: 35000 | K6: 55000 | L6: 18000
C7: =SUM(D7:L7) -> 0
C8: =SUM(D8:L8) -> 0
C9: =SUM(D9:L9) -> 0
C10: =SUM(D10:L10) -> 0
C11: =SUM(D11:L11) -> 0
C12: =SUM(D12:L12) -> 0
C13: =SUM(D13:L13) -> 0
C14: =SUM(D14:L14) -> 0
C15: =SUM(D15:L15) -> 0
C16: =SUM(D16:L16) -> 0
C17: =SUM(D17:L17) -> 0
C18: =SUM(D18:L18) -> 0
... C69: =SUM(D69:L69) -> 0

Sheet Utenze
D1: 2026 | M1: 2027
A2: CODICE | D2: APRILE | E2: MAGGIO | F2: GIUGNO | G2: LUGLIO | H2: AGOSTO | I2: SETTEMBRE | J2: OTTOBRE | K2: NOVEMBRE | L2: DICEMBRE | M2: GENNAIO | N2: FEBBRAIO | O2: MARZO | P2: APRILE | Q2: MAGGIO | R2: GIUGNO
B3: Utenze | C3: =SUM(D3:L3) -> 190804.63 | D3: =SUM(D4:D134) -> 0 | E3: =SUM(E4:E134) -> 0 | F3: =SUM(F4:F134) -> 0 | G3: =SUM(G4:G134) -> 34025.61 | H3: =SUM(H4:H134) -> 40779.02 | I3: =SUM(I4:I134) -> 25500 | J3: =SUM(J4:J134) -> 27000 | K3: =SUM(K4:K134) -> 26500 | ... R3: =SUM(R4:R134) -> 0
A4: 570913 | B4: Energia elettrica | C4: =SUM(D4:L4) -> 139161.54 | G4: 27525.61 | H4: =635.93+28000 -> 28635.93 | I4: 19000 | J4: 17000 | K4: 20000 | L4: 27000
A5: 570919 | B5: Gas | C5: =SUM(D5:L5) -> 39000 | G5: 6500 | H5: 6500 | I5: 6500 | J5: 6500 | K5: 6500 | L5: 6500
A6: 18 | B6: Acqua - Ausino | C6: =SUM(D6:L6) -> 2143.09 | H6: 2143.09
A7: 44 | B7: Vodafone (intur) | C7: =SUM(D7:L7) -> 0
A8: 570909 | B8: Connectivia | C8: =SUM(D8:L8) -> 10500 | H8: 3500 | J8: 3500 | L8: 3500
C9: =SUM(D9:L9) -> 0
C10: =SUM(D10:L10) -> 0
C11: =SUM(D11:L11) -> 0
C12: =SUM(D12:L12) -> 0
C13: =SUM(D13:L13) -> 0
C14: =SUM(D14:L14) -> 0
C15: =SUM(D15:L15) -> 0
C16: =SUM(D16:L16) -> 0
C17: =SUM(D17:L17) -> 0
C18: =SUM(D18:L18) -> 0
C19: =SUM(D19:L19) -> 0
C20: =SUM(D20:L20) -> 0
... C68: =SUM(D68:L68) -> 0

Sheet Materie Prime-Consumo 
D1: 2026 | M1: 2027
A2: CODICE | D2: APRILE | E2: MAGGIO | F2: GIUGNO | G2: LUGLIO | H2: AGOSTO | I2: SETTEMBRE | J2: OTTOBRE | K2: NOVEMBRE | L2: DICEMBRE | M2: GENNAIO | N2: FEBBRAIO | O2: MARZO | P2: APRILE | Q2: MAGGIO | R2: GIUGNO
B3: PREVISIONALE | C3: =SUM(D3:L3) -> 675000 | G3: 120000 | H3: 145000 | I3: 140000 | J3: 135000 | K3: 75000 | L3: 60000
B4: Materie Prime e Consumo | C4: =SUM(D4:L4) -> 206026.2 | D4: =SUM(D5:D184) -> 0 | E4: =SUM(E5:E184) -> 0 | F4: =SUM(F5:F184) -> 0 | G4: =SUM(G5:G184) -> 71238.46 | H4: =SUM(H5:H184) -> 76677.59 | I4: =SUM(I5:I184) -> 38647.56 | J4: =SUM(J5:J184) -> 19426.94 | K4: =SUM(K5:K184) -> 35.65 | ... R4: =SUM(R5:R184) -> 0
A5: 801 | B5: A. Migliore srl | C5: =SUM(D5:L5) -> 0
A6: 281 | B6: Abiti da lavoro Cavaliere srls | C6: =SUM(D6:L6) -> 0
A7: 1183 | B7: Adra srl | C7: =SUM(D7:L7) -> 1830.18 | H7: 839.47 | I7: 990.71
A8: 412 | B8: Alberto D'Urso | C8: =SUM(D8:L8) -> 761.92 | G8: 761.92
A9: 1589 | B9: Alnumar di Garofalo Massimiliano | C9: =SUM(D9:L9) -> 3816.25 | G9: 1920.41 | H9: 1895.84
A10: 92 | B10: Amalfi sei esse | C10: =SUM(D10:L10) -> 34429.33 | G10: 6384.75 | H10: 6825.63 | I10: 9528.63 | J10: 11654.67 | K10: 35.65
A11: 1720 | B11: Amalfi ghiaccio | C11: =SUM(D11:L11) -> 0
A12: 131 | B12: Amalfi Web | C12: =SUM(D12:L12) -> 0
A13: 147 | B13: Amato Filippo | C13: =SUM(D13:L13) -> 0
A14: 325 | B14: Alfera srl | C14: =SUM(D14:L14) -> 5236.01 | H14: 2260 | I14: 2976.01
A15: 916 | B15: Allestimenti Di Palo | C15: =SUM(D15:L15) -> 0
A16: 790 | B16: Amato Prisco pane | C16: =SUM(D16:L16) -> 474.24 | G16: 474.24
A17: 1260 | B17: Aniello Bisogno & Figli | C17: =SUM(D17:L17) -> 0
A18: 667 | B18: Attianese Frutta e Verdura | C18: =SUM(D18:L18) -> 0
A19: 1298 | B19: Apicella Lorenzo | C19: =SUM(D19:L19) -> 0
A20: 758 | B20: B&G Di Palo Commercio | C20: =SUM(D20:L20) -> 0
A21: 74 | B21: Bellagaia | C21: =SUM(D21:L21) -> 14310.64 | G21: 8248.92 | H21: 6061.72
A22: 399 | B22: Campitiello Fabio | C22: =SUM(D22:L22) -> 0
A23: 864 | B23: Capuano Raffaele | C23: =SUM(D23:L23) -> 0
A24: 208 | B24: Casa Vinicola Sammarco | C24: =SUM(D24:L24) -> 2745.35 | G24: 666.12 | H24: 1141.92 | I24: 937.31
A25: 1137 | B25: Coccorullo Falegnamenria | C25: =SUM(D25:L25) -> 0
A26: 125 | B26: Centro Distribuzione Maglio | C26: =SUM(D26:L26) -> 3093.2 | G26: 1588.4 | H26: 1504.8
A27: 315 | B27: Centro service Snc | C27: =SUM(D27:L27) -> 513.62 | H27: 513.62
A28: 423 | B28: Cica | C28: =SUM(D28:L28) -> 5117.69 | G28: 2062.02 | H28: 2834.35 | I28: 221.32
A29: 417 | B29: Cimmini Filomena | C29: =SUM(D29:L29) -> 0
A30: 369 | B30: Creative Idea | C30: =SUM(D30:L30) -> 0
A31: 1003 | B31: Ditta Pansa | C31: =SUM(D31:L31) -> 0
A32: 226 | B32: De Luca | C32: =SUM(D32:L32) -> 0
A33: 7 | B33: DG Network | C33: =SUM(D33:L33) -> 0
A34: 161 | B34: Di Sarno Coffee | C34: =SUM(D34:L34) -> 14555.98 | G34: 8248.04 | H34: 6307.94
A35: 32 | B35: Ditta Apicella | C35: =SUM(D35:L35) -> 0
A36: 1003 | B36: Ditta Pansa | C36: =SUM(D36:L36) -> 0
A37: 133 | B37: Fabbrocino Michele | C37: =SUM(D37:L37) -> 24378.92 | G37: 3183.82 | H37: 9238 | I37: 10345.23 | J37: 1611.87
A38: 672 | B38: Barela Farmacia | C38: =SUM(D38:L38) -> 0
A39: 127 | B39: Feio Srl | C39: =SUM(D39:L39) -> 0
A40: 179 | B40: Ferrigno Maria | C40: =SUM(D40:L40) -> 0
...

Sheet Tasse e Imposte
D1: 2026 | M1: 2027
A2: CODICE | D2: APRILE | E2: MAGGIO | F2: GIUGNO | G2: LUGLIO | H2: AGOSTO | I2: SETTEMBRE | J2: OTTOBRE | K2: NOVEMBRE | L2: DICEMBRE | M2: GENNAIO | N2: FEBBRAIO | O2: MARZO | P2: APRILE | Q2: MAGGIO | R2: GIUGNO
B3: Tasse e Imposte | C3: =SUM(D3:L3) -> 414860.36 | D3: =SUM(D4:D136) -> 0 | E3: =SUM(E4:E136) -> 0 | F3: =SUM(F4:F136) -> 0 | G3: =SUM(G4:G136) -> 95437.2 | H3: =SUM(H4:H136) -> 48571.24 | I3: =SUM(I4:I136) -> 133000.94 | J3: =SUM(J4:J136) -> 55260.64 | K3: =SUM(K4:K136) -> 82590.34 | ... R3: =SUM(R4:R136) -> 0
A4: 710104 | B4: IMU | C4: =SUM(D4:L4) -> 0
A5: 630511 | B5: IMPOSTE | C5: =SUM(D5:L5) -> 167514.36 | G5: 24151.2 | H5: 24221.24 | I5: 24300.94 | J5: 24380.64 | K5: =24460.34+46000 -> 70460.34 | M5: NOVEMBRE I ACCONTO E II ACCONTO TOTALI
A6: 630519 | B6: TARI HOTEL | C6: =SUM(D6:L6) -> 85000 | G6: 0 | I6: 85000
A7: 350101 | B7: IVA | C7: =SUM(D7:L7) -> 60000 | G7: 50000 | J7: 10000
A8: 350305 | B8: RITENUTE PROFESSIONISTI (1040)
A9: 390590 | B9: IMPOSTA DI SOGGIORNO HP | C9: =SUM(D9:L9) -> 84796 | G9: 18296 | H9: 20000 | I9: 19000 | J9: 17500 | K9: 10000
B10: IMPOSTA DI SOGGIORNO AR | C10: =SUM(D10:L10) -> 10844 | G10: 1834 | H10: 2900 | I10: 2700 | J10: 2030 | K10: 1380
A11: 390593 | B11: IMPOSTA DI SOGGIORNO CVM | C11: =SUM(D11:L11) -> 5784 | G11: 934 | H11: 1100 | I11: 1800 | J11: 1200 | K11: 750
B12: IMPOSTA DI SOGGIORNO APT | C12: =SUM(D12:L12) -> 922 | G12: 222 | H12: 350 | I12: 200 | J12: 150
A13: 630519 | B13: TARI RESIDENCE | C13: =SUM(D13:L13) -> 0
B14: TARI CVM | C14: =SUM(D14:L14) -> 0
B15: IRES/IRAP | C15: =SUM(D15:L15) -> 0
C16: =SUM(D16:L16) -> 0
C17: =SUM(D17:L17) -> 0
C18: =SUM(D18:L18) -> 0
C19: =SUM(D19:L19) -> 0
C20: =SUM(D20:L20) -> 0
C21: =SUM(D21:L21) -> 0
C22: =SUM(D22:L22) -> 0
C23: =SUM(D23:L23) -> 0
C24: =SUM(D24:L24) -> 0
C25: =SUM(D25:L25) -> 0
C26: =SUM(D26:L26) -> 0
C27: =SUM(D27:L27) -> 0
... C70: =SUM(D70:L70) -> 0

Sheet Commisisoni Portali
D1: 2026 | M1: 2027
A2: CODICE | D2: APRILE | E2: MAGGIO | F2: GIUGNO | G2: LUGLIO | H2: AGOSTO | I2: SETTEMBRE | J2: OTTOBRE | K2: NOVEMBRE | L2: DICEMBRE | M2: GENNAIO | N2: FEBBRAIO | O2: MARZO | P2: APRILE | Q2: MAGGIO | R2: GIUGNO
B3: Commisisoni Portali | C3: =SUM(D3:L3) -> 148897 | D3: =SUM(D4:D130) -> 0 | E3: =SUM(E4:E130) -> 0 | F3: =SUM(F4:F130) -> 0 | G3: =SUM(G4:G130) -> 43897 | H3: =SUM(H4:H130) -> 44300 | I3: =SUM(I4:I130) -> 10500 | J3: =SUM(J4:J130) -> 28000 | K3: =SUM(K4:K130) -> 14000 | ... R3: =SUM(R4:R130) -> 0
A4: 57010192 | B4: Commissioni Booking | C4: =SUM(D4:L4) -> 122980 | G4: 37280 | H4: 38000 | I4: 5000 | J4: 28000 | K4: 14000 | L4: 700
A5: 57010192 | B5: Commissioni Expedia | C5: =SUM(D5:L5) -> 25917 | G5: 6617 | H5: 6300 | I5: 5500 | K5: 0 | L5: 7500
A6: 414 | B6: NEXI PAYMENTS S.p.A. | C6: =SUM(D6:L6) -> 0
C7: =SUM(D7:L7) -> 0
C8: =SUM(D8:L8) -> 0
C9: =SUM(D9:L9) -> 0
C10: =SUM(D10:L10) -> 0
C11: =SUM(D11:L11) -> 0
C12: =SUM(D12:L12) -> 0
C13: =SUM(D13:L13) -> 0
C14: =SUM(D14:L14) -> 0
C15: =SUM(D15:L15) -> 0
C16: =SUM(D16:L16) -> 0
C17: =SUM(D17:L17) -> 0
C18: =SUM(D18:L18) -> 0
... C64: =SUM(D64:L64) -> 0

Sheet Mutui e Finaziamenti
D1: 2026 | M1: 2027
A2: CODICE | D2: APRILE | E2: MAGGIO | F2: GIUGNO | G2: LUGLIO | H2: AGOSTO | I2: SETTEMBRE | J2: OTTOBRE | K2: NOVEMBRE | L2: DICEMBRE | M2: GENNAIO | N2: FEBBRAIO | O2: MARZO | P2: APRILE | Q2: MAGGIO | R2: GIUGNO
B3: Mutui e Finanaziamenti | C3: =SUM(D3:L3) -> 248062.43 | D3: =SUM(D4:D134) -> 0 | E3: =SUM(E4:E134) -> 0 | F3: =SUM(F4:F134) -> 0 | G3: =SUM(G4:G134) -> 13659.3 | H3: =SUM(H4:H134) -> 13658.59 | I3: =SUM(I4:I134) -> 13627.32 | J3: =SUM(J4:J134) -> 13657.16 | K3: =SUM(K4:K134) -> 13628.34 | ... R3: =SUM(R4:R134) -> 0
A4: 310394 | B4: Mutuo MPS | C4: =SUM(D4:L4) -> 166176 | L4: 166176
A5: 310392 | B5: EX Muto Intesa (mps) | C5: =SUM(D5:L5) -> 73522.91 | G5: 12265.38 | H5: 12264.67 | I5: 12233.4 | J5: 12263.24 | K5: 12234.42 | L5: 12261.8
A6: 310305 | B6: Finanziamento MPS 75k | C6: =SUM(D6:L6) -> 8363.52 | G6: 1393.92 | H6: 1393.92 | I6: 1393.92 | J6: 1393.92 | K6: 1393.92 | L6: 1393.92
C7: =SUM(D7:L7) -> 0
C8: =SUM(D8:L8) -> 0
C9: =SUM(D9:L9) -> 0
C10: =SUM(D10:L10) -> 0
C11: =SUM(D11:L11) -> 0
C12: =SUM(D12:L12) -> 0
C13: =SUM(D13:L13) -> 0
C14: =SUM(D14:L14) -> 0
C15: =SUM(D15:L15) -> 0
C16: =SUM(D16:L16) -> 0
C17: =SUM(D17:L17) -> 0
C18: =SUM(D18:L18) -> 0
... C68: =SUM(D68:L68) -> 0

Sheet Consulenze
D1: 2026 | M1: 2027
A2: CODICE | D2: APRILE | E2: MAGGIO | F2: GIUGNO | G2: LUGLIO | H2: AGOSTO | I2: SETTEMBRE | J2: OTTOBRE | K2: NOVEMBRE | L2: DICEMBRE | M2: GENNAIO | N2: FEBBRAIO | O2: MARZO | P2: APRILE | Q2: MAGGIO | R2: GIUGNO
B3: Consulenze | C3: =SUM(D3:L3) -> 55786.8 | D3: =SUM(D4:D134) -> 0 | E3: =SUM(E4:E134) -> 0 | F3: =SUM(F4:F134) -> 0 | G3: =SUM(G4:G134) -> 24754.8 | H3: =SUM(H4:H134) -> 3416 | I3: =SUM(I4:I134) -> 27616 | J3: =SUM(J4:J134) -> 0 | K3: =SUM(K4:K134) -> 0 | ... R3: =SUM(R4:R134) -> 0
A4: 61010191 | B4: Consulenza del lavoro | C4: =SUM(D4:L4) -> 5992.04 | G4: 2292.04 | I4: 3700 | K4: 0
A5: 610101 | B5: Consulenza fiscale | C5: =SUM(D5:L5) -> 10693.6 | G5: 5193.6 | I5: 5500
A6: 610105 | B6: Consulenza legale | C6: =SUM(D6:L6) -> 15000 | G6: 0 | H6: 0 | I6: 15000
A7: 610107 | B7: Consulenza notarile | C7: =SUM(D7:L7) -> 0
A8: 1549 | B8: Team Work | C8: =SUM(D8:L8) -> 0
A9: 630515 | B9: Polizza Generali | C9: =SUM(D9:L9) -> 9000 | G9: 9000
B10: Hospitality Project | C10: =SUM(D10:L10) -> 10248 | G10: 3416 | H10: 3416 | I10: 3416
A11: 1693 | B11: JoAnne Dunn Photographers | C11: =SUM(D11:L11) -> 0
A12: 369 | B12: Creative Idea S.N.C. Di De Martino Diodato & C. | C12: =SUM(D12:L12) -> 3111 | G12: 3111
A13: 132 | B13: STUDIO QUATTRO S.R.L. | C13: =SUM(D13:L13) -> 1742.16 | G13: 1742.16
C14: =SUM(D14:L14) -> 0
C15: =SUM(D15:L15) -> 0
C16: =SUM(D16:L16) -> 0
C17: =SUM(D17:L17) -> 0
C18: =SUM(D18:L18) -> 0
C19: =SUM(D19:L19) -> 0
C20: =SUM(D20:L20) -> 0
C21: =SUM(D21:L21) -> 0
C22: =SUM(D22:L22) -> 0
C23: =SUM(D23:L23) -> 0
C24: =SUM(D24:L24) -> 0
C25: =SUM(D25:L25) -> 0
... C68: =SUM(D68:L68) -> 0

Sheet Godimento Beni di Terzi
D1: 2026 | M1: 2027
A2: CODICE | D2: APRILE | E2: MAGGIO | F2: GIUGNO | G2: LUGLIO | H2: AGOSTO | I2: SETTEMBRE | J2: OTTOBRE | K2: NOVEMBRE | L2: DICEMBRE | M2: GENNAIO | N2: FEBBRAIO | O2: MARZO | P2: APRILE | Q2: MAGGIO | R2: GIUGNO
B4: Gofimento Beni di Terzi | C4: =SUM(D4:L4) -> 1488918 | D4: =SUM(D5:D135) -> 0 | E4: =SUM(E5:E135) -> 0 | F4: =SUM(F5:F135) -> 0 | G4: =SUM(G5:G135) -> 404000 | H4: =SUM(H5:H135) -> 60000 | I4: =SUM(I5:I135) -> 0 | J4: =SUM(J5:J135) -> 244000 | K4: =SUM(K5:K135) -> 50000 | ... R4: =SUM(R5:R135) -> 0
A5: 651101 | B5: Fitto Ramo d' Azienda | C5: =SUM(D5:L5) -> 1218918 | G5: 244000 | H5: 0 | J5: 244000 | L5: 730918
A6: 651101 | B6: Fitto AR | C6: =SUM(D6:L6) -> 120000 | G6: 60000 | H6: 60000
A7: 651101 | B7: Fitto CVM | C7: =SUM(D7:L7) -> 150000 | G7: 100000 | K7: 50000
C8: =SUM(D8:L8) -> 0
C9: =SUM(D9:L9) -> 0
C10: =SUM(D10:L10) -> 0
C11: =SUM(D11:L11) -> 0
C12: =SUM(D12:L12) -> 0
C13: =SUM(D13:L13) -> 0
C14: =SUM(D14:L14) -> 0
C15: =SUM(D15:L15) -> 0
C16: =SUM(D16:L16) -> 0
C17: =SUM(D17:L17) -> 0
C18: =SUM(D18:L18) -> 0
C19: =SUM(D19:L19) -> 0
... C69: =SUM(D69:L69) -> 0

Sheet Canoni e servizi
D1: 2026 | M1: 2027
A2: CODICE | D2: APRILE | E2: MAGGIO | F2: GIUGNO | G2: LUGLIO | H2: AGOSTO | I2: SETTEMBRE | J2: OTTOBRE | K2: NOVEMBRE | L2: DICEMBRE | M2: GENNAIO | N2: FEBBRAIO | O2: MARZO | P2: APRILE | Q2: MAGGIO | R2: GIUGNO
B4: Canoni e servizi | C4: =SUM(D4:L4) -> 45763.68 | D4: =SUM(D5:D131) -> 0 | E4: =SUM(E5:E131) -> 0 | F4: =SUM(F5:F131) -> 0 | G4: =SUM(G5:G131) -> 19210.48 | H4: =SUM(H5:H131) -> 4317.84 | I4: =SUM(I5:I131) -> 1408.84 | J4: =SUM(J5:J131) -> 1408.84 | K4: =SUM(K5:K131) -> 1408.84 | ... R4: =SUM(R5:R131) -> 378.2
A5: 12 | B5: Proxima Service | C5: =SUM(D5:L5) -> 0
A6: 948 | B6: Hoxell | C6: =SUM(D6:L6) -> 0
A7: 10 | B7: Sistemi (E_solver) | C7: =SUM(D7:L7) -> 0
B8: Zucchetti | C8: =SUM(D8:L8) -> 16752.5 | G8: 152.5 | L8: 16600
A9: 1270 | B9: BESTRANK SOCIETA' A | C9: =SUM(D9:L9) -> 0
A10: 81 | B10: PLAN ITALIA S.R.L. | C10: =SUM(D10:L10) -> 0
B11: Altamira | C11: =SUM(D11:L11) -> 2269.2 | G11: =310*1.22 -> 378.2 | H11: =310*1.22 -> 378.2 | I11: =310*1.22 -> 378.2 | J11: =310*1.22 -> 378.2 | K11: =310*1.22 -> 378.2 | L11: =310*1.22 -> 378.2 | M11: =310*1.22 -> 378.2 | N11: =310*1.22 -> 378.2 | ... R11: =310*1.22 -> 378.2
A12: 750195 | B12: Commissioni Transato Pos | C12: =SUM(D12:L12) -> 8175.92 | G12: 7362.04 | H12: 813.88
A13: 76 | B13: Soft tecnology | C13: =SUM(D13:L13) -> 0
A14: 750107 | B14: Commissioni e spese Bancarie Varie(Imposta di bollo/tenuta conto/bonifici/etc ) | C14: =SUM(D14:L14) -> 2000 | H14: 2000
A15: 1076 | B15: Noleggio Tesla | C15: =SUM(D15:L15) -> 6183.84 | G15: 1030.64 | H15: 1030.64 | I15: 1030.64 | J15: 1030.64 | K15: 1030.64 | L15: 1030.64
A16: 1276 | B16: Alba Leasing S.P.A. | C16: =SUM(D16:L16) -> 0
A17: 137 | B17: Primavera Servizi Srl | C17: =SUM(D17:L17) -> 0
A18: 630515 | B18: Polizza Generali | C18: =SUM(D18:L18) -> 9000 | G18: 9000
A19: 52 | B19: Aruba | C19: =SUM(D19:L19) -> 0
A20: 654 | B20: GOOGLE CLOUD ITALY S.R.L. | C20: =SUM(D20:L20) -> 0
A21: 1222 | B21: Pietra Di Luna Hotel - S.R.L. | C21: =SUM(D21:L21) -> 921.1 | G21: 921.1
A22: 1010 | B22: VALLOUFFICIO SOLUZIONI di Zavaglia Nicola & C. S.A.S. | C22: =SUM(D22:L22) -> 461.12 | G22: 366 | H22: 95.12
C23: =SUM(D23:L23) -> 0
C24: =SUM(D24:L24) -> 0
C25: =SUM(D25:L25) -> 0
C26: =SUM(D26:L26) -> 0
C27: =SUM(D27:L27) -> 0
C28: =SUM(D28:L28) -> 0
C29: =SUM(D29:L29) -> 0
C30: =SUM(D30:L30) -> 0
C31: =SUM(D31:L31) -> 0
C32: =SUM(D32:L32) -> 0
C33: =SUM(D33:L33) -> 0
C34: =SUM(D34:L34) -> 0
... C66: =SUM(D66:L66) -> 0

Sheet  Varie ed Eventuali
D1: 2026 | M1: 2027
A2: CODICE | D2: APRILE | E2: MAGGIO | F2: GIUGNO | G2: LUGLIO | H2: AGOSTO | I2: SETTEMBRE | J2: OTTOBRE | K2: NOVEMBRE | L2: DICEMBRE | M2: GENNAIO | N2: FEBBRAIO | O2: MARZO | P2: APRILE | Q2: MAGGIO | R2: GIUGNO
B3: Variee ed Eventuali | C3: =SUM(D3:L3) -> 44336.34 | D3: =SUM(D4:D133) -> 0 | E3: =SUM(E4:E133) -> 0 | F3: =SUM(F4:F133) -> 0 | G3: =SUM(G4:G133) -> 3731.7 | H3: =SUM(H4:H133) -> 13534.88 | I3: =SUM(I4:I133) -> 6767.44 | J3: =SUM(J4:J133) -> 6767.44 | K3: =SUM(K4:K133) -> 6767.44 | ... R3: =SUM(R4:R133) -> 0
A4: 650107 | B4: Spese Condominiali | C4: =SUM(D4:L4) -> 40604.64 | H4: 13534.88 | I4: 6767.44 | J4: 6767.44 | K4: 6767.44 | L4: 6767.44
A5: 1080 | B5: AUTOSTRADE PER L'ITALIA S.P.A. | C5: =SUM(D5:L5) -> 0
A6: 795 | B6: DEL RISPARMIO | C6: =SUM(D6:L6) -> 0
A7: 1625 | B7: EDILIZIA ED | C7: =SUM(D7:L7) -> 0
A8: 127 | B8: FEIO S.R.L. | C8: =SUM(D8:L8) -> 0
A9: 647 | B9: H & M HENNES & MAURITZ S.R.L. | C9: =SUM(D9:L9) -> 0
A10: 1629 | B10: Mana srls | C10: =SUM(D10:L10) -> 1650 | G10: 1650
A11: 1626 | B11: ROSANTO S.R.L. | C11: =SUM(D11:L11) -> 0
A12: 1638 | B12: CENTRO MODA S.R.L. | C12: =SUM(D12:L12) -> 0
A13: 1646 | B13: DIECI S.R.L.S. | C13: =SUM(D13:L13) -> 0
A14: 1647 | B14: HAIR GALLERY EUROPE SRL | C14: =SUM(D14:L14) -> 0
A15: 179 | B15: FERRIGNO MARIA C S N C | C15: =SUM(D15:L15) -> 0
A16: 744 | B16: Nola Ferramenta Srl | C16: =SUM(D16:L16) -> 0
A17: 1036 | B17: Re Denari di Marco Oliva & C. Sas | C17: =SUM(D17:L17) -> 0
A18: 70 | B18: MAGALDI LIFE SRL SOC. UNIP. | C18: =SUM(D18:L18) -> 0
A19: 1696 | B19: READYPRINT DI PIPITONE BRUNO | C19: =SUM(D19:L19) -> 0
A20: 170 | B20: Leroy Merlin Italia srl | C20: =SUM(D20:L20) -> 0
A21: 109 | B21: MEDIAMARKET S.P.A. CON SOCIO UNICO | C21: =SUM(D21:L21) -> 0
A22: 123 | B22: PREGIS S.P.A. | C22: =SUM(D22:L22) -> 0
... A27: 1773 | B27: Gruppo Adam s.r.l. | C27: =SUM(D27:L27) -> 0
A28: 1768 | B28: I.R.P.S. Srl | C28: =SUM(D28:L28) -> 599.5 | G28: 599.5
A29: 231 | B29: Ikea Italia Retail Srl | C29: =SUM(D29:L29) -> 0
A30: 1752 | B30: Lo Scoglio Dei F.Lli De Simone S.R.L. | C30: =SUM(D30:L30) -> 0
A31: 1202 | B31: Nila S.R.L. | C31: =SUM(D31:L31) -> 782.2 | G31: 782.2
A32: 1772 | B32: Propac S.R.L. | C32: =SUM(D32:L32) -> 0
A33: 797 | B33: Puntoffice Di Cardarelli Rita | C33: =SUM(D33:L33) -> 0
A34: 980 | B34: Ristorante O Padrone Do'Mare Di De Siano Giacinto & C. Snc | C34: =SUM(D34:L34) -> 0
A35: 1298 | B35: Apicella Lorenzo | C35: =SUM(D35:L35) -> 700 | G35: 700
C36: =SUM(D36:L36) -> 0
C37: =SUM(D37:L37) -> 0
C38: =SUM(D38:L38) -> 0
C39: =SUM(D39:L39) -> 0
C40: =SUM(D40:L40) -> 0
C41: =SUM(D41:L41) -> 0
C42: =SUM(D42:L42) -> 0
C43: =SUM(D43:L43) -> 0
C44: =SUM(D44:L44) -> 0
...

Sheet DA MAPPARE
A1: Fornitori NON mappati in d_fornitori.csv — assegnare una voce (hotelops fornitori) e rigenerare
A2: Cod | B2: Nome (da export) | C2: GENNAIO | D2: FEBBRAIO | E2: MARZO | F2: APRILE | G2: MAGGIO | H2: GIUGNO | I2: LUGLIO | J2: AGOSTO | K2: SETTEMBRE | L2: OTTOBRE | M2: NOVEMBRE | N2: DICEMBRE

Sheet ESCLUSI
A1: Fornitori ESCLUSI dalla cassa per scelta (is_excluded) — fuori dal saldo proiettato. NON sono un TODO: il motivo è in colonna Motivo.
A2: Cod | B2: Nome (da CSV) | C2: GENNAIO | D2: FEBBRAIO | E2: MARZO | F2: APRILE | G2: MAGGIO | H2: GIUGNO | I2: LUGLIO | J2: AGOSTO | K2: SETTEMBRE | L2: OTTOBRE | M2: NOVEMBRE | N2: DICEMBRE | O2: Motivo
A3: 27 | B3: AL MORO DI ROMAGNOLI ANDREA SAS | I3: 394.98 | O3: escluso da app cashflow
A4: 1758 | B4: BRILY DI AVETA VINCENZO | H4: 14.23 | O4: escluso da app cashflow
A5: 1765 | B5: Fercolor s.r.l. | H5: 54.39 | O5: escluso da app cashflow
A6: 1745 | B6: POPPITI ALDO | H6: 19.61 | O6: escluso da app cashflow
A7: 1755 | B7: VARZI GENERATION SRL | H7: 19.9 | O7: escluso da app cashflow

Sheet DA MAPPARE1
A1: Fornitori NON mappati in d_fornitori.csv — assegnare una voce (hotelops fornitori) e rigenerare
A2: Cod | B2: Nome (da export) | C2: GENNAIO | D2: FEBBRAIO | E2: MARZO | F2: APRILE | G2: MAGGIO | H2: GIUGNO | I2: LUGLIO | J2: AGOSTO | K2: SETTEMBRE | L2: OTTOBRE | M2: NOVEMBRE | N2: DICEMBRE
A3: 648 | B3: ALBA NEON S.R.L. | I3: 976
A4: 949 | B4: ASSOCIAZIONE SOUL FOOD | I4: 1490
A5: 1721 | B5: LEIDIVA DI SEPE ROSARIO | I5: 507.52
