Workbook

Sheet Controlli
A1: CONTROLLI PIANO FINANZIARIO — ORTI
A3: 1. SALDO PARTENZA
A4: C4 = Saldo iniziale hardcoded? | B4: =IF(_xlfn.ISFORMULA('Piano Finanziario'!C4),"ERRORE","OK") -> OK
A5: D4 = C37 (catena saldo mese prec)? | B5: =IF('Piano Finanziario'!D4='Piano Finanziario'!C37,"OK","ERRORE") -> OK
A6: Catena D4:K4 = mese prec riga 37? | B6: =IF(AND('Piano Finanziario'!D4='Piano Finanziario'!C37,'Piano Finanziario'!E4='Piano Finanziario'!D37,'Piano Finanziario'!F4='Piano Finanziario'!E37,'Piano Finanziario'!G4='Piano Finanziario'!F37,'Piano Finanziario'!H4='Piano Finanziario'!G37,'Piano Finanziario'!I4='Piano Finanziario'!H37,'Piano Finanziario'!J4='Piano Finanziario'!I37,'Piano Finanziario'!K4='Piano Finanziario'!J37),"OK","ERRORE") -> OK
A7: (non applicabile — mesi passati rimossi) | B7: OK
A9: 2. TOTALE ENTRATE (riga 12)
A10: Riga 12 = SUM(6:11) per mesi C:K? | B10: =IF(AND('Piano Finanziario'!C12=SUM('Piano Finanziario'!C6:'Piano Finanziario'!C11),'Piano Finanziario'!D12=SUM('Piano Finanziario'!D6:'Piano Finanziario'!D11),'Piano Finanziario'!E12=SUM('Piano Finanziario'!E6:'Piano Finanziario'!E11),'Piano Finanziario'!F12=SUM('Piano Finanziario'!F6:'Piano Finanziario'!F11),'Piano Finanziario'!G12=SUM('Piano Finanziario'!G6:'Piano Finanziario'!G11),'Piano Finanziario'!H12=SUM('Piano Finanziario'!H6:'Piano Finanziario'!H11),'Piano Finanziario'!I12=SUM('Piano Finanziario'!I6:'Piano Finanziario'!I11),'Piano Finanziario'!J12=SUM('Piano Finanziario'!J6:'Piano Finanziario'!J11),'Piano Finanziario'!K12=SUM('Piano Finanziario'!K6:'Piano Finanziario'!K11)),"OK","ERRORE") -> OK
A12: 3. TOTALE USCITE (riga 27)
A13: Riga 27 = SUM(14:26) per mesi C:K? | B13: =IF(AND('Piano Finanziario'!C27=SUM('Piano Finanziario'!C14:'Piano Finanziario'!C26),'Piano Finanziario'!D27=SUM('Piano Finanziario'!D14:'Piano Finanziario'!D26),'Piano Finanziario'!E27=SUM('Piano Finanziario'!E14:'Piano Finanziario'!E26),'Piano Finanziario'!F27=SUM('Piano Finanziario'!F14:'Piano Finanziario'!F26),'Piano Finanziario'!G27=SUM('Piano Finanziario'!G14:'Piano Finanziario'!G26),'Piano Finanziario'!H27=SUM('Piano Finanziario'!H14:'Piano Finanziario'!H26),'Piano Finanziario'!I27=SUM('Piano Finanziario'!I14:'Piano Finanziario'!I26),'Piano Finanziario'!J27=SUM('Piano Finanziario'!J14:'Piano Finanziario'!J26),'Piano Finanziario'!K27=SUM('Piano Finanziario'!K14:'Piano Finanziario'!K26)),"OK","ERRORE") -> OK
A15: 4. CASH FLOW (riga 29)
A16: Riga 29 = Entrate - Uscite per mesi C:K? | B16: =IF(AND('Piano Finanziario'!C29='Piano Finanziario'!C12-'Piano Finanziario'!C27,'Piano Finanziario'!D29='Piano Finanziario'!D12-'Piano Finanziario'!D27,'Piano Finanziario'!E29='Piano Finanziario'!E12-'Piano Finanziario'!E27,'Piano Finanziario'!F29='Piano Finanziario'!F12-'Piano Finanziario'!F27,'Piano Finanziario'!G29='Piano Finanziario'!G12-'Piano Finanziario'!G27,'Piano Finanziario'!H29='Piano Finanziario'!H12-'Piano Finanziario'!H27,'Piano Finanziario'!I29='Piano Finanziario'!I12-'Piano Finanziario'!I27,'Piano Finanziario'!J29='Piano Finanziario'!J12-'Piano Finanziario'!J27,'Piano Finanziario'!K29='Piano Finanziario'!K12-'Piano Finanziario'!K27),"OK","ERRORE") -> OK
A21: 6. RIFERIMENTI USCITE — FOGLI DETTAGLIO (mesi I:R)
A22: Riga 14 — Salari e Stipendi | B22: =IF(AND('Piano Finanziario'!C14='Salari e Stipendi'!D4,'Piano Finanziario'!D14='Salari e Stipendi'!E4,'Piano Finanziario'!E14='Salari e Stipendi'!F4,'Piano Finanziario'!F14='Salari e Stipendi'!G4,'Piano Finanziario'!G14='Salari e Stipendi'!H4,'Piano Finanziario'!H14='Salari e Stipendi'!I4,'Piano Finanziario'!I14='Salari e Stipendi'!J4,'Piano Finanziario'!J14='Salari e Stipendi'!K4,'Piano Finanziario'!K14='Salari e Stipendi'!L4),"OK","ERRORE") -> OK
A23: Riga 15 — Utenze | B23: =IF(AND('Piano Finanziario'!C15=Utenze!D3,'Piano Finanziario'!D15=Utenze!E3,'Piano Finanziario'!E15=Utenze!F3,'Piano Finanziario'!F15=Utenze!G3,'Piano Finanziario'!G15=Utenze!H3,'Piano Finanziario'!H15=Utenze!I3,'Piano Finanziario'!I15=Utenze!J3,'Piano Finanziario'!J15=Utenze!K3,'Piano Finanziario'!K15=Utenze!L3),"OK","ERRORE") -> OK
A24: Riga 16 — Materie Prime/Consumo | B24: =IF(AND('Piano Finanziario'!C16=MAX('Materie Prime-Consumo '!D3,'Materie Prime-Consumo '!D4),'Piano Finanziario'!D16=MAX('Materie Prime-Consumo '!E3,'Materie Prime-Consumo '!E4),'Piano Finanziario'!E16=MAX('Materie Prime-Consumo '!F3,'Materie Prime-Consumo '!F4),'Piano Finanziario'!F16=MAX('Materie Prime-Consumo '!G3,'Materie Prime-Consumo '!G4),'Piano Finanziario'!G16=MAX('Materie Prime-Consumo '!H3,'Materie Prime-Consumo '!H4),'Piano Finanziario'!H16=MAX('Materie Prime-Consumo '!I3,'Materie Prime-Consumo '!I4),'Piano Finanziario'!I16=MAX('Materie Prime-Consumo '!J3,'Materie Prime-Consumo '!J4),'Piano Finanziario'!J16=MAX('Materie Prime-Consumo '!K3,'Materie Prime-Consumo '!K4),'Piano Finanziario'!K16=MAX('Materie Prime-Consumo '!L3,'Materie Prime-Consumo '!L4)),"OK","ERRORE") -> OK
A25: Riga 17 — Tasse e Imposte | B25: =IF(AND('Piano Finanziario'!C17='Tasse e Imposte'!D3,'Piano Finanziario'!D17='Tasse e Imposte'!E3,'Piano Finanziario'!E17='Tasse e Imposte'!F3,'Piano Finanziario'!F17='Tasse e Imposte'!G3,'Piano Finanziario'!G17='Tasse e Imposte'!H3,'Piano Finanziario'!H17='Tasse e Imposte'!I3,'Piano Finanziario'!I17='Tasse e Imposte'!J3,'Piano Finanziario'!J17='Tasse e Imposte'!K3,'Piano Finanziario'!K17='Tasse e Imposte'!L3),"OK","ERRORE") -> OK
A26: Riga 18 — Commissioni Portali | B26: =IF(AND('Piano Finanziario'!C18='Commisisoni Portali'!D3,'Piano Finanziario'!D18='Commisisoni Portali'!E3,'Piano Finanziario'!E18='Commisisoni Portali'!F3,'Piano Finanziario'!F18='Commisisoni Portali'!G3,'Piano Finanziario'!G18='Commisisoni Portali'!H3,'Piano Finanziario'!H18='Commisisoni Portali'!I3,'Piano Finanziario'!I18='Commisisoni Portali'!J3,'Piano Finanziario'!J18='Commisisoni Portali'!K3,'Piano Finanziario'!K18='Commisisoni Portali'!L3),"OK","ERRORE") -> OK
A27: Riga 19 — Mutui e Finanziamenti | B27: =IF(AND('Piano Finanziario'!C19='Mutui e Finaziamenti'!D3,'Piano Finanziario'!D19='Mutui e Finaziamenti'!E3,'Piano Finanziario'!E19='Mutui e Finaziamenti'!F3,'Piano Finanziario'!F19='Mutui e Finaziamenti'!G3,'Piano Finanziario'!G19='Mutui e Finaziamenti'!H3,'Piano Finanziario'!H19='Mutui e Finaziamenti'!I3,'Piano Finanziario'!I19='Mutui e Finaziamenti'!J3,'Piano Finanziario'!J19='Mutui e Finaziamenti'!K3,'Piano Finanziario'!K19='Mutui e Finaziamenti'!L3),"OK","ERRORE") -> OK
A28: Riga 20 — Consulenze | B28: =IF(AND('Piano Finanziario'!C20=Consulenze!D3,'Piano Finanziario'!D20=Consulenze!E3,'Piano Finanziario'!E20=Consulenze!F3,'Piano Finanziario'!F20=Consulenze!G3,'Piano Finanziario'!G20=Consulenze!H3,'Piano Finanziario'!H20=Consulenze!I3,'Piano Finanziario'!I20=Consulenze!J3,'Piano Finanziario'!J20=Consulenze!K3,'Piano Finanziario'!K20=Consulenze!L3),"OK","ERRORE") -> OK
A29: Riga 21 — Godimento Beni di Terzi | B29: =IF(AND('Piano Finanziario'!C21='Godimento Beni di Terzi'!D4,'Piano Finanziario'!D21='Godimento Beni di Terzi'!E4,'Piano Finanziario'!E21='Godimento Beni di Terzi'!F4,'Piano Finanziario'!F21='Godimento Beni di Terzi'!G4,'Piano Finanziario'!G21='Godimento Beni di Terzi'!H4,'Piano Finanziario'!H21='Godimento Beni di Terzi'!I4,'Piano Finanziario'!I21='Godimento Beni di Terzi'!J4,'Piano Finanziario'!J21='Godimento Beni di Terzi'!K4,'Piano Finanziario'!K21='Godimento Beni di Terzi'!L4),"OK","ERRORE") -> OK
A30: Riga 22 — Varie ed Eventuali | B30: =IF(AND('Piano Finanziario'!C22=' Varie ed Eventuali'!D3,'Piano Finanziario'!D22=' Varie ed Eventuali'!E3,'Piano Finanziario'!E22=' Varie ed Eventuali'!F3,'Piano Finanziario'!F22=' Varie ed Eventuali'!G3,'Piano Finanziario'!G22=' Varie ed Eventuali'!H3,'Piano Finanziario'!H22=' Varie ed Eventuali'!I3,'Piano Finanziario'!I22=' Varie ed Eventuali'!J3,'Piano Finanziario'!J22=' Varie ed Eventuali'!K3,'Piano Finanziario'!K22=' Varie ed Eventuali'!L3),"OK","ERRORE") -> OK
A31: Riga 23 — Canoni e servizi | B31: =IF(AND('Piano Finanziario'!C23='Canoni e servizi'!D4,'Piano Finanziario'!D23='Canoni e servizi'!E4,'Piano Finanziario'!E23='Canoni e servizi'!F4,'Piano Finanziario'!F23='Canoni e servizi'!G4,'Piano Finanziario'!G23='Canoni e servizi'!H4,'Piano Finanziario'!H23='Canoni e servizi'!I4,'Piano Finanziario'!I23='Canoni e servizi'!J4,'Piano Finanziario'!J23='Canoni e servizi'!K4,'Piano Finanziario'!K23='Canoni e servizi'!L4),"OK","ERRORE") -> OK
A33: 7. SALDO PROIETTATO (riga 37)
A34: Riga 37 = riga 4 + riga 29 per mesi attivi I:R? | B34: =IF(AND('Piano Finanziario'!C37='Piano Finanziario'!C4+'Piano Finanziario'!C29,'Piano Finanziario'!D37='Piano Finanziario'!D4+'Piano Finanziario'!D29,'Piano Finanziario'!E37='Piano Finanziario'!E4+'Piano Finanziario'!E29,'Piano Finanziario'!F37='Piano Finanziario'!F4+'Piano Finanziario'!F29,'Piano Finanziario'!G37='Piano Finanziario'!G4+'Piano Finanziario'!G29,'Piano Finanziario'!H37='Piano Finanziario'!H4+'Piano Finanziario'!H29,'Piano Finanziario'!I37='Piano Finanziario'!I4+'Piano Finanziario'!I29,'Piano Finanziario'!J37='Piano Finanziario'!J4+'Piano Finanziario'!J29,'Piano Finanziario'!K37='Piano Finanziario'!K4+'Piano Finanziario'!K29),"OK","ERRORE") -> OK
A36: 8. CASH FLOW CON AFFIDAMENTI (riga 45)
A37: Riga 45 = riga 37 + riga 43 per mesi attivi I:R? | B37: =IF(AND('Piano Finanziario'!C45='Piano Finanziario'!C37+'Piano Finanziario'!C43,'Piano Finanziario'!D45='Piano Finanziario'!D37+'Piano Finanziario'!D43,'Piano Finanziario'!E45='Piano Finanziario'!E37+'Piano Finanziario'!E43,'Piano Finanziario'!F45='Piano Finanziario'!F37+'Piano Finanziario'!F43,'Piano Finanziario'!G45='Piano Finanziario'!G37+'Piano Finanziario'!G43,'Piano Finanziario'!H45='Piano Finanziario'!H37+'Piano Finanziario'!H43,'Piano Finanziario'!I45='Piano Finanziario'!I37+'Piano Finanziario'!I43,'Piano Finanziario'!J45='Piano Finanziario'!J37+'Piano Finanziario'!J43,'Piano Finanziario'!K45='Piano Finanziario'!K37+'Piano Finanziario'!K43),"OK","ERRORE") -> OK
A39: 9. COLONNA TOTALI (T)
A40: L12 Totale Entrate = SUM(C12:K12)? | B40: =IF('Piano Finanziario'!L12=SUM('Piano Finanziario'!C12:'Piano Finanziario'!K12),"OK","ERRORE") -> OK
A41: L27 Totale Uscite = SUM(C27:K27)? | B41: =IF('Piano Finanziario'!L27=SUM('Piano Finanziario'!C27:'Piano Finanziario'!K27),"OK","ERRORE") -> OK
A42: L29 Cash Flow = L12 - L27? | B42: =IF('Piano Finanziario'!L29='Piano Finanziario'!L12-'Piano Finanziario'!L27,"OK","ERRORE") -> OK
A44: =CONCATENATE("RISULTATO COMPLESSIVO") -> RISULTATO COMPLESSIVO | B44: =IF(COUNTIF(B4:B42,"ERRORE")=0,"✓ TUTTI I "&COUNTA(B4:B42)&" CONTROLLI OK","✗ "&COUNTIF(B4:B42,"ERRORE")&" ERRORI TROVATI su "&COUNTA(B4:B42)&" verifiche") -> ✓ TUTTI I 22 CONTROLLI OK

Sheet Piano Finanziario
A1: ORTI S.R.L. | C1: 2026
C2: APRILE | D2: MAGGIO | E2: GIUGNO | F2: LUGLIO | G2: AGOSTO | H2: SETTEMBRE | I2: OTTOBRE | J2: NOVEMBRE | K2: DICEMBRE | L2: TOTALI
A4: SALDO MESE PRECED | C4: 339337.46 | D4: =C37 -> 339337.46 | E4: =D37 -> 382984.03 | F4: =E37 -> 128423.73 | G4: =F37 -> 405473.59 | H4: =G37 -> 911588.89 | I4: =H37 -> 1264189.3 | J4: =I37 -> 1257887.9 | K4: =J37 -> 860272.38
A6: Entrate Hotel | D6: 450000 | E6: 600000 | F6: 750000 | G6: 830000 | H6: 580000 | I6: =110000+160000 -> 270000 | L6: =SUM(C6:K6) -> 3480000
A7: Entrate Residence | D7: 60000 | E7: 100000 | F7: 120000 | G7: 140000 | H7: 100000 | I7: =26000+17000 -> 43000 | L7: =SUM(C7:K7) -> 563000
A8: Entrate CVM | D8: 22000 | E8: 25000 | F8: 45000 | G8: 48000 | H8: 30000 | I8: =5798+10000 -> 15798 | L8: =SUM(C8:K8) -> 185798
A9: Entrate Supermercato | D9: 25620 | E9: 25620 | F9: 25620 | G9: 25620 | H9: 25620 | I9: 25620 | J9: 25620 | K9: 25620 | L9: =SUM(C9:K9) -> 204960
A10: Rientro Sospesi | L10: =SUM(C10:K10) -> 0
A11: Caparre Intur | L11: =SUM(C11:K11) -> 0
A12: TOTALE ENTRATE | C12: =SUM(C6:C11) -> 0 | D12: =SUM(D6:D11) -> 557620 | E12: =SUM(E6:E11) -> 750620 | F12: =SUM(F6:F11) -> 940620 | G12: =SUM(G6:G11) -> 1043620 | H12: =SUM(H6:H11) -> 735620 | I12: =SUM(I6:I11) -> 354418 | J12: =SUM(J6:J11) -> 25620 | K12: =SUM(K6:K11) -> 25620 | L12: =SUM(C12:K12) -> 4433758
A14: Salari e Stipendi | C14: ='Salari e Stipendi'!D4 -> 0 | D14: ='Salari e Stipendi'!E4 -> 95700.26 | E14: ='Salari e Stipendi'!F4 -> 120969.2 | F14: ='Salari e Stipendi'!G4 -> 135000 | G14: ='Salari e Stipendi'!H4 -> 155000 | H14: ='Salari e Stipendi'!I4 -> 140000 | I14: ='Salari e Stipendi'!J4 -> 115000 | J14: ='Salari e Stipendi'!K4 -> 175000 | K14: ='Salari e Stipendi'!L4 -> 58000 | L14: =SUM(C14:K14) -> 994669.46
A15: Utenze | C15: =Utenze!D3 -> 0 | D15: =Utenze!E3 -> 23633.52 | E15: =Utenze!F3 -> 36973.64 | F15: =Utenze!G3 -> 33450 | G15: =Utenze!H3 -> 36500 | H15: =Utenze!I3 -> 28500 | I15: =Utenze!J3 -> 31500 | J15: =Utenze!K3 -> 29500 | K15: =Utenze!L3 -> 41000 | L15: =SUM(C15:K15) -> 261057.16
A16: Materie Prime/Consumo | C16: =MAX('Materie Prime-Consumo '!D3,'Materie Prime-Consumo '!D4) -> 0 | D16: =MAX('Materie Prime-Consumo '!E3,'Materie Prime-Consumo '!E4) -> 49324.14 | E16: =MAX('Materie Prime-Consumo '!F3,'Materie Prime-Consumo '!F4) -> 95000 | F16: =MAX('Materie Prime-Consumo '!G3,'Materie Prime-Consumo '!G4) -> 120000 | G16: =MAX('Materie Prime-Consumo '!H3,'Materie Prime-Consumo '!H4) -> 145000 | H16: =MAX('Materie Prime-Consumo '!I3,'Materie Prime-Consumo '!I4) -> 140000 | I16: =MAX('Materie Prime-Consumo '!J3,'Materie Prime-Consumo '!J4) -> 135000 | J16: =MAX('Materie Prime-Consumo '!K3,'Materie Prime-Consumo '!K4) -> 75000 | K16: =MAX('Materie Prime-Consumo '!L3,'Materie Prime-Consumo '!L4) -> 60000 | L16: =SUM(C16:K16) -> 819324.14
A17: Tasse e Imposte | C17: ='Tasse e Imposte'!D3 -> 0 | D17: ='Tasse e Imposte'!E3 -> 17054 | E17: ='Tasse e Imposte'!F3 -> 140705 | F17: ='Tasse e Imposte'!G3 -> 76000 | G17: ='Tasse e Imposte'!H3 -> 19400 | H17: ='Tasse e Imposte'!I3 -> 23500 | I17: ='Tasse e Imposte'!J3 -> 30730 | J17: ='Tasse e Imposte'!K3 -> 12130 | K17: ='Tasse e Imposte'!L3 -> 0 | L17: =SUM(C17:K17) -> 319519
A18: Commissioni Portali | C18: ='Commisisoni Portali'!D3 -> 0 | D18: ='Commisisoni Portali'!E3 -> 15961.81 | E18: ='Commisisoni Portali'!F3 -> 23105.49 | F18: ='Commisisoni Portali'!G3 -> 39300 | G18: ='Commisisoni Portali'!H3 -> 43300 | H18: ='Commisisoni Portali'!I3 -> 10160 | I18: ='Commisisoni Portali'!J3 -> 28000 | J18: ='Commisisoni Portali'!K3 -> 14000 | K18: ='Commisisoni Portali'!L3 -> 8200 | L18: =SUM(C18:K18) -> 182027.3
A19: Mutui e Finaziamenti | C19: ='Mutui e Finaziamenti'!D3 -> 0 | D19: ='Mutui e Finaziamenti'!E3 -> 13773.46 | E19: ='Mutui e Finaziamenti'!F3 -> 179801.8 | F19: ='Mutui e Finaziamenti'!G3 -> 13659.3 | G19: ='Mutui e Finaziamenti'!H3 -> 13658.59 | H19: ='Mutui e Finaziamenti'!I3 -> 13627.32 | I19: ='Mutui e Finaziamenti'!J3 -> 13657.16 | J19: ='Mutui e Finaziamenti'!K3 -> 13628.34 | K19: ='Mutui e Finaziamenti'!L3 -> 179831.72 | L19: =SUM(C19:K19) -> 441637.69
A20: Consulenze | C20: =Consulenze!D3 -> 0 | D20: =Consulenze!E3 -> 10354.9 | E20: =Consulenze!F3 -> 10354.9 | F20: =Consulenze!G3 -> 38432 | G20: =Consulenze!H3 -> 0 | H20: =Consulenze!I3 -> 23700 | I20: =Consulenze!J3 -> 0 | J20: =Consulenze!K3 -> 0 | K20: =Consulenze!L3 -> 0 | L20: =SUM(C20:K20) -> 82841.8
A21: Godimento Beni di Terzi | C21: ='Godimento Beni di Terzi'!D4 -> 0 | D21: ='Godimento Beni di Terzi'!E4 -> 196998.53 | E21: ='Godimento Beni di Terzi'!F4 -> 299427.16 | F21: ='Godimento Beni di Terzi'!G4 -> 122000 | G21: ='Godimento Beni di Terzi'!H4 -> 120000 | H21: ='Godimento Beni di Terzi'!I4 -> 0 | I21: ='Godimento Beni di Terzi'!J4 -> 0 | J21: ='Godimento Beni di Terzi'!K4 -> 100000 | K21: ='Godimento Beni di Terzi'!L4 -> 0 | L21: =SUM(C21:K21) -> 838425.69
A22: Varie ed Eventuali | C22: =' Varie ed Eventuali'!D3 -> 0 | D22: =' Varie ed Eventuali'!E3 -> 68701.73 | E22: =' Varie ed Eventuali'!F3 -> 72773.46 | F22: =' Varie ed Eventuali'!G3 -> 62534.57 | G22: =' Varie ed Eventuali'!H3 -> 0 | H22: =' Varie ed Eventuali'!I3 -> 0 | I22: =' Varie ed Eventuali'!J3 -> 0 | J22: =' Varie ed Eventuali'!K3 -> 0 | K22: =' Varie ed Eventuali'!L3 -> 0 | L22: =SUM(C22:K22) -> 204009.76
A23: Canoni e servizi | C23: ='Canoni e servizi'!D4 -> 0 | D23: ='Canoni e servizi'!E4 -> 22471.08 | E23: ='Canoni e servizi'!F4 -> 26069.65 | F23: ='Canoni e servizi'!G4 -> 23194.27 | G23: ='Canoni e servizi'!H4 -> 4646.11 | H23: ='Canoni e servizi'!I4 -> 3532.23 | I23: ='Canoni e servizi'!J4 -> 6832.23 | J23: ='Canoni e servizi'!K4 -> 3977.23 | K23: ='Canoni e servizi'!L4 -> 25132.23 | L23: =SUM(C23:K23) -> 115855.03
A24: Deposito Fitto | L24: =SUM(C24:K24) -> 0
A27: TOTALE USCITE | C27: =SUM(C14:C26) -> 0 | D27: =SUM(D14:D26) -> 513973.43 | E27: =SUM(E14:E26) -> 1005180.3 | F27: =SUM(F14:F26) -> 663570.14 | G27: =SUM(G14:G26) -> 537504.7 | H27: =SUM(H14:H26) -> 383019.55 | I27: =SUM(I14:I26) -> 360719.39 | J27: =SUM(J14:J26) -> 423235.57 | K27: =SUM(K14:K26) -> 372163.95 | L27: =SUM(C27:K27) -> 4259367
A29: Cash Flow | C29: =C12-C27 -> 0 | D29: =D12-D27 -> 43646.57 | E29: =E12-E27 -> -254560.3 | F29: =F12-F27 -> 277049.86 | G29: =G12-G27 -> 506115.3 | H29: =H12-H27 -> 352600.45 | I29: =I12-I27 -> -6301.39 | J29: =J12-J27 -> -397615.57 | ... L29: =L12-L27 -> 174390.97
A31: 30/04/2026 | C31: 30/04/2026
A32: Saldo MPS | C32: 251897.54
A33: Saldo Intesa | C33: 87439.92
A35: TOTALE BANCHE | C35: =SUM(C32:C34) -> 339337.46
A37: Saldo di Periodo/Proiettato | C37: =C4+C29 -> 339337.46 | D37: =D4+D29 -> 382984.03 | E37: =E4+E29 -> 128423.73 | F37: =F4+F29 -> 405473.59 | G37: =G4+G29 -> 911588.89 | H37: =H4+H29 -> 1264189.3 | I37: =I4+I29 -> 1257887.9 | J37: =J4+J29 -> 860272.38 | K37: =K4+K29 -> 513728.43 | L37: =K37 -> 513728.43
A39: Fin. MPS 60 mesi | C39: 0 | D39: 0 | E39: 0 | F39: 0 | G39: 0 | H39: 0 | I39: 0 | J39: 0 | K39: 0
A43: TOTALE AFFIDAMENTI | C43: =SUM(C39:C42) -> 0 | D43: =SUM(D39:D42) -> 0 | E43: =SUM(E39:E42) -> 0 | F43: =SUM(F39:F42) -> 0 | G43: =SUM(G39:G42) -> 0 | H43: =SUM(H39:H42) -> 0 | I43: =SUM(I39:I42) -> 0 | J43: =SUM(J39:J42) -> 0 | K43: =SUM(K39:K42) -> 0 | L43: =SUM(C43:K43) -> 0
A45: CASH FLOW CON AFFID. | C45: =C37+C43 -> 339337.46 | D45: =D37+D43 -> 382984.03 | E45: =E37+E43 -> 128423.73 | F45: =F37+F43 -> 405473.59 | G45: =G37+G43 -> 911588.89 | H45: =H37+H43 -> 1264189.3 | I45: =I37+I43 -> 1257887.9 | J45: =J37+J43 -> 860272.38 | K45: =K37+K43 -> 513728.43 | L45: =K45 -> 513728.43

Sheet Salari e Stipendi
D1: 2026
A2: CODICE | D2: APRILE | E2: MAGGIO | F2: GIUGNO | G2: LUGLIO | H2: AGOSTO | I2: SETTEMBRE | J2: OTTOBRE | K2: NOVEMBRE | L2: DICEMBRE
B4: Salari e Stipendi | C4: =SUM(D4:L4) -> 994669.46 | D4: =SUM(D5:D135) -> 0 | E4: =SUM(E5:E135) -> 95700.26 | F4: =SUM(F5:F135) -> 120969.2 | G4: =SUM(G5:G135) -> 135000 | H4: =SUM(H5:H135) -> 155000 | I4: =SUM(I5:I135) -> 140000 | J4: =SUM(J5:J135) -> 115000 | K4: =SUM(K5:K135) -> 175000 | L4: =SUM(L5:L135) -> 58000
A5: 670101 | B5: SALARI | C5: =SUM(D5:L5) -> 648671.46 | E5: 62451 | F5: 76220.46 | G5: 85000 | H5: 95000 | I5: 90000 | J5: 80000 | K5: 120000 | L5: 40000
A6: 350301 | B6: F24 | C6: =SUM(D6:L6) -> 345998 | E6: 33249.26 | F6: 44748.74 | G6: 50000 | H6: 60000 | I6: 50000 | J6: 35000 | K6: 55000 | L6: 18000
C7: =SUM(D7:L7) -> 0
C8: =SUM(D8:L8) -> 0
C9: =SUM(D9:L9) -> 0
C10: =SUM(D10:L10) -> 0
C11: =SUM(D11:L11) -> 0
C12: =SUM(D12:L12) -> 0
C13: =SUM(D13:L13) -> 0
C14: =SUM(D14:L14) -> 0
C15: =SUM(D15:L15) -> 0
C16: =SUM(D16:L16) -> 0
C17: =SUM(D17:L17) -> 0
C18: =SUM(D18:L18) -> 0
... C69: =SUM(D69:L69) -> 0

Sheet Utenze
D1: 2026
A2: CODICE | D2: APRILE | E2: MAGGIO | F2: GIUGNO | G2: LUGLIO | H2: AGOSTO | I2: SETTEMBRE | J2: OTTOBRE | K2: NOVEMBRE | L2: DICEMBRE
B3: Utenze | C3: =SUM(D3:L3) -> 261057.16 | D3: =SUM(D4:D134) -> 0 | E3: =SUM(E4:E134) -> 23633.52 | F3: =SUM(F4:F134) -> 36973.64 | G3: =SUM(G4:G134) -> 33450 | H3: =SUM(H4:H134) -> 36500 | I3: =SUM(I4:I134) -> 28500 | J3: =SUM(J4:J134) -> 31500 | K3: =SUM(K4:K134) -> 29500 | L3: =SUM(L4:L134) -> 41000
A4: 570913 | B4: Energia elettrica | C4: =SUM(D4:L4) -> 146620.09 | E4: 6554.07 | F4: 15066.02 | G4: 20000 | H4: 22000 | I4: 19000 | J4: 17000 | K4: 20000 | L4: 27000
A5: 570919 | B5: Gas | C5: =SUM(D5:L5) -> 51935.95 | E5: 6435.95 | F5: 6500 | G5: 6500 | H5: 6500 | I5: 6500 | J5: 6500 | K5: 6500 | L5: 6500
A6: 18 | B6: Acqua - Ausino | C6: =SUM(D6:L6) -> 35801.12 | E6: 8143.5 | F6: 10407.62 | G6: 4250 | H6: 4500 | J6: 4500 | L6: 4000
A7: 44 | B7: Vodafone (intur) | C7: =SUM(D7:L7) -> 11200 | E7: 2500 | G7: 2700 | I7: 3000 | K7: 3000
A8: 570909 | B8: Connectivia | C8: =SUM(D8:L8) -> 15500 | F8: 5000 | H8: 3500 | J8: 3500 | L8: 3500
C9: =SUM(D9:L9) -> 0
C10: =SUM(D10:L10) -> 0
C11: =SUM(D11:L11) -> 0
C12: =SUM(D12:L12) -> 0
C13: =SUM(D13:L13) -> 0
C14: =SUM(D14:L14) -> 0
C15: =SUM(D15:L15) -> 0
C16: =SUM(D16:L16) -> 0
C17: =SUM(D17:L17) -> 0
C18: =SUM(D18:L18) -> 0
C19: =SUM(D19:L19) -> 0
C20: =SUM(D20:L20) -> 0
... C68: =SUM(D68:L68) -> 0

Sheet Materie Prime-Consumo 
D1: 2026
A2: CODICE | D2: APRILE | E2: MAGGIO | F2: GIUGNO | G2: LUGLIO | H2: AGOSTO | I2: SETTEMBRE | J2: OTTOBRE | K2: NOVEMBRE | L2: DICEMBRE
B3: PREVISIONALE | C3: =SUM(D3:L3) -> 810000 | E3: 40000 | F3: 95000 | G3: 120000 | H3: 145000 | I3: 140000 | J3: 135000 | K3: 75000 | L3: 60000
B4: Materie Prime e Consumo | C4: =SUM(D4:L4) -> 120166.27 | D4: =SUM(D5:D185) -> 0 | E4: =SUM(E5:E185) -> 49324.14 | F4: =SUM(F5:F185) -> 37011.15 | G4: =SUM(G5:G185) -> 22544.44 | H4: =SUM(H5:H185) -> 11286.54 | I4: =SUM(I5:I185) -> 0 | J4: =SUM(J5:J185) -> 0 | K4: =SUM(K5:K185) -> 0 | L4: =SUM(L5:L185) -> 0
A5: 801 | B5: A. Migliore srl | C5: =SUM(D5:L5) -> 0
A6: 281 | B6: Abiti da lavoro Cavaliere srls | C6: =SUM(D6:L6) -> 0
A7: 1183 | B7: Adra srl | C7: =SUM(D7:L7) -> 160.38 | E7: 160.38
A8: 412 | B8: Alberto D'Urso | C8: =SUM(D8:L8) -> 1752.84 | E8: 876.42 | F8: 876.42
A9: 1589 | B9: Alnumar di Garofalo Massimiliano | E9: 1650.48
A10: 92 | B10: Amalfi sei esse | C10: =SUM(D10:L10) -> 14333.14 | F10: 1122.76 | G10: 6384.75 | H10: =131.81+121.08+6522.34+50.4 -> 6825.63
A11: 1720 | B11: Amalfi ghiaccio | E11: 219.6
A12: 131 | B12: Amalfi Web | C12: =SUM(D12:L12) -> 2000.8 | E12: 2000.8
A13: 147 | B13: Amato Filippo | C13: =SUM(D13:L13) -> 0
A14: 325 | B14: Alfera srl | C14: =SUM(D14:L14) -> 0
A15: 916 | B15: Allestimenti Di Palo | C15: =SUM(D15:L15) -> 0
A16: 790 | B16: Amato Prisco pane | C16: =SUM(D16:L16) -> 367.38 | E16: 367.38
A17: 1260 | B17: Aniello Bisogno & Figli | C17: =SUM(D17:L17) -> 0
A18: 667 | B18: Attianese Frutta e Verdura | C18: =SUM(D18:L18) -> 0
A19: 1298 | B19: Apicella Lorenzo | C19: =SUM(D19:L19) -> 0
A20: 758 | B20: B&G Di Palo Commercio | C20: =SUM(D20:L20) -> 0
A21: 74 | B21: Bellagaia | C21: =SUM(D21:L21) -> 3537.31 | F21: 3537.31
A22: 399 | B22: Campitiello Fabio | C22: =SUM(D22:L22) -> 0
A23: 864 | B23: Capuano Raffaele | C23: =SUM(D23:L23) -> 80 | E23: 80
A24: 208 | B24: Casa Vinicola Sammarco | C24: =SUM(D24:L24) -> 666.12 | G24: 666.12
A25: 1137 | B25: Coccorullo Falegnamenria | C25: =SUM(D25:L25) -> 0
A26: 125 | B26: Centro Distribuzione Maglio | C26: =SUM(D26:L26) -> 1086 | F26: 1086
A27: 315 | B27: Centro service Snc | C27: =SUM(D27:L27) -> 0
A28: 423 | B28: Cica | C28: =SUM(D28:L28) -> 2650.14 | E28: =400.13+338.94 -> 739.07 | F28: =78.98+64.3+568.07+749.38 -> 1460.73 | G28: =63.25+387.09 -> 450.34
A29: 417 | B29: Cimmini Filomena | C29: =SUM(D29:L29) -> 51.48 | E29: 51.48
A30: 369 | B30: Creative Idea | C30: =SUM(D30:L30) -> 0
A31: 1003 | B31: Ditta Pansa | C31: =SUM(D31:L31) -> 0
A32: 226 | B32: De Luca | C32: =SUM(D32:L32) -> 768.94 | E32: 768.94
A33: 7 | B33: DG Network | C33: =SUM(D33:L33) -> 0
A34: 161 | B34: Di Sarno Coffee | C34: =SUM(D34:L34) -> 11086.18 | E34: 7289.58 | F34: =9241.54-E34 -> 1951.96 | G34: 1844.64
A35: 32 | B35: Ditta Apicella | C35: =SUM(D35:L35) -> 0
A36: 1003 | B36: Ditta Pansa | C36: =SUM(D36:L36) -> 0
A37: 133 | B37: Fabbrocino Michele | C37: =SUM(D37:L37) -> 5951.6 | F37: 543.4 | G37: =4664.63-F37 -> 4121.23 | H37: 1286.97
A38: 672 | B38: Barela Farmacia | C38: =SUM(D38:L38) -> 0
A39: 127 | B39: Feio Srl | C39: =SUM(D39:L39) -> 969.9 | E39: 969.9
A40: 179 | B40: Ferrigno Maria | C40: =SUM(D40:L40) -> 891 | E40: 891
...

Sheet Tasse e Imposte
D1: 2026
A2: CODICE | D2: APRILE | E2: MAGGIO | F2: GIUGNO | G2: LUGLIO | H2: AGOSTO | I2: SETTEMBRE | J2: OTTOBRE | K2: NOVEMBRE | L2: DICEMBRE
B3: Tasse e Imposte | C3: =SUM(D3:L3) -> 319519 | D3: =SUM(D4:D135) -> 0 | E3: =SUM(E4:E135) -> 17054 | F3: =SUM(F4:F135) -> 140705 | G3: =SUM(G4:G135) -> 76000 | H3: =SUM(H4:H135) -> 19400 | I3: =SUM(I4:I135) -> 23500 | J3: =SUM(J4:J135) -> 30730 | K3: =SUM(K4:K135) -> 12130 | L3: =SUM(L4:L135) -> 0
A4: 710104 | B4: IMU | C4: =SUM(D4:L4) -> 5325 | F4: 5325
A5: 630511 | B5: IMPOSTE | C5: =SUM(D5:L5) -> 7500 | G5: 7500
A6: 630519 | B6: TARI HOTEL | C6: =SUM(D6:L6) -> 0 | G6: 0
A7: 350101 | B7: IVA | C7: =SUM(D7:L7) -> 60000 | G7: 50000 | J7: 10000
A8: 350305 | B8: RITENUTE PROFESSIONISTI (1040)
A9: 390590 | B9: IMPOSTA DI SOGGIORNO HP | C9: =SUM(D9:L9) -> 103200 | E9: 14000 | F9: 12300 | G9: 15000 | H9: 15400 | I9: 19000 | J9: 17500 | K9: 10000
B10: IMPOSTA DI SOGGIORNO AR | C10: =SUM(D10:L10) -> 14540 | E10: 1920 | F10: 1210 | G10: 2400 | H10: 2900 | I10: 2700 | J10: 2030 | K10: 1380
A11: 390593 | B11: IMPOSTA DI SOGGIORNO CVM | C11: =SUM(D11:L11) -> 7954 | E11: 1134 | F11: 870 | G11: 1100 | H11: 1100 | I11: 1800 | J11: 1200 | K11: 750
A12: 630519 | B12: TARI RESIDENCE | C12: =SUM(D12:L12) -> 0
B13: TARI CVM | C13: =SUM(D13:L13) -> 0
B14: IRES/IRAP | C14: =SUM(D14:L14) -> 121000 | F14: 121000
C15: =SUM(D15:L15) -> 0
C16: =SUM(D16:L16) -> 0
C17: =SUM(D17:L17) -> 0
C18: =SUM(D18:L18) -> 0
C19: =SUM(D19:L19) -> 0
C20: =SUM(D20:L20) -> 0
C21: =SUM(D21:L21) -> 0
C22: =SUM(D22:L22) -> 0
C23: =SUM(D23:L23) -> 0
C24: =SUM(D24:L24) -> 0
C25: =SUM(D25:L25) -> 0
C26: =SUM(D26:L26) -> 0
... C69: =SUM(D69:L69) -> 0

Sheet Commisisoni Portali
D1: 2026
A2: CODICE | D2: APRILE | E2: MAGGIO | F2: GIUGNO | G2: LUGLIO | H2: AGOSTO | I2: SETTEMBRE | J2: OTTOBRE | K2: NOVEMBRE | L2: DICEMBRE
B3: Commisisoni Portali | C3: =SUM(D3:L3) -> 182027.3 | D3: =SUM(D4:D130) -> 0 | E3: =SUM(E4:E130) -> 15961.81 | F3: =SUM(F4:F130) -> 23105.49 | G3: =SUM(G4:G130) -> 39300 | H3: =SUM(H4:H130) -> 43300 | I3: =SUM(I4:I130) -> 10160 | J3: =SUM(J4:J130) -> 28000 | K3: =SUM(K4:K130) -> 14000 | L3: =SUM(L4:L130) -> 8200
A4: 57010192 | B4: Commissioni Booking | C4: =SUM(D4:L4) -> 144409.2 | E4: 11549.2 | F4: 16500 | G4: 32000 | H4: 37000 | I4: 4660 | J4: 28000 | K4: 14000 | L4: 700
A5: 57010192 | B5: Commissioni Expedia | C5: =SUM(D5:L5) -> 35583.16 | E5: 2383.16 | F5: 6600 | G5: 7300 | H5: 6300 | I5: 5500 | K5: 0 | L5: 7500
A6: 414 | B6: NEXI PAYMENTS S.p.A. | C6: =SUM(D6:L6) -> 2034.94 | E6: 2029.45 | F6: 5.49
C7: =SUM(D7:L7) -> 0
C8: =SUM(D8:L8) -> 0
C9: =SUM(D9:L9) -> 0
C10: =SUM(D10:L10) -> 0
C11: =SUM(D11:L11) -> 0
C12: =SUM(D12:L12) -> 0
C13: =SUM(D13:L13) -> 0
C14: =SUM(D14:L14) -> 0
C15: =SUM(D15:L15) -> 0
C16: =SUM(D16:L16) -> 0
C17: =SUM(D17:L17) -> 0
C18: =SUM(D18:L18) -> 0
... C64: =SUM(D64:L64) -> 0

Sheet Mutui e Finaziamenti
D1: 2026
A2: CODICE | D2: APRILE | E2: MAGGIO | F2: GIUGNO | G2: LUGLIO | H2: AGOSTO | I2: SETTEMBRE | J2: OTTOBRE | K2: NOVEMBRE | L2: DICEMBRE
B3: Mutui e Finanaziamenti | C3: =SUM(D3:L3) -> 441637.69 | D3: =SUM(D4:D134) -> 0 | E3: =SUM(E4:E134) -> 13773.46 | F3: =SUM(F4:F134) -> 179801.8 | G3: =SUM(G4:G134) -> 13659.3 | H3: =SUM(H4:H134) -> 13658.59 | I3: =SUM(I4:I134) -> 13627.32 | J3: =SUM(J4:J134) -> 13657.16 | K3: =SUM(K4:K134) -> 13628.34 | L3: =SUM(L4:L134) -> 179831.72
A4: 310394 | B4: Mutuo MPS | C4: =SUM(D4:L4) -> 332352 | F4: 166176 | L4: 166176
A5: 310392 | B5: EX Muto Intesa (mps) | C5: =SUM(D5:L5) -> 98134.33 | E5: 12379.54 | F5: 12231.88 | G5: 12265.38 | H5: 12264.67 | I5: 12233.4 | J5: 12263.24 | K5: 12234.42 | L5: 12261.8
A6: 310305 | B6: Finanziamento MPS 75k | C6: =SUM(D6:L6) -> 11151.36 | E6: 1393.92 | F6: 1393.92 | G6: 1393.92 | H6: 1393.92 | I6: 1393.92 | J6: 1393.92 | K6: 1393.92 | L6: 1393.92
C7: =SUM(D7:L7) -> 0
C8: =SUM(D8:L8) -> 0
C9: =SUM(D9:L9) -> 0
C10: =SUM(D10:L10) -> 0
C11: =SUM(D11:L11) -> 0
C12: =SUM(D12:L12) -> 0
C13: =SUM(D13:L13) -> 0
C14: =SUM(D14:L14) -> 0
C15: =SUM(D15:L15) -> 0
C16: =SUM(D16:L16) -> 0
C17: =SUM(D17:L17) -> 0
C18: =SUM(D18:L18) -> 0
... C68: =SUM(D68:L68) -> 0

Sheet Consulenze
D1: 2026
A2: CODICE | D2: APRILE | E2: MAGGIO | F2: GIUGNO | G2: LUGLIO | H2: AGOSTO | I2: SETTEMBRE | J2: OTTOBRE | K2: NOVEMBRE | L2: DICEMBRE
B3: Consulenze | C3: =SUM(D3:L3) -> 82841.8 | D3: =SUM(D4:D134) -> 0 | E3: =SUM(E4:E134) -> 10354.9 | F3: =SUM(F4:F134) -> 10354.9 | G3: =SUM(G4:G134) -> 38432 | H3: =SUM(H4:H134) -> 0 | I3: =SUM(I4:I134) -> 23700 | J3: =SUM(J4:J134) -> 0 | K3: =SUM(K4:K134) -> 0 | L3: =SUM(L4:L134) -> 0
A4: 61010191 | B4: Consulenza del lavoro | C4: =SUM(D4:L4) -> 9822.9 | E4: 3522.9 | G4: 2600 | I4: 3700 | K4: 0
A5: 610101 | B5: Consulenza fiscale | C5: =SUM(D5:L5) -> 10000 | G5: 5000 | I5: 5000
A6: 610105 | B6: Consulenza legale | C6: =SUM(D6:L6) -> 33522.9 | F6: 3522.9 | G6: 15000 | I6: 15000
A7: 610107 | B7: Consulenza notarile | C7: =SUM(D7:L7) -> 0
A8: 1549 | B8: Team Work | C8: =SUM(D8:L8) -> 10248 | E8: 3416 | F8: 3416 | G8: 3416
A9: 630515 | B9: Polizza Generali | C9: =SUM(D9:L9) -> 9000 | G9: 9000
B10: Hospitality Project | C10: =SUM(D10:L10) -> 10248 | E10: 3416 | F10: 3416 | G10: 3416
A11: 1693 | B11: JoAnne Dunn Photographers | C11: =SUM(D11:L11) -> 0
C12: =SUM(D12:L12) -> 0
C13: =SUM(D13:L13) -> 0
C14: =SUM(D14:L14) -> 0
C15: =SUM(D15:L15) -> 0
C16: =SUM(D16:L16) -> 0
C17: =SUM(D17:L17) -> 0
C18: =SUM(D18:L18) -> 0
C19: =SUM(D19:L19) -> 0
C20: =SUM(D20:L20) -> 0
C21: =SUM(D21:L21) -> 0
C22: =SUM(D22:L22) -> 0
C23: =SUM(D23:L23) -> 0
... C68: =SUM(D68:L68) -> 0

Sheet Godimento Beni di Terzi
D1: 2026
A2: CODICE | D2: APRILE | E2: MAGGIO | F2: GIUGNO | G2: LUGLIO | H2: AGOSTO | I2: SETTEMBRE | J2: OTTOBRE | K2: NOVEMBRE | L2: DICEMBRE
B4: Gofimento Beni di Terzi | C4: =SUM(D4:L4) -> 838425.69 | D4: =SUM(D5:D135) -> 0 | E4: =SUM(E5:E135) -> 196998.53 | F4: =SUM(F5:F135) -> 299427.16 | G4: =SUM(G5:G135) -> 122000 | H4: =SUM(H5:H135) -> 120000 | I4: =SUM(I5:I135) -> 0 | J4: =SUM(J5:J135) -> 0 | K4: =SUM(K5:K135) -> 100000 | L4: =SUM(L5:L135) -> 0
A5: 651101 | B5: Fitto Ramo d' Azienda | C5: =SUM(D5:L5) -> 568425.69 | E5: 146998.53 | F5: 299427.16 | G5: 122000
A6: 651101 | B6: Fitto AR | C6: =SUM(D6:L6) -> 120000 | H6: 120000
A7: 651101 | B7: Fitto CVM | C7: =SUM(D7:L7) -> 150000 | E7: 50000 | K7: 100000
C8: =SUM(D8:L8) -> 0
C9: =SUM(D9:L9) -> 0
C10: =SUM(D10:L10) -> 0
C11: =SUM(D11:L11) -> 0
C12: =SUM(D12:L12) -> 0
C13: =SUM(D13:L13) -> 0
C14: =SUM(D14:L14) -> 0
C15: =SUM(D15:L15) -> 0
C16: =SUM(D16:L16) -> 0
C17: =SUM(D17:L17) -> 0
C18: =SUM(D18:L18) -> 0
C19: =SUM(D19:L19) -> 0
... C69: =SUM(D69:L69) -> 0

Sheet Canoni e servizi
D1: 2026
A2: CODICE | D2: APRILE | E2: MAGGIO | F2: GIUGNO | G2: LUGLIO | H2: AGOSTO | I2: SETTEMBRE | J2: OTTOBRE | K2: NOVEMBRE | L2: DICEMBRE
B4: Canoni e servizi | C4: =SUM(D4:L4) -> 115855.03 | D4: =SUM(D5:D131) -> 0 | E4: =SUM(E5:E131) -> 22471.08 | F4: =SUM(F5:F131) -> 26069.65 | G4: =SUM(G5:G131) -> 23194.27 | H4: =SUM(H5:H131) -> 4646.11 | I4: =SUM(I5:I131) -> 3532.23 | J4: =SUM(J5:J131) -> 6832.23 | K4: =SUM(K5:K131) -> 3977.23 | L4: =SUM(L5:L131) -> 25132.23
A5: 12 | B5: Proxima Service | C5: =SUM(D5:L5) -> 6723.42 | E5: 0 | F5: 6723.42
A6: 948 | B6: Hoxell | C6: =SUM(D6:L6) -> 2750.4 | E6: 605.4 | K6: 2145
A7: 10 | B7: Sistemi (E_solver) | C7: =SUM(D7:L7) -> 3832.68 | F7: 1332.68 | I7: 1250 | L7: 1250
B8: Zucchetti | C8: =SUM(D8:L8) -> 16600 | L8: 16600
A9: 1270 | B9: BESTRANK SOCIETA' A | C9: =SUM(D9:L9) -> 0
A10: 81 | B10: PLAN ITALIA S.R.L. | C10: =SUM(D10:L10) -> 15000 | G10: 5000 | J10: 5000 | L10: 5000
B11: Altamira | C11: =SUM(D11:L11) -> 3025.6 | E11: 378.2 | F11: =310*1.22 -> 378.2 | G11: =310*1.22 -> 378.2 | H11: =310*1.22 -> 378.2 | I11: =310*1.22 -> 378.2 | J11: =310*1.22 -> 378.2 | K11: =310*1.22 -> 378.2 | L11: =310*1.22 -> 378.2
A12: 750195 | B12: Commissioni Transato Pos | C12: =SUM(D12:L12) -> 41940.69 | E12: 18033.45 | F12: 15731.32 | G12: 7362.04 | H12: 813.88
A13: 76 | B13: Soft tecnology | C13: =SUM(D13:L13) -> 1350 | F13: 450 | I13: 450 | L13: 450
A14: 750107 | B14: Commissioni e spese Bancarie Varie(Imposta di bollo/tenuta conto/bonifici/etc ) | C14: =SUM(D14:L14) -> 4000 | E14: 2000 | H14: 2000
A15: 1076 | B15: Noleggio Tesla | C15: =SUM(D15:L15) -> 8245.12 | E15: 1030.64 | F15: 1030.64 | G15: 1030.64 | H15: 1030.64 | I15: 1030.64 | J15: 1030.64 | K15: 1030.64 | L15: 1030.64
A16: 1276 | B16: Alba Leasing S.P.A. | C16: =SUM(D16:L16) -> 3387.12 | E16: 423.39 | F16: 423.39 | G16: 423.39 | H16: 423.39 | I16: 423.39 | J16: 423.39 | K16: 423.39 | L16: 423.39
A17: 137 | B17: Primavera Servizi Srl | C17: =SUM(D17:L17) -> 0 | E17: 0 | F17: 0
A18: 630515 | B18: Polizza Generali | C18: =SUM(D18:L18) -> 9000 | G18: 9000
C19: =SUM(D19:L19) -> 0
C20: =SUM(D20:L20) -> 0
C21: =SUM(D21:L21) -> 0
C22: =SUM(D22:L22) -> 0
C23: =SUM(D23:L23) -> 0
C24: =SUM(D24:L24) -> 0
C25: =SUM(D25:L25) -> 0
C26: =SUM(D26:L26) -> 0
C27: =SUM(D27:L27) -> 0
C28: =SUM(D28:L28) -> 0
C29: =SUM(D29:L29) -> 0
C30: =SUM(D30:L30) -> 0
... C66: =SUM(D66:L66) -> 0

Sheet  Varie ed Eventuali
D1: 2026
A2: CODICE | D2: APRILE | E2: MAGGIO | F2: GIUGNO | G2: LUGLIO | H2: AGOSTO | I2: SETTEMBRE | J2: OTTOBRE | K2: NOVEMBRE | L2: DICEMBRE
B3: Variee ed Eventuali | C3: =SUM(D3:L3) -> 204009.76 | D3: =SUM(D4:D134) -> 0 | E3: =SUM(E4:E134) -> 68701.73 | F3: =SUM(F4:F134) -> 72773.46 | G3: =SUM(G4:G134) -> 62534.57 | H3: =SUM(H4:H134) -> 0 | I3: =SUM(I4:I134) -> 0 | J3: =SUM(J4:J134) -> 0 | K3: =SUM(K4:K134) -> 0 | L3: =SUM(L4:L134) -> 0
A4: 801 | B4: A. MIGLIORE S.R.L. | C4: =SUM(D4:L4) -> 60000 | E4: 20000 | F4: 20000 | G4: 20000
A5: 650107 | B5: Spese Condominiali | C5: =SUM(D5:L5) -> 127603.71 | E5: 42534.57 | F5: 42534.57 | G5: 42534.57
A6: 1080 | B6: AUTOSTRADE PER L'ITALIA S.P.A. | C6: =SUM(D6:L6) -> 0
A7: 795 | B7: DEL RISPARMIO | C7: =SUM(D7:L7) -> 0
A8: 1625 | B8: EDILIZIA ED | C8: =SUM(D8:L8) -> 0
A9: 127 | B9: FEIO S.R.L. | C9: =SUM(D9:L9) -> 1939.8 | E9: 969.9 | F9: 969.9
A10: 647 | B10: H & M HENNES & MAURITZ S.R.L. | C10: =SUM(D10:L10) -> 299.13 | E10: 299.13
A11: 1629 | B11: Mana srls | C11: =SUM(D11:L11) -> 825 | E11: 825
A12: 1626 | B12: ROSANTO S.R.L. | C12: =SUM(D12:L12) -> 320 | E12: 160 | F12: 160
A13: 1638 | B13: CENTRO MODA S.R.L. | C13: =SUM(D13:L13) -> 4615.02 | E13: 2618.01 | F13: 1997.01
A14: 1646 | B14: DIECI S.R.L.S. | C14: =SUM(D14:L14) -> 396.02 | E14: 198.01 | F14: 198.01
A15: 1647 | B15: HAIR GALLERY EUROPE SRL | C15: =SUM(D15:L15) -> 31.68 | E15: 15.84 | F15: 15.84
A16: 179 | B16: FERRIGNO MARIA C S N C | C16: =SUM(D16:L16) -> 132 | E16: 66 | F16: 66
A17: 744 | B17: Nola Ferramenta Srl | C17: =SUM(D17:L17) -> 100.02 | E17: 100.02
A18: 1036 | B18: Re Denari di Marco Oliva & C. Sas | C18: =SUM(D18:L18) -> 140 | E18: 140
A19: 70 | B19: MAGALDI LIFE SRL SOC. UNIP. | C19: =SUM(D19:L19) -> 118.22 | E19: 59.11 | F19: 59.11
A20: 1696 | B20: READYPRINT DI PIPITONE BRUNO | C20: =SUM(D20:L20) -> 11.49 | E20: 11.49
A21: 170 | B21: Leroy Merlin Italia srl | C21: =SUM(D21:L21) -> 163.76 | E21: 81.88 | F21: 81.88
A22: 109 | B22: MEDIAMARKET S.P.A. CON SOCIO UNICO | C22: =SUM(D22:L22) -> 427.76 | E22: 213.88 | F22: 213.88
A23: 123 | B23: PREGIS S.P.A. | C23: =SUM(D23:L23) -> 6725.77 | E23: 408.89 | F23: 6316.88
A24: 1183 | B24: ADRA S.R.L. | C24: =SUM(D24:L24) -> 160.38 | F24: 160.38
C25: =SUM(D25:L25) -> 0
C26: =SUM(D26:L26) -> 0
C27: =SUM(D27:L27) -> 0
C28: =SUM(D28:L28) -> 0
C29: =SUM(D29:L29) -> 0
C30: =SUM(D30:L30) -> 0
C31: =SUM(D31:L31) -> 0
C32: =SUM(D32:L32) -> 0
C33: =SUM(D33:L33) -> 0
C34: =SUM(D34:L34) -> 0
C35: =SUM(D35:L35) -> 0
C36: =SUM(D36:L36) -> 0
... C68: =SUM(D68:L68) -> 0
