Workbook

Sheet Controlli
A1: CONTROLLI PIANO FINANZIARIO — ORTI
A3: 1. SALDO PARTENZA
A4: C4:E4 = saldi iniziali hardcoded (mesi chiusi)? | B4: =IF(OR(_xlfn.ISFORMULA('Piano Finanziario'!C4),_xlfn.ISFORMULA('Piano Finanziario'!D4),_xlfn.ISFORMULA('Piano Finanziario'!E4)),"ERRORE","OK")
A5: F4 = E37 (luglio parte da saldo reale giugno)? | B5: =IF('Piano Finanziario'!F4='Piano Finanziario'!E37,"OK","ERRORE")
A6: Catena F4:Q4 = mese prec riga 37? | B6: =IF(AND('Piano Finanziario'!F4='Piano Finanziario'!E37,'Piano Finanziario'!G4='Piano Finanziario'!F37,'Piano Finanziario'!H4='Piano Finanziario'!G37,'Piano Finanziario'!I4='Piano Finanziario'!H37,'Piano Finanziario'!J4='Piano Finanziario'!I37,'Piano Finanziario'!K4='Piano Finanziario'!J37,'Piano Finanziario'!L4='Piano Finanziario'!K37,'Piano Finanziario'!M4='Piano Finanziario'!L37,'Piano Finanziario'!N4='Piano Finanziario'!M37,'Piano Finanziario'!O4='Piano Finanziario'!N37,'Piano Finanziario'!P4='Piano Finanziario'!O37,'Piano Finanziario'!Q4='Piano Finanziario'!P37),"OK","ERRORE")
A7: (non applicabile — mesi passati rimossi) | B7: OK
A9: 2. TOTALE ENTRATE (riga 12)
A10: Riga 12 = SUM(6:11) per mesi C:K? | B10: =IF(AND('Piano Finanziario'!C12=SUM('Piano Finanziario'!C6:'Piano Finanziario'!C11),'Piano Finanziario'!D12=SUM('Piano Finanziario'!D6:'Piano Finanziario'!D11),'Piano Finanziario'!E12=SUM('Piano Finanziario'!E6:'Piano Finanziario'!E11),'Piano Finanziario'!F12=SUM('Piano Finanziario'!F6:'Piano Finanziario'!F11),'Piano Finanziario'!G12=SUM('Piano Finanziario'!G6:'Piano Finanziario'!G11),'Piano Finanziario'!H12=SUM('Piano Finanziario'!H6:'Piano Finanziario'!H11),'Piano Finanziario'!I12=SUM('Piano Finanziario'!I6:'Piano Finanziario'!I11),'Piano Finanziario'!J12=SUM('Piano Finanziario'!J6:'Piano Finanziario'!J11),'Piano Finanziario'!K12=SUM('Piano Finanziario'!K6:'Piano Finanziario'!K11)),"OK","ERRORE")
A12: 3. TOTALE USCITE (riga 27)
A13: Riga 27 = SUM(14:26) per mesi C:K? | B13: =IF(AND('Piano Finanziario'!C27=SUM('Piano Finanziario'!C14:'Piano Finanziario'!C26),'Piano Finanziario'!D27=SUM('Piano Finanziario'!D14:'Piano Finanziario'!D26),'Piano Finanziario'!E27=SUM('Piano Finanziario'!E14:'Piano Finanziario'!E26),'Piano Finanziario'!F27=SUM('Piano Finanziario'!F14:'Piano Finanziario'!F26),'Piano Finanziario'!G27=SUM('Piano Finanziario'!G14:'Piano Finanziario'!G26),'Piano Finanziario'!H27=SUM('Piano Finanziario'!H14:'Piano Finanziario'!H26),'Piano Finanziario'!I27=SUM('Piano Finanziario'!I14:'Piano Finanziario'!I26),'Piano Finanziario'!J27=SUM('Piano Finanziario'!J14:'Piano Finanziario'!J26),'Piano Finanziario'!K27=SUM('Piano Finanziario'!K14:'Piano Finanziario'!K26)),"OK","ERRORE")
A15: 4. CASH FLOW (riga 29)
A16: Riga 29 = Entrate - Uscite per mesi C:K? | B16: =IF(AND('Piano Finanziario'!C29='Piano Finanziario'!C12-'Piano Finanziario'!C27,'Piano Finanziario'!D29='Piano Finanziario'!D12-'Piano Finanziario'!D27,'Piano Finanziario'!E29='Piano Finanziario'!E12-'Piano Finanziario'!E27,'Piano Finanziario'!F29='Piano Finanziario'!F12-'Piano Finanziario'!F27,'Piano Finanziario'!G29='Piano Finanziario'!G12-'Piano Finanziario'!G27,'Piano Finanziario'!H29='Piano Finanziario'!H12-'Piano Finanziario'!H27,'Piano Finanziario'!I29='Piano Finanziario'!I12-'Piano Finanziario'!I27,'Piano Finanziario'!J29='Piano Finanziario'!J12-'Piano Finanziario'!J27,'Piano Finanziario'!K29='Piano Finanziario'!K12-'Piano Finanziario'!K27),"OK","ERRORE")
A21: 6. RIFERIMENTI USCITE — FOGLI DETTAGLIO (mesi I:R)
A22: Riga 14 — Salari e Stipendi | B22: =IF(AND('Piano Finanziario'!C14='Salari e Stipendi'!D4,'Piano Finanziario'!D14='Salari e Stipendi'!E4,'Piano Finanziario'!E14='Salari e Stipendi'!F4,'Piano Finanziario'!F14='Salari e Stipendi'!G4,'Piano Finanziario'!G14='Salari e Stipendi'!H4,'Piano Finanziario'!H14='Salari e Stipendi'!I4,'Piano Finanziario'!I14='Salari e Stipendi'!J4,'Piano Finanziario'!J14='Salari e Stipendi'!K4,'Piano Finanziario'!K14='Salari e Stipendi'!L4),"OK","ERRORE")
A23: Riga 15 — Utenze | B23: =IF(AND('Piano Finanziario'!C15=Utenze!D3,'Piano Finanziario'!D15=Utenze!E3,'Piano Finanziario'!E15=Utenze!F3,'Piano Finanziario'!F15=Utenze!G3,'Piano Finanziario'!G15=Utenze!H3,'Piano Finanziario'!H15=Utenze!I3,'Piano Finanziario'!I15=Utenze!J3,'Piano Finanziario'!J15=Utenze!K3,'Piano Finanziario'!K15=Utenze!L3),"OK","ERRORE")
A24: Riga 16 — Materie Prime/Consumo | B24: =IF(AND('Piano Finanziario'!C16=MAX('Materie Prime-Consumo '!D3,'Materie Prime-Consumo '!D4),'Piano Finanziario'!D16=MAX('Materie Prime-Consumo '!E3,'Materie Prime-Consumo '!E4),'Piano Finanziario'!E16=MAX('Materie Prime-Consumo '!F3,'Materie Prime-Consumo '!F4),'Piano Finanziario'!F16=MAX('Materie Prime-Consumo '!G3,'Materie Prime-Consumo '!G4),'Piano Finanziario'!G16=MAX('Materie Prime-Consumo '!H3,'Materie Prime-Consumo '!H4),'Piano Finanziario'!H16=MAX('Materie Prime-Consumo '!I3,'Materie Prime-Consumo '!I4),'Piano Finanziario'!I16=MAX('Materie Prime-Consumo '!J3,'Materie Prime-Consumo '!J4),'Piano Finanziario'!J16=MAX('Materie Prime-Consumo '!K3,'Materie Prime-Consumo '!K4),'Piano Finanziario'!K16=MAX('Materie Prime-Consumo '!L3,'Materie Prime-Consumo '!L4)),"OK","ERRORE")
A25: Riga 17 — Tasse e Imposte | B25: =IF(AND('Piano Finanziario'!C17='Tasse e Imposte'!D3,'Piano Finanziario'!D17='Tasse e Imposte'!E3,'Piano Finanziario'!E17='Tasse e Imposte'!F3,'Piano Finanziario'!F17='Tasse e Imposte'!G3,'Piano Finanziario'!G17='Tasse e Imposte'!H3,'Piano Finanziario'!H17='Tasse e Imposte'!I3,'Piano Finanziario'!I17='Tasse e Imposte'!J3,'Piano Finanziario'!J17='Tasse e Imposte'!K3,'Piano Finanziario'!K17='Tasse e Imposte'!L3),"OK","ERRORE")
A26: Riga 18 — Commissioni Portali | B26: =IF(AND('Piano Finanziario'!C18='Commisisoni Portali'!D3,'Piano Finanziario'!D18='Commisisoni Portali'!E3,'Piano Finanziario'!E18='Commisisoni Portali'!F3,'Piano Finanziario'!F18='Commisisoni Portali'!G3,'Piano Finanziario'!G18='Commisisoni Portali'!H3,'Piano Finanziario'!H18='Commisisoni Portali'!I3,'Piano Finanziario'!I18='Commisisoni Portali'!J3,'Piano Finanziario'!J18='Commisisoni Portali'!K3,'Piano Finanziario'!K18='Commisisoni Portali'!L3),"OK","ERRORE")
A27: Riga 19 — Mutui e Finanziamenti | B27: =IF(AND('Piano Finanziario'!C19='Mutui e Finaziamenti'!D3,'Piano Finanziario'!D19='Mutui e Finaziamenti'!E3,'Piano Finanziario'!E19='Mutui e Finaziamenti'!F3,'Piano Finanziario'!F19='Mutui e Finaziamenti'!G3,'Piano Finanziario'!G19='Mutui e Finaziamenti'!H3,'Piano Finanziario'!H19='Mutui e Finaziamenti'!I3,'Piano Finanziario'!I19='Mutui e Finaziamenti'!J3,'Piano Finanziario'!J19='Mutui e Finaziamenti'!K3,'Piano Finanziario'!K19='Mutui e Finaziamenti'!L3),"OK","ERRORE")
A28: Riga 20 — Consulenze | B28: =IF(AND('Piano Finanziario'!C20=Consulenze!D3,'Piano Finanziario'!D20=Consulenze!E3,'Piano Finanziario'!E20=Consulenze!F3,'Piano Finanziario'!F20=Consulenze!G3,'Piano Finanziario'!G20=Consulenze!H3,'Piano Finanziario'!H20=Consulenze!I3,'Piano Finanziario'!I20=Consulenze!J3,'Piano Finanziario'!J20=Consulenze!K3,'Piano Finanziario'!K20=Consulenze!L3),"OK","ERRORE")
A29: Riga 21 — Godimento Beni di Terzi | B29: =IF(AND('Piano Finanziario'!C21='Godimento Beni di Terzi'!D4,'Piano Finanziario'!D21='Godimento Beni di Terzi'!E4,'Piano Finanziario'!E21='Godimento Beni di Terzi'!F4,'Piano Finanziario'!F21='Godimento Beni di Terzi'!G4,'Piano Finanziario'!G21='Godimento Beni di Terzi'!H4,'Piano Finanziario'!H21='Godimento Beni di Terzi'!I4,'Piano Finanziario'!I21='Godimento Beni di Terzi'!J4,'Piano Finanziario'!J21='Godimento Beni di Terzi'!K4,'Piano Finanziario'!K21='Godimento Beni di Terzi'!L4),"OK","ERRORE")
A30: Riga 22 — Varie ed Eventuali | B30: =IF(AND('Piano Finanziario'!C22=' Varie ed Eventuali'!D3,'Piano Finanziario'!D22=' Varie ed Eventuali'!E3,'Piano Finanziario'!E22=' Varie ed Eventuali'!F3,'Piano Finanziario'!F22=' Varie ed Eventuali'!G3,'Piano Finanziario'!G22=' Varie ed Eventuali'!H3,'Piano Finanziario'!H22=' Varie ed Eventuali'!I3,'Piano Finanziario'!I22=' Varie ed Eventuali'!J3,'Piano Finanziario'!J22=' Varie ed Eventuali'!K3,'Piano Finanziario'!K22=' Varie ed Eventuali'!L3),"OK","ERRORE")
A31: Riga 23 — Canoni e servizi | B31: =IF(AND('Piano Finanziario'!C23='Canoni e servizi'!D4,'Piano Finanziario'!D23='Canoni e servizi'!E4,'Piano Finanziario'!E23='Canoni e servizi'!F4,'Piano Finanziario'!F23='Canoni e servizi'!G4,'Piano Finanziario'!G23='Canoni e servizi'!H4,'Piano Finanziario'!H23='Canoni e servizi'!I4,'Piano Finanziario'!I23='Canoni e servizi'!J4,'Piano Finanziario'!J23='Canoni e servizi'!K4,'Piano Finanziario'!K23='Canoni e servizi'!L4),"OK","ERRORE")
A33: 7. SALDO PROIETTATO (riga 37)
A34: Riga 37 = riga 4 + riga 29 per mesi attivi I:R? | B34: =IF(AND('Piano Finanziario'!C37='Piano Finanziario'!C4+'Piano Finanziario'!C29,'Piano Finanziario'!D37='Piano Finanziario'!D4+'Piano Finanziario'!D29,'Piano Finanziario'!E37='Piano Finanziario'!E4+'Piano Finanziario'!E29,'Piano Finanziario'!F37='Piano Finanziario'!F4+'Piano Finanziario'!F29,'Piano Finanziario'!G37='Piano Finanziario'!G4+'Piano Finanziario'!G29,'Piano Finanziario'!H37='Piano Finanziario'!H4+'Piano Finanziario'!H29,'Piano Finanziario'!I37='Piano Finanziario'!I4+'Piano Finanziario'!I29,'Piano Finanziario'!J37='Piano Finanziario'!J4+'Piano Finanziario'!J29,'Piano Finanziario'!K37='Piano Finanziario'!K4+'Piano Finanziario'!K29),"OK","ERRORE")
A36: 8. CASH FLOW CON AFFIDAMENTI (riga 45)
A37: Riga 45 = riga 37 + riga 43 per mesi attivi I:R? | B37: =IF(AND('Piano Finanziario'!C45='Piano Finanziario'!C37+'Piano Finanziario'!C43,'Piano Finanziario'!D45='Piano Finanziario'!D37+'Piano Finanziario'!D43,'Piano Finanziario'!E45='Piano Finanziario'!E37+'Piano Finanziario'!E43,'Piano Finanziario'!F45='Piano Finanziario'!F37+'Piano Finanziario'!F43,'Piano Finanziario'!G45='Piano Finanziario'!G37+'Piano Finanziario'!G43,'Piano Finanziario'!H45='Piano Finanziario'!H37+'Piano Finanziario'!H43,'Piano Finanziario'!I45='Piano Finanziario'!I37+'Piano Finanziario'!I43,'Piano Finanziario'!J45='Piano Finanziario'!J37+'Piano Finanziario'!J43,'Piano Finanziario'!K45='Piano Finanziario'!K37+'Piano Finanziario'!K43),"OK","ERRORE")
A39: 9. COLONNA TOTALI (T)
A40: L12 Totale Entrate = SUM(C12:K12)? | B40: =IF('Piano Finanziario'!L12=SUM('Piano Finanziario'!C12:'Piano Finanziario'!K12),"OK","ERRORE")
A41: L27 Totale Uscite = SUM(C27:K27)? | B41: =IF('Piano Finanziario'!L27=SUM('Piano Finanziario'!C27:'Piano Finanziario'!K27),"OK","ERRORE")
A42: L29 Cash Flow = L12 - L27? | B42: =IF('Piano Finanziario'!L29='Piano Finanziario'!L12-'Piano Finanziario'!L27,"OK","ERRORE")
A44: =CONCATENATE("RISULTATO COMPLESSIVO") | B44: =IF(COUNTIF(B4:B42,"ERRORE")=0,"✓ TUTTI I "&COUNTA(B4:B42)&" CONTROLLI OK","✗ "&COUNTIF(B4:B42,"ERRORE")&" ERRORI TROVATI su "&COUNTA(B4:B42)&" verifiche")

Sheet Piano Finanziario
A1: ORTI S.R.L. | C1: 2026 | L1: 2027
C2: APRILE | D2: MAGGIO | E2: GIUGNO | F2: LUGLIO | G2: AGOSTO | H2: SETTEMBRE | I2: OTTOBRE | J2: NOVEMBRE | K2: DICEMBRE | L2: GENNAIO | M2: FEBBRAIO | N2: MARZO | O2: APRILE | P2: MAGGIO | Q2: GIUGNO | R2: TOTALI
A4: SALDO MESE PRECED | C4: 339337.46 | D4: 581125.86 | E4: 863258.63 | F4: =E37 | G4: =F37 | H4: =G37 | I4: =H37 | J4: =I37 | K4: =J37 | L4: =K37 | M4: =L37 | ... Q4: =P37
A6: Entrate Hotel | F6: 750000 | G6: 830000 | H6: 580000 | I6: =110000+160000 | R6: =SUM(C6:Q6)
A7: Entrate Residence | F7: 120000 | G7: 140000 | H7: 100000 | I7: =26000+17000 | R7: =SUM(C7:Q7)
A8: Entrate CVM | F8: 45000 | G8: 48000 | H8: 30000 | I8: =5798+10000 | R8: =SUM(C8:Q8)
A9: Entrate Supermercato | F9: 25620 | G9: 25620 | H9: 25620 | I9: 25620 | J9: 25620 | K9: 25620 | R9: =SUM(C9:Q9)
A10: Rientro Sospesi | R10: =SUM(C10:Q10)
A11: Caparre Intur | R11: =SUM(C11:Q11)
A12: TOTALE ENTRATE | C12: =SUM(C6:C11) | D12: =SUM(D6:D11) | E12: =SUM(E6:E11) | F12: =SUM(F6:F11) | G12: =SUM(G6:G11) | H12: =SUM(H6:H11) | I12: =SUM(I6:I11) | J12: =SUM(J6:J11) | ... Q12: =SUM(Q6:Q11) | R12: =SUM(C12:Q12)
A14: Salari e Stipendi | C14: ='Salari e Stipendi'!D4 | D14: ='Salari e Stipendi'!E4 | E14: ='Salari e Stipendi'!F4 | F14: ='Salari e Stipendi'!G4 | G14: ='Salari e Stipendi'!H4 | H14: ='Salari e Stipendi'!I4 | I14: ='Salari e Stipendi'!J4 | J14: ='Salari e Stipendi'!K4 | ... Q14: ='Salari e Stipendi'!R4 | R14: =SUM(C14:Q14)
A15: Utenze | C15: =Utenze!D3 | D15: =Utenze!E3 | E15: =Utenze!F3 | F15: =Utenze!G3 | G15: =Utenze!H3 | H15: =Utenze!I3 | I15: =Utenze!J3 | J15: =Utenze!K3 | ... Q15: =Utenze!R3 | R15: =SUM(C15:Q15)
A16: Materie Prime/Consumo | C16: =MAX('Materie Prime-Consumo '!D3,'Materie Prime-Consumo '!D4) | D16: =MAX('Materie Prime-Consumo '!E3,'Materie Prime-Consumo '!E4) | E16: =MAX('Materie Prime-Consumo '!F3,'Materie Prime-Consumo '!F4) | F16: =MAX('Materie Prime-Consumo '!G3,'Materie Prime-Consumo '!G4) | G16: =MAX('Materie Prime-Consumo '!H3,'Materie Prime-Consumo '!H4) | H16: =MAX('Materie Prime-Consumo '!I3,'Materie Prime-Consumo '!I4) | I16: =MAX('Materie Prime-Consumo '!J3,'Materie Prime-Consumo '!J4) | J16: =MAX('Materie Prime-Consumo '!K3,'Materie Prime-Consumo '!K4) | ... Q16: =MAX('Materie Prime-Consumo '!R3,'Materie Prime-Consumo '!R4) | R16: =SUM(C16:Q16)
A17: Tasse e Imposte | C17: ='Tasse e Imposte'!D3 | D17: ='Tasse e Imposte'!E3 | E17: ='Tasse e Imposte'!F3 | F17: ='Tasse e Imposte'!G3 | G17: ='Tasse e Imposte'!H3 | H17: ='Tasse e Imposte'!I3 | I17: ='Tasse e Imposte'!J3 | J17: ='Tasse e Imposte'!K3 | ... Q17: ='Tasse e Imposte'!R3 | R17: =SUM(C17:Q17)
A18: Commissioni Portali | C18: ='Commisisoni Portali'!D3 | D18: ='Commisisoni Portali'!E3 | E18: ='Commisisoni Portali'!F3 | F18: ='Commisisoni Portali'!G3 | G18: ='Commisisoni Portali'!H3 | H18: ='Commisisoni Portali'!I3 | I18: ='Commisisoni Portali'!J3 | J18: ='Commisisoni Portali'!K3 | ... Q18: ='Commisisoni Portali'!R3 | R18: =SUM(C18:Q18)
A19: Mutui e Finaziamenti | C19: ='Mutui e Finaziamenti'!D3 | D19: ='Mutui e Finaziamenti'!E3 | E19: ='Mutui e Finaziamenti'!F3 | F19: ='Mutui e Finaziamenti'!G3 | G19: ='Mutui e Finaziamenti'!H3 | H19: ='Mutui e Finaziamenti'!I3 | I19: ='Mutui e Finaziamenti'!J3 | J19: ='Mutui e Finaziamenti'!K3 | ... Q19: ='Mutui e Finaziamenti'!R3 | R19: =SUM(C19:Q19)
A20: Consulenze | C20: =Consulenze!D3 | D20: =Consulenze!E3 | E20: =Consulenze!F3 | F20: =Consulenze!G3 | G20: =Consulenze!H3 | H20: =Consulenze!I3 | I20: =Consulenze!J3 | J20: =Consulenze!K3 | ... Q20: =Consulenze!R3 | R20: =SUM(C20:Q20)
A21: Godimento Beni di Terzi | C21: ='Godimento Beni di Terzi'!D4 | D21: ='Godimento Beni di Terzi'!E4 | E21: ='Godimento Beni di Terzi'!F4 | F21: ='Godimento Beni di Terzi'!G4 | G21: ='Godimento Beni di Terzi'!H4 | H21: ='Godimento Beni di Terzi'!I4 | I21: ='Godimento Beni di Terzi'!J4 | J21: ='Godimento Beni di Terzi'!K4 | ... Q21: ='Godimento Beni di Terzi'!R4 | R21: =SUM(C21:Q21)
A22: Varie ed Eventuali | C22: =' Varie ed Eventuali'!D3 | D22: =' Varie ed Eventuali'!E3 | E22: =' Varie ed Eventuali'!F3 | F22: =' Varie ed Eventuali'!G3 | G22: =' Varie ed Eventuali'!H3 | H22: =' Varie ed Eventuali'!I3 | I22: =' Varie ed Eventuali'!J3 | J22: =' Varie ed Eventuali'!K3 | ... Q22: =' Varie ed Eventuali'!R3 | R22: =SUM(C22:Q22)
A23: Canoni e servizi | C23: ='Canoni e servizi'!D4 | D23: ='Canoni e servizi'!E4 | E23: ='Canoni e servizi'!F4 | F23: ='Canoni e servizi'!G4 | G23: ='Canoni e servizi'!H4 | H23: ='Canoni e servizi'!I4 | I23: ='Canoni e servizi'!J4 | J23: ='Canoni e servizi'!K4 | ... Q23: ='Canoni e servizi'!R4 | R23: =SUM(C23:Q23)
A24: Deposito Fitto | R24: =SUM(C24:Q24)
A27: TOTALE USCITE | C27: =SUM(C14:C26) | D27: =SUM(D14:D26) | E27: =SUM(E14:E26) | F27: =SUM(F14:F26) | G27: =SUM(G14:G26) | H27: =SUM(H14:H26) | I27: =SUM(I14:I26) | J27: =SUM(J14:J26) | ... Q27: =SUM(Q14:Q26) | R27: =SUM(C27:Q27)
A29: Cash Flow | C29: =C12-C27 | D29: =D12-D27 | E29: =E12-E27 | F29: =F12-F27 | G29: =G12-G27 | H29: =H12-H27 | I29: =I12-I27 | J29: =J12-J27 | ... R29: =R12-R27
A31: 30/04/2026 | C31: 30/04/2026 | D31: 31/05/2026 | E31: 30/06/2026
A32: Saldo MPS | B32: 30/06/2026 | C32: 726,946.18 € | D32: 469192.55 | E32: 726946.18
A33: Saldo Intesa | C33: 136,312.45 € | D33: 111933.31 | E33: 136312.45
A35: TOTALE BANCHE | C35: =SUM(C32:C34)
A37: Saldo di Periodo/Proiettato | C37: =C4+C29 | D37: =D4+D29 | E37: =E4+E29 | F37: =F4+F29 | G37: =G4+G29 | H37: =H4+H29 | I37: =I4+I29 | J37: =J4+J29 | ... Q37: =Q4+Q29 | R37: =Q37
A39: Fin. MPS 60 mesi | C39: 0 | D39: 0 | E39: 0 | F39: 0 | G39: 0 | H39: 0 | I39: 0 | J39: 0 | K39: 0
A43: TOTALE AFFIDAMENTI | C43: =SUM(C39:C42) | D43: =SUM(D39:D42) | E43: =SUM(E39:E42) | F43: =SUM(F39:F42) | G43: =SUM(G39:G42) | H43: =SUM(H39:H42) | I43: =SUM(I39:I42) | J43: =SUM(J39:J42) | ... Q43: =SUM(Q39:Q42) | R43: =SUM(C43:Q43)
A45: CASH FLOW CON AFFID. | C45: =C37+C43 | D45: =D37+D43 | E45: =E37+E43 | F45: =F37+F43 | G45: =G37+G43 | H45: =H37+H43 | I45: =I37+I43 | J45: =J37+J43 | ... Q45: =Q37+Q43 | R45: =Q45

Sheet Salari e Stipendi
D1: 2026 | M1: 2027
A2: CODICE | D2: APRILE | E2: MAGGIO | F2: GIUGNO | G2: LUGLIO | H2: AGOSTO | I2: SETTEMBRE | J2: OTTOBRE | K2: NOVEMBRE | L2: DICEMBRE | M2: GENNAIO | N2: FEBBRAIO | O2: MARZO | P2: APRILE | Q2: MAGGIO | R2: GIUGNO
B4: Salari e Stipendi | C4: =SUM(D4:L4) | D4: =SUM(D5:D135) | E4: =SUM(E5:E135) | F4: =SUM(F5:F135) | G4: =SUM(G5:G135) | H4: =SUM(H5:H135) | I4: =SUM(I5:I135) | J4: =SUM(J5:J135) | K4: =SUM(K5:K135) | ... R4: =SUM(R5:R135)
A5: 670101 | B5: SALARI | C5: =SUM(D5:L5) | G5: 94171.34 | H5: 95000 | I5: 90000 | J5: 80000 | K5: 120000 | L5: 40000
A6: 350301 | B6: F24 | C6: =SUM(D6:L6) | G6: 59500 | H6: 60000 | I6: 50000 | J6: 35000 | K6: 55000 | L6: 18000
C7: =SUM(D7:L7)
C8: =SUM(D8:L8)
C9: =SUM(D9:L9)
C10: =SUM(D10:L10)
C11: =SUM(D11:L11)
C12: =SUM(D12:L12)
C13: =SUM(D13:L13)
C14: =SUM(D14:L14)
C15: =SUM(D15:L15)
C16: =SUM(D16:L16)
C17: =SUM(D17:L17)
C18: =SUM(D18:L18)
... C69: =SUM(D69:L69)

Sheet Utenze
D1: 2026 | M1: 2027
A2: CODICE | D2: APRILE | E2: MAGGIO | F2: GIUGNO | G2: LUGLIO | H2: AGOSTO | I2: SETTEMBRE | J2: OTTOBRE | K2: NOVEMBRE | L2: DICEMBRE | M2: GENNAIO | N2: FEBBRAIO | O2: MARZO | P2: APRILE | Q2: MAGGIO | R2: GIUGNO
B3: Utenze | C3: =SUM(D3:L3) | D3: =SUM(D4:D134) | E3: =SUM(E4:E134) | F3: =SUM(F4:F134) | G3: =SUM(G4:G134) | H3: =SUM(H4:H134) | I3: =SUM(I4:I134) | J3: =SUM(J4:J134) | K3: =SUM(K4:K134) | ... R3: =SUM(R4:R134)
A4: 570913 | B4: Energia elettrica | C4: =SUM(D4:L4) | G4: 27525.61 | H4: 33530.5 | I4: 19000 | J4: 17000 | K4: 20000 | L4: 27000
A5: 570919 | B5: Gas | C5: =SUM(D5:L5) | G5: 6500 | H5: 6500 | I5: 6500 | J5: 6500 | K5: 6500 | L5: 6500
A6: 18 | B6: Acqua - Ausino | C6: =SUM(D6:L6) | H6: 2143.09
A7: 44 | B7: Vodafone (intur) | C7: =SUM(D7:L7)
A8: 570909 | B8: Connectivia | C8: =SUM(D8:L8) | H8: 3500 | J8: 3500 | L8: 3500
C9: =SUM(D9:L9)
C10: =SUM(D10:L10)
C11: =SUM(D11:L11)
C12: =SUM(D12:L12)
C13: =SUM(D13:L13)
C14: =SUM(D14:L14)
C15: =SUM(D15:L15)
C16: =SUM(D16:L16)
C17: =SUM(D17:L17)
C18: =SUM(D18:L18)
C19: =SUM(D19:L19)
C20: =SUM(D20:L20)
... C68: =SUM(D68:L68)

Sheet Materie Prime-Consumo 
D1: 2026 | M1: 2027
A2: CODICE | D2: APRILE | E2: MAGGIO | F2: GIUGNO | G2: LUGLIO | H2: AGOSTO | I2: SETTEMBRE | J2: OTTOBRE | K2: NOVEMBRE | L2: DICEMBRE | M2: GENNAIO | N2: FEBBRAIO | O2: MARZO | P2: APRILE | Q2: MAGGIO | R2: GIUGNO
B3: PREVISIONALE | C3: =SUM(D3:L3) | G3: 120000 | H3: 145000 | I3: 140000 | J3: 135000 | K3: 75000 | L3: 60000
B4: Materie Prime e Consumo | C4: =SUM(D4:L4) | D4: =SUM(D5:D184) | E4: =SUM(E5:E184) | F4: =SUM(F5:F184) | G4: =SUM(G5:G184) | H4: =SUM(H5:H184) | I4: =SUM(I5:I184) | J4: =SUM(J5:J184) | K4: =SUM(K5:K184) | ... R4: =SUM(R5:R184)
A5: 801 | B5: A. Migliore srl | C5: =SUM(D5:L5)
A6: 281 | B6: Abiti da lavoro Cavaliere srls | C6: =SUM(D6:L6)
A7: 1183 | B7: Adra srl | C7: =SUM(D7:L7) | H7: 839.47 | I7: 990.71
A8: 412 | B8: Alberto D'Urso | C8: =SUM(D8:L8) | G8: 761.92
A9: 1589 | B9: Alnumar di Garofalo Massimiliano | C9: =SUM(D9:L9) | G9: 1920.41 | H9: 1895.84
A10: 92 | B10: Amalfi sei esse | C10: =SUM(D10:L10) | G10: 6384.75 | H10: 6825.63 | I10: 9528.63 | J10: 11654.67 | K10: 89.77
A11: 1720 | B11: Amalfi ghiaccio | C11: =SUM(D11:L11)
A12: 131 | B12: Amalfi Web | C12: =SUM(D12:L12)
A13: 147 | B13: Amato Filippo | C13: =SUM(D13:L13)
A14: 325 | B14: Alfera srl | C14: =SUM(D14:L14) | H14: 2260 | I14: 2976.01
A15: 916 | B15: Allestimenti Di Palo | C15: =SUM(D15:L15)
A16: 790 | B16: Amato Prisco pane | C16: =SUM(D16:L16) | G16: 474.24 | H16: 836.16
A17: 1260 | B17: Aniello Bisogno & Figli | C17: =SUM(D17:L17)
A18: 667 | B18: Attianese Frutta e Verdura | C18: =SUM(D18:L18)
A19: 1298 | B19: Apicella Lorenzo | C19: =SUM(D19:L19)
A20: 758 | B20: B&G Di Palo Commercio | C20: =SUM(D20:L20)
A21: 74 | B21: Bellagaia | C21: =SUM(D21:L21) | G21: 8248.92 | H21: 6061.72 | I21: 1666.67
A22: 399 | B22: Campitiello Fabio | C22: =SUM(D22:L22)
A23: 864 | B23: Capuano Raffaele | C23: =SUM(D23:L23) | G23: 80
A24: 208 | B24: Casa Vinicola Sammarco | C24: =SUM(D24:L24) | G24: 666.12 | H24: 1141.92 | I24: 937.31 | J24: 146.03
A25: 1137 | B25: Coccorullo Falegnamenria | C25: =SUM(D25:L25)
A26: 125 | B26: Centro Distribuzione Maglio | C26: =SUM(D26:L26) | G26: 1588.4 | H26: 1504.8
A27: 315 | B27: Centro service Snc | C27: =SUM(D27:L27) | H27: 513.62
A28: 423 | B28: Cica | C28: =SUM(D28:L28) | G28: 2062.02 | H28: 2834.35 | I28: 221.32
A29: 417 | B29: Cimmini Filomena | C29: =SUM(D29:L29) | G29: 51.48
A30: 369 | B30: Creative Idea | C30: =SUM(D30:L30)
A31: 1003 | B31: Ditta Pansa | C31: =SUM(D31:L31) | H31: 90
A32: 226 | B32: De Luca | C32: =SUM(D32:L32)
A33: 7 | B33: DG Network | C33: =SUM(D33:L33)
A34: 161 | B34: Di Sarno Coffee | C34: =SUM(D34:L34) | G34: 8248.04 | H34: 6307.94
A35: 32 | B35: Ditta Apicella | C35: =SUM(D35:L35)
A36: 1003 | B36: Ditta Pansa | C36: =SUM(D36:L36)
A37: 133 | B37: Fabbrocino Michele | C37: =SUM(D37:L37) | G37: 3183.82 | H37: 9238 | I37: 10345.23 | J37: 1786.56
A38: 672 | B38: Barela Farmacia | C38: =SUM(D38:L38)
A39: 127 | B39: Feio Srl | C39: =SUM(D39:L39) | G39: 1697.14 | H39: 1380.55 | I39: 253.27
A40: 179 | B40: Ferrigno Maria | C40: =SUM(D40:L40) | H40: 33
...

Sheet Tasse e Imposte
D1: 2026 | M1: 2027
A2: CODICE | D2: APRILE | E2: MAGGIO | F2: GIUGNO | G2: LUGLIO | H2: AGOSTO | I2: SETTEMBRE | J2: OTTOBRE | K2: NOVEMBRE | L2: DICEMBRE | M2: GENNAIO | N2: FEBBRAIO | O2: MARZO | P2: APRILE | Q2: MAGGIO | R2: GIUGNO
B3: Tasse e Imposte | C3: =SUM(D3:L3) | D3: =SUM(D4:D136) | E3: =SUM(E4:E136) | F3: =SUM(F4:F136) | G3: =SUM(G4:G136) | H3: =SUM(H4:H136) | I3: =SUM(I4:I136) | J3: =SUM(J4:J136) | K3: =SUM(K4:K136) | ... R3: =SUM(R4:R136)
A4: 710104 | B4: IMU | C4: =SUM(D4:L4)
A5: 630511 | B5: IMPOSTE | C5: =SUM(D5:L5) | G5: 24151.2 | H5: 24221.24 | I5: 24300.94 | J5: 24380.64 | K5: =24460.34+46000 | M5: NOVEMBRE I ACCONTO E II ACCONTO TOTALI
A6: 630519 | B6: TARI HOTEL | C6: =SUM(D6:L6) | G6: 0 | I6: 85000
A7: 350101 | B7: IVA | C7: =SUM(D7:L7) | G7: 50000 | J7: 10000
A8: 350305 | B8: RITENUTE PROFESSIONISTI (1040)
A9: 390590 | B9: IMPOSTA DI SOGGIORNO HP | C9: =SUM(D9:L9) | G9: 18296 | H9: 20000 | I9: 19000 | J9: 17500 | K9: 10000
B10: IMPOSTA DI SOGGIORNO AR | C10: =SUM(D10:L10) | G10: 1834 | H10: 2900 | I10: 2700 | J10: 2030 | K10: 1380
A11: 390593 | B11: IMPOSTA DI SOGGIORNO CVM | C11: =SUM(D11:L11) | G11: 934 | H11: 1100 | I11: 1800 | J11: 1200 | K11: 750
B12: IMPOSTA DI SOGGIORNO APT | C12: =SUM(D12:L12) | G12: 222 | H12: 350 | I12: 200 | J12: 150
A13: 630519 | B13: TARI RESIDENCE | C13: =SUM(D13:L13)
B14: TARI CVM | C14: =SUM(D14:L14)
B15: IRES/IRAP | C15: =SUM(D15:L15)
C16: =SUM(D16:L16)
C17: =SUM(D17:L17)
C18: =SUM(D18:L18)
C19: =SUM(D19:L19)
C20: =SUM(D20:L20)
C21: =SUM(D21:L21)
C22: =SUM(D22:L22)
C23: =SUM(D23:L23)
C24: =SUM(D24:L24)
C25: =SUM(D25:L25)
C26: =SUM(D26:L26)
C27: =SUM(D27:L27)
... C70: =SUM(D70:L70)

Sheet Commisisoni Portali
D1: 2026 | M1: 2027
A2: CODICE | D2: APRILE | E2: MAGGIO | F2: GIUGNO | G2: LUGLIO | H2: AGOSTO | I2: SETTEMBRE | J2: OTTOBRE | K2: NOVEMBRE | L2: DICEMBRE | M2: GENNAIO | N2: FEBBRAIO | O2: MARZO | P2: APRILE | Q2: MAGGIO | R2: GIUGNO
B3: Commisisoni Portali | C3: =SUM(D3:L3) | D3: =SUM(D4:D130) | E3: =SUM(E4:E130) | F3: =SUM(F4:F130) | G3: =SUM(G4:G130) | H3: =SUM(H4:H130) | I3: =SUM(I4:I130) | J3: =SUM(J4:J130) | K3: =SUM(K4:K130) | ... R3: =SUM(R4:R130)
A4: 57010192 | B4: Commissioni Booking | C4: =SUM(D4:L4) | G4: 37280 | H4: 38000 | I4: 5000 | J4: 28000 | K4: 14000 | L4: 700
A5: 57010192 | B5: Commissioni Expedia | C5: =SUM(D5:L5) | G5: 6617 | H5: 6300 | I5: 5500 | K5: 0 | L5: 7500
A6: 414 | B6: NEXI PAYMENTS S.p.A. | C6: =SUM(D6:L6) | G6: 70.51
C7: =SUM(D7:L7)
C8: =SUM(D8:L8)
C9: =SUM(D9:L9)
C10: =SUM(D10:L10)
C11: =SUM(D11:L11)
C12: =SUM(D12:L12)
C13: =SUM(D13:L13)
C14: =SUM(D14:L14)
C15: =SUM(D15:L15)
C16: =SUM(D16:L16)
C17: =SUM(D17:L17)
C18: =SUM(D18:L18)
... C64: =SUM(D64:L64)

Sheet Mutui e Finaziamenti
D1: 2026 | M1: 2027
A2: CODICE | D2: APRILE | E2: MAGGIO | F2: GIUGNO | G2: LUGLIO | H2: AGOSTO | I2: SETTEMBRE | J2: OTTOBRE | K2: NOVEMBRE | L2: DICEMBRE | M2: GENNAIO | N2: FEBBRAIO | O2: MARZO | P2: APRILE | Q2: MAGGIO | R2: GIUGNO
B3: Mutui e Finanaziamenti | C3: =SUM(D3:L3) | D3: =SUM(D4:D134) | E3: =SUM(E4:E134) | F3: =SUM(F4:F134) | G3: =SUM(G4:G134) | H3: =SUM(H4:H134) | I3: =SUM(I4:I134) | J3: =SUM(J4:J134) | K3: =SUM(K4:K134) | ... R3: =SUM(R4:R134)
A4: 310394 | B4: Mutuo MPS | C4: =SUM(D4:L4) | L4: 166176
A5: 310392 | B5: EX Muto Intesa (mps) | C5: =SUM(D5:L5) | G5: 12265.38 | H5: 12264.67 | I5: 12233.4 | J5: 12263.24 | K5: 12234.42 | L5: 12261.8
A6: 310305 | B6: Finanziamento MPS 75k | C6: =SUM(D6:L6) | G6: 1393.92 | H6: 1393.92 | I6: 1393.92 | J6: 1393.92 | K6: 1393.92 | L6: 1393.92
C7: =SUM(D7:L7)
C8: =SUM(D8:L8)
C9: =SUM(D9:L9)
C10: =SUM(D10:L10)
C11: =SUM(D11:L11)
C12: =SUM(D12:L12)
C13: =SUM(D13:L13)
C14: =SUM(D14:L14)
C15: =SUM(D15:L15)
C16: =SUM(D16:L16)
C17: =SUM(D17:L17)
C18: =SUM(D18:L18)
... C68: =SUM(D68:L68)

Sheet Consulenze
D1: 2026 | M1: 2027
A2: CODICE | D2: APRILE | E2: MAGGIO | F2: GIUGNO | G2: LUGLIO | H2: AGOSTO | I2: SETTEMBRE | J2: OTTOBRE | K2: NOVEMBRE | L2: DICEMBRE | M2: GENNAIO | N2: FEBBRAIO | O2: MARZO | P2: APRILE | Q2: MAGGIO | R2: GIUGNO
B3: Consulenze | C3: =SUM(D3:L3) | D3: =SUM(D4:D134) | E3: =SUM(E4:E134) | F3: =SUM(F4:F134) | G3: =SUM(G4:G134) | H3: =SUM(H4:H134) | I3: =SUM(I4:I134) | J3: =SUM(J4:J134) | K3: =SUM(K4:K134) | ... R3: =SUM(R4:R134)
A4: 61010191 | B4: Consulenza del lavoro | C4: =SUM(D4:L4) | G4: 2292.04 | I4: 3700 | K4: 0
A5: 610101 | B5: Consulenza fiscale | C5: =SUM(D5:L5) | G5: 5193.6 | I5: 5500
A6: 610105 | B6: Consulenza legale | C6: =SUM(D6:L6) | G6: 0 | H6: 2292.04 | I6: 15000
A7: 610107 | B7: Consulenza notarile | C7: =SUM(D7:L7)
A8: 1549 | B8: Team Work | C8: =SUM(D8:L8)
A9: 630515 | B9: Polizza Generali | C9: =SUM(D9:L9) | G9: 9000
B10: Hospitality Project | C10: =SUM(D10:L10) | G10: 3416 | H10: 3416 | I10: 3416
A11: 1693 | B11: JoAnne Dunn Photographers | C11: =SUM(D11:L11)
A12: 369 | B12: Creative Idea S.N.C. Di De Martino Diodato & C. | C12: =SUM(D12:L12) | G12: 3111
A13: 132 | B13: STUDIO QUATTRO S.R.L. | C13: =SUM(D13:L13) | G13: 1742.16
C14: =SUM(D14:L14)
C15: =SUM(D15:L15)
C16: =SUM(D16:L16)
C17: =SUM(D17:L17)
C18: =SUM(D18:L18)
C19: =SUM(D19:L19)
C20: =SUM(D20:L20)
C21: =SUM(D21:L21)
C22: =SUM(D22:L22)
C23: =SUM(D23:L23)
C24: =SUM(D24:L24)
C25: =SUM(D25:L25)
... C68: =SUM(D68:L68)

Sheet Godimento Beni di Terzi
D1: 2026 | M1: 2027
A2: CODICE | D2: APRILE | E2: MAGGIO | F2: GIUGNO | G2: LUGLIO | H2: AGOSTO | I2: SETTEMBRE | J2: OTTOBRE | K2: NOVEMBRE | L2: DICEMBRE | M2: GENNAIO | N2: FEBBRAIO | O2: MARZO | P2: APRILE | Q2: MAGGIO | R2: GIUGNO
B4: Gofimento Beni di Terzi | C4: =SUM(D4:L4) | D4: =SUM(D5:D135) | E4: =SUM(E5:E135) | F4: =SUM(F5:F135) | G4: =SUM(G5:G135) | H4: =SUM(H5:H135) | I4: =SUM(I5:I135) | J4: =SUM(J5:J135) | K4: =SUM(K5:K135) | ... R4: =SUM(R5:R135)
A5: 651101 | B5: Fitto Ramo d' Azienda | C5: =SUM(D5:L5) | G5: 446425.69 | H5: 0 | J5: 244000 | L5: 730918
A6: 651101 | B6: Fitto AR | C6: =SUM(D6:L6) | G6: 60000 | H6: 60000
A7: 651101 | B7: Fitto CVM | C7: =SUM(D7:L7) | G7: 100000 | K7: 50000
C8: =SUM(D8:L8)
C9: =SUM(D9:L9)
C10: =SUM(D10:L10)
C11: =SUM(D11:L11)
C12: =SUM(D12:L12)
C13: =SUM(D13:L13)
C14: =SUM(D14:L14)
C15: =SUM(D15:L15)
C16: =SUM(D16:L16)
C17: =SUM(D17:L17)
C18: =SUM(D18:L18)
C19: =SUM(D19:L19)
... C69: =SUM(D69:L69)

Sheet Canoni e servizi
D1: 2026 | M1: 2027
A2: CODICE | D2: APRILE | E2: MAGGIO | F2: GIUGNO | G2: LUGLIO | H2: AGOSTO | I2: SETTEMBRE | J2: OTTOBRE | K2: NOVEMBRE | L2: DICEMBRE | M2: GENNAIO | N2: FEBBRAIO | O2: MARZO | P2: APRILE | Q2: MAGGIO | R2: GIUGNO
B4: Canoni e servizi | C4: =SUM(D4:L4) | D4: =SUM(D5:D131) | E4: =SUM(E5:E131) | F4: =SUM(F5:F131) | G4: =SUM(G5:G131) | H4: =SUM(H5:H131) | I4: =SUM(I5:I131) | J4: =SUM(J5:J131) | K4: =SUM(K5:K131) | ... R4: =SUM(R5:R131)
A5: 12 | B5: Proxima Service | C5: =SUM(D5:L5)
A6: 948 | B6: Hoxell | C6: =SUM(D6:L6)
A7: 10 | B7: Sistemi (E_solver) | C7: =SUM(D7:L7)
B8: Zucchetti | C8: =SUM(D8:L8) | G8: 152.5 | L8: 16600
A9: 1270 | B9: BESTRANK SOCIETA' A | C9: =SUM(D9:L9)
A10: 81 | B10: PLAN ITALIA S.R.L. | C10: =SUM(D10:L10)
B11: Altamira | C11: =SUM(D11:L11) | G11: =310*1.22 | H11: 378.2 | I11: =310*1.22 | J11: =310*1.22 | K11: =310*1.22 | L11: =310*1.22 | M11: =310*1.22 | N11: =310*1.22 | O11: =310*1.22 | P11: =310*1.22 | ... R11: =310*1.22
A12: 750195 | B12: Commissioni Transato Pos | C12: =SUM(D12:L12) | G12: 7362.04 | H12: 813.88
A13: 76 | B13: Soft tecnology | C13: =SUM(D13:L13) | H13: 279.5
A14: 750107 | B14: Commissioni e spese Bancarie Varie(Imposta di bollo/tenuta conto/bonifici/etc ) | C14: =SUM(D14:L14) | H14: 2000
A15: 1076 | B15: Noleggio Tesla | C15: =SUM(D15:L15)
A16: 1276 | B16: Alba Leasing S.P.A. | C16: =SUM(D16:L16)
A17: 137 | B17: Primavera Servizi Srl | C17: =SUM(D17:L17) | H17: 73.2
A18: 630515 | B18: Polizza Generali | C18: =SUM(D18:L18) | G18: 9000
A19: 52 | B19: Aruba | C19: =SUM(D19:L19) | G19: 14.52
A20: 654 | B20: GOOGLE CLOUD ITALY S.R.L. | C20: =SUM(D20:L20) | G20: 24.04
A21: 1222 | B21: Pietra Di Luna Hotel - S.R.L. | C21: =SUM(D21:L21) | G21: 921.1
A22: 1010 | B22: VALLOUFFICIO SOLUZIONI di Zavaglia Nicola & C. S.A.S. | C22: =SUM(D22:L22) | G22: 366
A23: 131 | B23: Amalfiweb S.r.l.s. | C23: =SUM(D23:L23) | I23: 1439.6
A24: 1078 | B24: Intesa Sanpaolo S.p.a | C24: =SUM(D24:L24) | H24: 95.12
C25: =SUM(D25:L25)
C26: =SUM(D26:L26)
C27: =SUM(D27:L27)
C28: =SUM(D28:L28)
C29: =SUM(D29:L29)
C30: =SUM(D30:L30)
C31: =SUM(D31:L31)
C32: =SUM(D32:L32)
C33: =SUM(D33:L33)
C34: =SUM(D34:L34)
C35: =SUM(D35:L35)
C36: =SUM(D36:L36)
... C66: =SUM(D66:L66)

Sheet  Varie ed Eventuali
D1: 2026 | M1: 2027
A2: CODICE | D2: APRILE | E2: MAGGIO | F2: GIUGNO | G2: LUGLIO | H2: AGOSTO | I2: SETTEMBRE | J2: OTTOBRE | K2: NOVEMBRE | L2: DICEMBRE | M2: GENNAIO | N2: FEBBRAIO | O2: MARZO | P2: APRILE | Q2: MAGGIO | R2: GIUGNO
B3: Variee ed Eventuali | C3: =SUM(D3:L3) | D3: =SUM(D4:D133) | E3: =SUM(E4:E133) | F3: =SUM(F4:F133) | G3: =SUM(G4:G133) | H3: =SUM(H4:H133) | I3: =SUM(I4:I133) | J3: =SUM(J4:J133) | K3: =SUM(K4:K133) | ... R3: =SUM(R4:R133)
A4: 650107 | B4: Spese Condominiali | C4: =SUM(D4:L4) | H4: 13534.88 | I4: 6767.44 | J4: 6767.44 | K4: 6767.44 | L4: 6767.44
A5: 1080 | B5: AUTOSTRADE PER L'ITALIA S.P.A. | C5: =SUM(D5:L5)
A6: 795 | B6: DEL RISPARMIO | C6: =SUM(D6:L6)
A7: 1625 | B7: EDILIZIA ED | C7: =SUM(D7:L7)
A8: 127 | B8: FEIO S.R.L. | C8: =SUM(D8:L8)
A9: 647 | B9: H & M HENNES & MAURITZ S.R.L. | C9: =SUM(D9:L9)
A10: 1629 | B10: Mana srls | C10: =SUM(D10:L10) | G10: 1650
A11: 1626 | B11: ROSANTO S.R.L. | C11: =SUM(D11:L11)
A12: 1638 | B12: CENTRO MODA S.R.L. | C12: =SUM(D12:L12) | G12: 1997.01
A13: 1646 | B13: DIECI S.R.L.S. | C13: =SUM(D13:L13) | G13: 198.01
A14: 1647 | B14: HAIR GALLERY EUROPE SRL | C14: =SUM(D14:L14) | G14: 15.84
A15: 179 | B15: FERRIGNO MARIA C S N C | C15: =SUM(D15:L15)
A16: 744 | B16: Nola Ferramenta Srl | C16: =SUM(D16:L16)
A17: 1036 | B17: Re Denari di Marco Oliva & C. Sas | C17: =SUM(D17:L17)
A18: 70 | B18: MAGALDI LIFE SRL SOC. UNIP. | C18: =SUM(D18:L18) | G18: 206.47 | H18: 80.08
A19: 1696 | B19: READYPRINT DI PIPITONE BRUNO | C19: =SUM(D19:L19)
A20: 170 | B20: Leroy Merlin Italia srl | C20: =SUM(D20:L20) | G20: 81.88
A21: 109 | B21: MEDIAMARKET S.P.A. CON SOCIO UNICO | C21: =SUM(D21:L21) | G21: 213.88
A22: 123 | B22: PREGIS S.P.A. | C22: =SUM(D22:L22)
A23: 1183 | B23: ADRA S.R.L. | C23: =SUM(D23:L23)
A24: 618 | B24: Apple Retail Italia | C24: =SUM(D24:L24) | G24: 22.5
A25: 1724 | B25: D.L. Brothers | C25: =SUM(D25:L25) | G25: 296.56
A26: 1748 | B26: Doctor Spy Societa' A Responsabilita' Limitata | C26: =SUM(D26:L26)
A27: 1773 | B27: Gruppo Adam s.r.l. | C27: =SUM(D27:L27)
A28: 1768 | B28: I.R.P.S. Srl | C28: =SUM(D28:L28) | G28: 599.5
A29: 231 | B29: Ikea Italia Retail Srl | C29: =SUM(D29:L29) | G29: 1039
A30: 1752 | B30: Lo Scoglio Dei F.Lli De Simone S.R.L. | C30: =SUM(D30:L30)
A31: 1202 | B31: Nila S.R.L. | C31: =SUM(D31:L31) | G31: 782.2
A32: 1772 | B32: Propac S.R.L. | C32: =SUM(D32:L32)
A33: 797 | B33: Puntoffice Di Cardarelli Rita | C33: =SUM(D33:L33) | G33: 58
A34: 980 | B34: Ristorante O Padrone Do'Mare Di De Siano Giacinto & C. Snc | C34: =SUM(D34:L34)
A35: 1298 | B35: Apicella Lorenzo | C35: =SUM(D35:L35) | G35: 700
A36: 734 | B36: LEONE S.R.L. Via della Dogana 25 | C36: =SUM(D36:L36) | G36: 362.89
C37: =SUM(D37:L37)
C38: =SUM(D38:L38)
C39: =SUM(D39:L39)
C40: =SUM(D40:L40)
...

Sheet DA MAPPARE
A1: Fornitori NON mappati in d_fornitori.csv — assegnare una voce (hotelops fornitori) e rigenerare
A2: Cod | B2: Nome (da export) | C2: GENNAIO | D2: FEBBRAIO | E2: MARZO | F2: APRILE | G2: MAGGIO | H2: GIUGNO | I2: LUGLIO | J2: AGOSTO | K2: SETTEMBRE | L2: OTTOBRE | M2: NOVEMBRE | N2: DICEMBRE

Sheet ESCLUSI
A1: Fornitori ESCLUSI dalla cassa per scelta (is_excluded) — fuori dal saldo proiettato. NON sono un TODO: il motivo è in colonna Motivo.
A2: Cod | B2: Nome (da CSV) | C2: GENNAIO | D2: FEBBRAIO | E2: MARZO | F2: APRILE | G2: MAGGIO | H2: GIUGNO | I2: LUGLIO | J2: AGOSTO | K2: SETTEMBRE | L2: OTTOBRE | M2: NOVEMBRE | N2: DICEMBRE | O2: Motivo
A3: 27 | B3: AL MORO DI ROMAGNOLI ANDREA SAS | I3: 394.98 | O3: escluso da app cashflow
A4: 1758 | B4: BRILY DI AVETA VINCENZO | H4: 14.23 | O4: escluso da app cashflow
A5: 1765 | B5: Fercolor s.r.l. | H5: 54.39 | O5: escluso da app cashflow
A6: 1745 | B6: POPPITI ALDO | H6: 19.61 | O6: escluso da app cashflow
A7: 1755 | B7: VARZI GENERATION SRL | H7: 19.9 | O7: escluso da app cashflow

Sheet DA MAPPARE1
A1: Fornitori NON mappati in d_fornitori.csv — assegnare una voce (hotelops fornitori) e rigenerare
A2: Cod | B2: Nome (da export) | C2: GENNAIO | D2: FEBBRAIO | E2: MARZO | F2: APRILE | G2: MAGGIO | H2: GIUGNO | I2: LUGLIO | J2: AGOSTO | K2: SETTEMBRE | L2: OTTOBRE | M2: NOVEMBRE | N2: DICEMBRE
A3: 648 | B3: ALBA NEON S.R.L. | I3: 976
A4: 949 | B4: ASSOCIAZIONE SOUL FOOD | I4: 1490
A5: 1721 | B5: LEIDIVA DI SEPE ROSARIO | I5: 507.52

Sheet DA MAPPARE2
A1: Fornitori NON mappati in d_fornitori.csv — assegnare una voce (hotelops fornitori) e rigenerare
A2: Cod | B2: Nome (da export) | C2: GENNAIO | D2: FEBBRAIO | E2: MARZO | F2: APRILE | G2: MAGGIO | H2: GIUGNO | I2: LUGLIO | J2: AGOSTO | K2: SETTEMBRE | L2: OTTOBRE | M2: NOVEMBRE | N2: DICEMBRE
A3: 648 | B3: ALBA NEON S.R.L. VIA CAVONE DEGLI SBIRRI 24 | I3: 976
A4: 949 | B4: ASSOCIAZIONE SOUL FOOD VIA FERRERIA 120 | I4: 1490
A5: 1829 | B5: atelier tessuti & arredo srls via olivella 24 | J5: 5368
A6: 617 | B6: D AUTOMOTIVE S.R.L. VIA LUIGI EINAUDI 9 | J6: 488
A7: 919 | B7: ERRA VIA VACCARO 90 | J7: 550
A8: 629 | B8: GDM S.P.A. VIA DEI VALTORTA 48 | I8: 133.29
A9: 1795 | B9: HYGIEN TECH S.R.L. VIALE ALEXANDRE GUSTAVE EIFFEL 100 | J9: 733.49
A10: 1721 | B10: LEIDIVA DI SEPE ROSARIO VIA SANTA TECLA 50 | I10: 507.52
A11: 1832 | B11: Presspower S.r.l. Strada San Tommaso 2 | J11: 39.42
A12: 1157 | B12: RG Commerciale S.r.l. Via Gaetano MODONESI, 8 | I12: 114.1
A13: 294 | B13: RISTORANTE MARIA GRAZIA S.R.L. VIA MARINA DEL CANTONE75 | I13: 822
A14: 1825 | B14: SLOPE S.R.L. VIA VITTORIO VENETO | J14: 18.9
A15: 1830 | B15: societa agricola BIO TI CA ss Contrada Roccaro snc | J15: 14.04
A16: 1823 | B16: TO SHARE SRLS SALITA TORRE DELLO ZIRO,28 | I16: 299.99
